Workbook
Name Consol: "Error"

Sheet PRICE LIST Motasa
A3: KELOMPOK PRODUK | B3: KODE PRODUK PRINSIPAL | C3: NAMA ITEM | D3: ISI/CTN | E3: SATUAN | F3: HARGA INCLUDE PPN 11% IN CTN | G3: HARGA/PCS
A4: ANTANGIN GROUP | B4: 10002 | C4: ANTANGIN JRG PLUS JAHE MERAH TD20 | D4: 1000 | E4: STRIP | F4: 3210000 | G4: =F4/D4 -> 3210
A5: ANTANGIN GROUP | B5: 10063 | C5: ANTANGIN JUNIORS SD5 | D5: 300 | E5: SACHET | F5: 600000 | G5: =F5/D5 -> 2000
A6: ANTANGIN GROUP | B6: 10074 | C6: ANTANGIN JRG + MADU SD12 | D6: 360 | E6: SACHET | F6: 1116000 | G6: =F6/D6 -> 3100
A7: ANTANGIN GROUP | B7: 10075 | C7: ANTANGIN MINT SD12 | D7: 360 | E7: SACHET | F7: 1116000 | G7: =F7/D7 -> 3100
A8: ANTANGIN GROUP | B8: 10077 | C8: ANTANGIN MINT SD5 | D8: 300 | E8: SACHET | F8: 930000 | G8: =F8/D8 -> 3100
A9: ANTANGIN GROUP | B9: 10110 | C9: ANTANGIN GOOD NIGTH TD20 | D9: 1000 | E9: STRIP | F9: 4036000 | G9: =F9/D9 -> 4036
A10: ANTANGIN GROUP | B10: 10112 | C10: ANTANGIN HABBATUSSAUDA SD12 | D10: 360 | E10: SACHET | F10: 1116000 | G10: =F10/D10 -> 3100
A11: ANTANGIN GROUP | B11: 10134 | C11: ANTANGIN HABBATUSSAUDA SD14 | D11: 420 | E11: SACHET | F11: 1115998.8 | G11: =F11/D11 -> 2657.14
A12: ANTANGIN GROUP | B12: 10135 | C12: ANTANGIN MINT SD14 | D12: 420 | E12: SACHET | F12: 1115998.8 | G12: =F12/D12 -> 2657.14
A13: CANDY GROUP | B13: 10039 | C13: OB HERBAL PERMEN HERBAL RASA MINT S5 | D13: 270 | E13: SACHET | F13: 558090 | G13: =F13/D13 -> 2067
A14: CANDY GROUP | B14: 10048 | C14: ANTANGIN PERMEN HERBAL RASA MADU MINT T30 | D14: 180 | E14: SACHET | F14: 372060 | G14: =F14/D14 -> 2067
A15: CANDY GROUP | B15: 10067 | C15: ANTANGIN PERMEN ANEKA RASA T250 | D15: 6 | E15: TOPLES | F15: 213666 | G15: =F15/D15 -> 35611
... A149: MADU GROUP | B149: 60108 | C149: MADU TJ STRAWBERRY D12 (DUS) | D149: 24 | E149: DUS | F149: 201531.6 | G149: =F149/D149 -> 8397.15

Sheet FORM DASAR KLP
A3: KODE PRODUK PRINSIPAL | B3: KELOMPOK PRODUK By Principle | C3: NAMA ITEM | D3: ISI/CTN | E3: SATUAN | F3: HARGA INCLUDE PPN 11% IN CTN | G3: HARGA/PCS
A4: 10002 | B4: ANTANGIN GROUP | C4: ANTANGIN JRG PLUS JAHE MERAH TD20 | D4: 1000 | E4: STRIP | F4: 3563100 | G4: =F4/D4 -> 3563.1
A5: 10063 | B5: ANTANGIN GROUP | C5: ANTANGIN JUNIORS SD5 | D5: 300 | E5: SACHET | F5: 666000 | G5: =F5/D5 -> 2220
A6: 10074 | B6: ANTANGIN GROUP | C6: ANTANGIN JRG + MADU SD12 | D6: 360 | E6: SACHET | F6: 1238760 | G6: =F6/D6 -> 3441
A7: 10075 | B7: ANTANGIN GROUP | C7: ANTANGIN MINT SD12 | D7: 360 | E7: SACHET | F7: 1238760 | G7: =F7/D7 -> 3441
A8: 10077 | B8: ANTANGIN GROUP | C8: ANTANGIN MINT SD5 | D8: 300 | E8: SACHET | F8: 1032300 | G8: =F8/D8 -> 3441
A9: 10110 | B9: ANTANGIN GROUP | C9: ANTANGIN GOOD NIGTH TD20 | D9: 1000 | E9: STRIP | F9: 4479960 | G9: =F9/D9 -> 4479.96
A10: 10112 | B10: ANTANGIN GROUP | C10: ANTANGIN HABBATUSSAUDA SD12 | D10: 360 | E10: SACHET | F10: 1238760 | G10: =F10/D10 -> 3441
A11: 10134 | B11: ANTANGIN GROUP | C11: ANTANGIN HABBATUSSAUDA SD14 | D11: 420 | E11: SACHET | F11: 1238758.7 | G11: =F11/D11 -> 2949.4254
A12: 10135 | B12: ANTANGIN GROUP | C12: ANTANGIN MINT SD14 | D12: 420 | E12: SACHET | F12: 1238758.7 | G12: =F12/D12 -> 2949.4254
A13: 10039 | B13: CANDY GROUP | C13: OB HERBAL PERMEN HERBAL RASA MINT S5 | D13: 270 | E13: SACHET | F13: 619479.9 | G13: =F13/D13 -> 2294.37
A14: 10048 | B14: CANDY GROUP | C14: ANTANGIN PERMEN HERBAL RASA MADU MINT T30 | D14: 180 | E14: SACHET | F14: 412986.6 | G14: =F14/D14 -> 2294.37
A15: 10067 | B15: CANDY GROUP | C15: ANTANGIN PERMEN ANEKA RASA T250 | D15: 6 | E15: TOPLES | F15: 237169.26 | G15: =F15/D15 -> 39528.21
... A149: 60108 | B149: MADU GROUP | C149: MADU TJ STRAWBERRY D12 (DUS) | D149: 24 | E149: DUS | F149: 223700.08 | G149: =F149/D149 -> 9320.8365

Sheet Cara Buat
A3: 1 | B3: Sortir Daftar Produk Principle sesuai Nama lalu sortir lagi by kelompok | D3: 1 | E3: Buat satu folder master barang, master kelompok, price list, mapping produk win to pcpl dan mapping produk pcpl to win
A4: 2 | B4: Copy dan Paste kan ke Sheet Form Master (sesuaikan kolom nya) | D4: 2 | E4: Master barang, master kelompok, price list, mapping produk win to pcpl dan mapping produk pcpl to win berdiri sendiri dalam satu book
A5: 3 | B5: Sheet kuning adalah rumus, jangan diganggu

Sheet Pvt Map 1
A3: Kode BARANG Win2 | B3: SATUAN Fix Win | C3: Kode Pcpl | D3: ISI/CTN | E3: Sum of No. Urut Item Sama
A4: G1011000001510 | B4: TUBE | C4: 40008216 | D4: 144
A5: G1011000005010 | B5: TUBE | C5: 40008217 | D5: 48
A6: G1020000002010 | B6: SCH | C6: 40014370 | D6: 144
A7: G1020000002010 | B7: SCH | C7: 40035630 | D7: 144
A8: G1020000040021 | B8: PCH | C8: 40056288 | D8: 6
A9: G1020000040020 | B9: PCH | C9: 40008247 | D9: 12
A10: G1020000070021 | B10: PCH | C10: 40056289 | D10: 6
A11: G1020000070021 | B11: PCH | C11: 40063060 | D11: 6
A12: G1020000070020 | B12: PCH | C12: 40013979 | D12: 12
A13: G1031001001210 | B13: PCS | C13: 40008387 | D13: 72
A14: G1031002000310 | B14: PCS | C14: 40008390 | D14: 120
A15: G1032101006011 | B15: PCS | C15: 40034355 | D15: 12
... A118: G1073101004510 | B118: BOX | C118: 40057201 | D118: 144
A119: G1073101004510 | B119: BOX | C119: 40061095 | D119: (blank)
A120: G1073201004510 | B120: BOX | C120: 40059201 | D120: 144
A121: G1073102004510 | B121: BOX | C121: 40036249 | D121: 144
A122: G1073102004510 | B122: BOX | C122: 40057203 | D122: 144
A123: G1073102004510 | B123: BOX | C123: 40061096 | D123: 144
A124: G1073103004510 | B124: BOX | C124: 40057315 | D124: 144
A125: G1073103004510 | B125: BOX | C125: 40061097 | D125: 144
A126: G1073001000010 | B126: SET | C126: 40036247 | D126: 24
A127: G1073001000010 | B127: SET | C127: 40057200 | D127: 24
A128: G1073001000010 | B128: SET | C128: 40028235 | D128: 24
A129: G1074101003510 | B129: BOX | C129: 40036708 | D129: 144
A130: G1074101003510 | B130: BOX | C130: 40057318 | D130: 144
A131: G1074102003510 | B131: BOX | C131: 40036709 | D131: 144
... A139: G1075001070010 | B139: PCH | C139: 40016506 | D139: 12
A140: G1075001070010 | B140: PCH | C140: 40049643 | D140: (blank)
A141: G1075002036010 | B141: PCH | C141: 40012018 | D141: 12
A142: G1075002070010 | B142: PCH | C142: 40008190 | D142: 12
A143: G1075003070011 | B143: PCH | C143: 40049642 | D143: 12
A144: G1075003070011 | B144: PCH | C144: 40049643 | D144: 12
A145: G1075004036010 | B145: PCH | C145: 40008191 | D145: 12
A146: G1075004070010 | B146: PCH | C146: 40049641 | D146: 12
A147: G1075004070010 | B147: PCH | C147: 40008192 | D147: 12
A148: G1076201000410 | B148: PCS | C148: 40043776 | D148: 120
A149: G1076201000410 | B149: PCS | C149: 40029462 | D149: 120
A150: G1076101000410 | B150: PCS | C150: 40028914 | D150: 576
A151: G1076202000410 | B151: PCS | C151: 40043777 | D151: 120
...

Sheet Table Pvt 1
A1: Kode Barang Win | B1: Kode Pcpl | C1: SATUAN Fix Win | D1: ISI/CTN | E1: Kode PCPL yang sama | F1: Column1
A2: F4011100007010 | B2: 040411111 | C2: BOX | D2: 6 | E2: 1 | F2: =Pvt_Map_1[[#This Row],[Kode Barang Win]] -> F4011100007010
A3: F4012101040010 | B3: 050413100 | C3: PCH | D3: 24 | E3: 1 | F3: =Pvt_Map_1[[#This Row],[Kode Barang Win]] -> F4012101040010
A4: F4012102040010 | B4: 050415100 | C4: PCH | D4: 24 | E4: 1 | F4: =Pvt_Map_1[[#This Row],[Kode Barang Win]] -> F4012102040010
A5: F4012001048020 | B5: 050413200 | C5: PUMP | D5: 24 | E5: 1 | F5: =Pvt_Map_1[[#This Row],[Kode Barang Win]] -> F4012001048020
A6: F4012002048020 | B6: 050415200 | C6: PUMP | D6: 24 | E6: 1 | F6: =Pvt_Map_1[[#This Row],[Kode Barang Win]] -> F4012002048020
A7: F4013001007010 | B7: 040413100 | C7: PCS | D7: 72 | E7: 1 | F7: =Pvt_Map_1[[#This Row],[Kode Barang Win]] -> F4013001007010
A8: F4013002007010 | B8: 040415100 | C8: PCS | D8: 72 | E8: 1 | F8: =Pvt_Map_1[[#This Row],[Kode Barang Win]] -> F4013002007010
A9: F4021001010010 | B9: 040402200 | C9: PCS | D9: 72 | E9: 1 | F9: =Pvt_Map_1[[#This Row],[Kode Barang Win]] -> F4021001010010
A10: F4031101040010 | B10: 050703100 | C10: PUMP | D10: 24 | E10: 1 | F10: =Pvt_Map_1[[#This Row],[Kode Barang Win]] -> F4031101040010
A11: F4031102040020 | B11: 050702100 | C11: PCH | D11: 24 | E11: 1 | F11: =Pvt_Map_1[[#This Row],[Kode Barang Win]] -> F4031102040020
A12: F4031103040020 | B12: 050701100 | C12: PCH | D12: 24 | E12: 1 | F12: =Pvt_Map_1[[#This Row],[Kode Barang Win]] -> F4031103040020
A13: F4031001048030 | B13: 050703101 | C13: BTL | D13: 24 | E13: 1 | F13: =Pvt_Map_1[[#This Row],[Kode Barang Win]] -> F4031001048030
... A72: F4065002008011 | B72: 191701307 | C72: TUBE | D72: 48 | E72: 1 | F72: =Pvt_Map_1[[#This Row],[Kode Barang Win]] -> F4065002008011
A73: F4065002008011 | B73: 191703000 | C73: TUBE | D73: 48 | E73: 1 | F73: =Pvt_Map_1[[#This Row],[Kode Barang Win]] -> F4065002008011
A74: F4065003002010 | B74: 191702000 | C74: TUBE | D74: 12 | E74: 1 | F74: =Pvt_Map_1[[#This Row],[Kode Barang Win]] -> F4065003002010
A75: F4066001008010 | B75: 041716400 | C75: PCS | D75: 144 | E75: 1 | F75: =Pvt_Map_1[[#This Row],[Kode Barang Win]] -> F4066001008010
A76: F4066002008010 | B76: 041720400 | C76: PCS | D76: 144 | E76: 1 | F76: =Pvt_Map_1[[#This Row],[Kode Barang Win]] -> F4066002008010
A77: F4066003008010 | B77: 041717400 | C77: PCS | D77: 144 | E77: 1 | F77: =Pvt_Map_1[[#This Row],[Kode Barang Win]] -> F4066003008010
A78: F4066004008010 | B78: 041715400 | C78: PCS | D78: 144 | E78: 1 | F78: =Pvt_Map_1[[#This Row],[Kode Barang Win]] -> F4066004008010
A79: F4066005008010 | B79: 041718400 | C79: PCS | D79: 144 | E79: 1 | F79: =Pvt_Map_1[[#This Row],[Kode Barang Win]] -> F4066005008010
A80: F4066006008010 | B80: 041719400 | C80: PCS | D80: 144 | E80: 1 | F80: =Pvt_Map_1[[#This Row],[Kode Barang Win]] -> F4066006008010
A81: F4067101018010 | B81: 051706300 | C81: PCH | D81: 48 | E81: 1 | F81: =Pvt_Map_1[[#This Row],[Kode Barang Win]] -> F4067101018010
A82: F4067102018010 | B82: 051703300 | C82: PCH | D82: 48 | E82: 1 | F82: =Pvt_Map_1[[#This Row],[Kode Barang Win]] -> F4067102018010
A83: F4067103018010 | B83: 051704300 | C83: PCH | D83: 48 | E83: 1 | F83: =Pvt_Map_1[[#This Row],[Kode Barang Win]] -> F4067103018010
A84: F4067104018010 | B84: 051705300 | C84: PCH | D84: 48 | E84: 1 | F84: =Pvt_Map_1[[#This Row],[Kode Barang Win]] -> F4067104018010
A85: F4067005018010 | B85: 051702300 | C85: PCH | D85: 48 | E85: 1 | F85: =Pvt_Map_1[[#This Row],[Kode Barang Win]] -> F4067005018010
A86: F4067005048020 | B86: 051702800 | C86: PUMP | D86: 24 | E86: 1 | F86: =Pvt_Map_1[[#This Row],[Kode Barang Win]] -> F4067005048020
... A130: F4067011048020 | B130: 051705800 | C130: PUMP | D130: 24 | E130: 1 | F130: =Pvt_Map_1[[#This Row],[Kode Barang Win]] -> F4067011048020
A131: F4053004003020 | B131: 112603000 | C131: BTL | D131: 48 | E131: 1 | F131: =Pvt_Map_1[[#This Row],[Kode Barang Win]] -> F4053004003020
A132: F4053001003020 | B132: 112601000 | C132: BTL | D132: 48 | E132: 1 | F132: =Pvt_Map_1[[#This Row],[Kode Barang Win]] -> F4053001003020
A133: F4053002003020 | B133: 112604000 | C133: BTL | D133: 48 | E133: 1 | F133: =Pvt_Map_1[[#This Row],[Kode Barang Win]] -> F4053002003020
A134: F4053003003020 | B134: 112602000 | C134: BTL | D134: 48 | E134: 1 | F134: =Pvt_Map_1[[#This Row],[Kode Barang Win]] -> F4053003003020
A135: F4061104040011 | B135: 051701495 | C135: PCH | D135: 12 | E135: 1 | F135: =Pvt_Map_1[[#This Row],[Kode Barang Win]] -> F4061104040011
A136: F4061104040011 | B136: 051701012 | C136: PCH | D136: 12 | F136: =Pvt_Map_1[[#This Row],[Kode Barang Win]] -> F4061104040011
A137: F4061204042010 | B137: 051701400 | C137: PCH | D137: 24 | E137: 1 | F137: =Pvt_Map_1[[#This Row],[Kode Barang Win]] -> F4061204042010
A138: F4061301042010 | B138: 051702400 | C138: PCH | D138: 24 | E138: 1 | F138: =Pvt_Map_1[[#This Row],[Kode Barang Win]] -> F4061301042010
A139: F4061403042010 | B139: 051703400 | C139: PCH | D139: 24 | E139: 1 | F139: =Pvt_Map_1[[#This Row],[Kode Barang Win]] -> F4061403042010
A140: F4061510042010 | B140: 051704400 | C140: PCH | D140: 24 | E140: 1 | F140: =Pvt_Map_1[[#This Row],[Kode Barang Win]] -> F4061510042010
A141: F4061611042010 | B141: 051705400 | C141: PCH | D141: 24 | E141: 1 | F141: =Pvt_Map_1[[#This Row],[Kode Barang Win]] -> F4061611042010
...

Sheet Fix Mapping
A1: KODE BARANG | B1: NAMA BARANG | C1: ISI/CTN | D1: SATUAN | E1: NAMA KELOMPOK | F1: Harga Beli Pcs (-PPN) | G1: Harga Beli Krt (- PPN) | H1: Harga Beli Pcs (+PPN) | I1: Harga Beli Krt (+PPN) | J1: Harga Jual Pcs GT (-PPN) | K1: Harga Jual Krt GT (- PPN) | L1: Harga Jual Pcs GT (+PPN | M1: Harga Jual Krt GT (+PPN) | N1: Harga Jual Pcs MT (-PPN) | O1: Harga Jual Krt MT (- PPN) | P1: Harga Jual Pcs MT (+PPN) | Q1: Harga Jual Krt MT (+PPN) | R1: NAMA PRINCIPLE | S1: PCPL KODE 1 | T1: PCPL KODE 2 | U1: PCPL KODE 3 | V1: PCPL KODE 4 | W1: PCPL KODE 5

Sheet Query Map.BrgDoubleDms
A1: Kode BARANG Win2 | B1: Nama Win | C1: PCPL KODE 1 | D1: PCPL KODE 2 | E1: PCPL KODE 3 | F1: PCPL KODE 4 | G1: PCPL KODE 5
B2: X | C2: =IFERROR(VLOOKUP(CONCATENATE(Table43_1[[#This Row],[Kode BARANG Win2]],1),'Form Fix'!$A$6:$H$663,4,0),0) -> 0 | D2: =IFERROR(VLOOKUP(CONCATENATE(Table43_1[[#This Row],[Kode BARANG Win2]],2),'Form Fix'!$A$6:$H$663,4,0),0) -> 0 | E2: =IFERROR(VLOOKUP(CONCATENATE(Table43_1[[#This Row],[Kode BARANG Win2]],3),'Form Fix'!$A$6:$H$663,4,0),0) -> 0 | F2: =IFERROR(VLOOKUP(CONCATENATE(Table43_1[[#This Row],[Kode BARANG Win2]],4),'Form Fix'!$A$6:$H$663,4,0),0) -> 0 | G2: =IFERROR(VLOOKUP(CONCATENATE(Table43_1[[#This Row],[Kode BARANG Win2]],5),'Form Fix'!$A$6:$H$663,4,0),0) -> 0
A3: G1011000001510 | B3: AUTOSOL METAL POLISH 15GR X 144 TUBE | C3: =IFERROR(VLOOKUP(CONCATENATE(Table43_1[[#This Row],[Kode BARANG Win2]],1),'Form Fix'!$A$6:$H$663,4,0),0) -> 0 | D3: =IFERROR(VLOOKUP(CONCATENATE(Table43_1[[#This Row],[Kode BARANG Win2]],2),'Form Fix'!$A$6:$H$663,4,0),0) -> 0 | E3: =IFERROR(VLOOKUP(CONCATENATE(Table43_1[[#This Row],[Kode BARANG Win2]],3),'Form Fix'!$A$6:$H$663,4,0),0) -> 0 | F3: =IFERROR(VLOOKUP(CONCATENATE(Table43_1[[#This Row],[Kode BARANG Win2]],4),'Form Fix'!$A$6:$H$663,4,0),0) -> 0 | G3: =IFERROR(VLOOKUP(CONCATENATE(Table43_1[[#This Row],[Kode BARANG Win2]],5),'Form Fix'!$A$6:$H$663,4,0),0) -> 0
A4: G1011000005010 | B4: AUTOSOL METAL POLISH 50GR X 48 TUBE | C4: =IFERROR(VLOOKUP(CONCATENATE(Table43_1[[#This Row],[Kode BARANG Win2]],1),'Form Fix'!$A$6:$H$663,4,0),0) -> 0 | D4: =IFERROR(VLOOKUP(CONCATENATE(Table43_1[[#This Row],[Kode BARANG Win2]],2),'Form Fix'!$A$6:$H$663,4,0),0) -> 0 | E4: =IFERROR(VLOOKUP(CONCATENATE(Table43_1[[#This Row],[Kode BARANG Win2]],3),'Form Fix'!$A$6:$H$663,4,0),0) -> 0 | F4: =IFERROR(VLOOKUP(CONCATENATE(Table43_1[[#This Row],[Kode BARANG Win2]],4),'Form Fix'!$A$6:$H$663,4,0),0) -> 0 | G4: =IFERROR(VLOOKUP(CONCATENATE(Table43_1[[#This Row],[Kode BARANG Win2]],5),'Form Fix'!$A$6:$H$663,4,0),0) -> 0
A5: G1020000002010 | B5: BIOSOL 20ML X 144 SCH | C5: =IFERROR(VLOOKUP(CONCATENATE(Table43_1[[#This Row],[Kode BARANG Win2]],1),'Form Fix'!$A$6:$H$663,4,0),0) -> 0 | D5: =IFERROR(VLOOKUP(CONCATENATE(Table43_1[[#This Row],[Kode BARANG Win2]],2),'Form Fix'!$A$6:$H$663,4,0),0) -> 0 | E5: =IFERROR(VLOOKUP(CONCATENATE(Table43_1[[#This Row],[Kode BARANG Win2]],3),'Form Fix'!$A$6:$H$663,4,0),0) -> 0 | F5: =IFERROR(VLOOKUP(CONCATENATE(Table43_1[[#This Row],[Kode BARANG Win2]],4),'Form Fix'!$A$6:$H$663,4,0),0) -> 0 | G5: =IFERROR(VLOOKUP(CONCATENATE(Table43_1[[#This Row],[Kode BARANG Win2]],5),'Form Fix'!$A$6:$H$663,4,0),0) -> 0
A6: G1020000040020 | B6: BIOSOL 400ML X 12 PCH | C6: =IFERROR(VLOOKUP(CONCATENATE(Table43_1[[#This Row],[Kode BARANG Win2]],1),'Form Fix'!$A$6:$H$663,4,0),0) -> 0 | D6: =IFERROR(VLOOKUP(CONCATENATE(Table43_1[[#This Row],[Kode BARANG Win2]],2),'Form Fix'!$A$6:$H$663,4,0),0) -> 0 | E6: =IFERROR(VLOOKUP(CONCATENATE(Table43_1[[#This Row],[Kode BARANG Win2]],3),'Form Fix'!$A$6:$H$663,4,0),0) -> 0 | F6: =IFERROR(VLOOKUP(CONCATENATE(Table43_1[[#This Row],[Kode BARANG Win2]],4),'Form Fix'!$A$6:$H$663,4,0),0) -> 0 | G6: =IFERROR(VLOOKUP(CONCATENATE(Table43_1[[#This Row],[Kode BARANG Win2]],5),'Form Fix'!$A$6:$H$663,4,0),0) -> 0
A7: G1020000040021 | B7: BIOSOL 400ML X 6 PCH BOGOF | C7: =IFERROR(VLOOKUP(CONCATENATE(Table43_1[[#This Row],[Kode BARANG Win2]],1),'Form Fix'!$A$6:$H$663,4,0),0) -> 0 | D7: =IFERROR(VLOOKUP(CONCATENATE(Table43_1[[#This Row],[Kode BARANG Win2]],2),'Form Fix'!$A$6:$H$663,4,0),0) -> 0 | E7: =IFERROR(VLOOKUP(CONCATENATE(Table43_1[[#This Row],[Kode BARANG Win2]],3),'Form Fix'!$A$6:$H$663,4,0),0) -> 0 | F7: =IFERROR(VLOOKUP(CONCATENATE(Table43_1[[#This Row],[Kode BARANG Win2]],4),'Form Fix'!$A$6:$H$663,4,0),0) -> 0 | G7: =IFERROR(VLOOKUP(CONCATENATE(Table43_1[[#This Row],[Kode BARANG Win2]],5),'Form Fix'!$A$6:$H$663,4,0),0) -> 0
A8: G1020000070020 | B8: BIOSOL 700ML X 12 PCH | C8: =IFERROR(VLOOKUP(CONCATENATE(Table43_1[[#This Row],[Kode BARANG Win2]],1),'Form Fix'!$A$6:$H$663,4,0),0) -> 0 | D8: =IFERROR(VLOOKUP(CONCATENATE(Table43_1[[#This Row],[Kode BARANG Win2]],2),'Form Fix'!$A$6:$H$663,4,0),0) -> 0 | E8: =IFERROR(VLOOKUP(CONCATENATE(Table43_1[[#This Row],[Kode BARANG Win2]],3),'Form Fix'!$A$6:$H$663,4,0),0) -> 0 | F8: =IFERROR(VLOOKUP(CONCATENATE(Table43_1[[#This Row],[Kode BARANG Win2]],4),'Form Fix'!$A$6:$H$663,4,0),0) -> 0 | G8: =IFERROR(VLOOKUP(CONCATENATE(Table43_1[[#This Row],[Kode BARANG Win2]],5),'Form Fix'!$A$6:$H$663,4,0),0) -> 0
A9: G1020000070021 | B9: BIOSOL 700ML X 6 PCH BOGOF | C9: =IFERROR(VLOOKUP(CONCATENATE(Table43_1[[#This Row],[Kode BARANG Win2]],1),'Form Fix'!$A$6:$H$663,4,0),0) -> 0 | D9: =IFERROR(VLOOKUP(CONCATENATE(Table43_1[[#This Row],[Kode BARANG Win2]],2),'Form Fix'!$A$6:$H$663,4,0),0) -> 0 | E9: =IFERROR(VLOOKUP(CONCATENATE(Table43_1[[#This Row],[Kode BARANG Win2]],3),'Form Fix'!$A$6:$H$663,4,0),0) -> 0 | F9: =IFERROR(VLOOKUP(CONCATENATE(Table43_1[[#This Row],[Kode BARANG Win2]],4),'Form Fix'!$A$6:$H$663,4,0),0) -> 0 | G9: =IFERROR(VLOOKUP(CONCATENATE(Table43_1[[#This Row],[Kode BARANG Win2]],5),'Form Fix'!$A$6:$H$663,4,0),0) -> 0
A10: G1021101050030 | B10: BIOSOL HIT POWER L2L B2B PRO 500ML X 24 JRG | C10: =IFERROR(VLOOKUP(CONCATENATE(Table43_1[[#This Row],[Kode BARANG Win2]],1),'Form Fix'!$A$6:$H$663,4,0),0) -> 0 | D10: =IFERROR(VLOOKUP(CONCATENATE(Table43_1[[#This Row],[Kode BARANG Win2]],2),'Form Fix'!$A$6:$H$663,4,0),0) -> 0 | E10: =IFERROR(VLOOKUP(CONCATENATE(Table43_1[[#This Row],[Kode BARANG Win2]],3),'Form Fix'!$A$6:$H$663,4,0),0) -> 0 | F10: =IFERROR(VLOOKUP(CONCATENATE(Table43_1[[#This Row],[Kode BARANG Win2]],4),'Form Fix'!$A$6:$H$663,4,0),0) -> 0 | G10: =IFERROR(VLOOKUP(CONCATENATE(Table43_1[[#This Row],[Kode BARANG Win2]],5),'Form Fix'!$A$6:$H$663,4,0),0) -> 0
A11: G1031001001210 | B11: CAP GAJAH LEM LALAT STICK 12S X 72 PCS | C11: =IFERROR(VLOOKUP(CONCATENATE(Table43_1[[#This Row],[Kode BARANG Win2]],1),'Form Fix'!$A$6:$H$663,4,0),0) -> 0 | D11: =IFERROR(VLOOKUP(CONCATENATE(Table43_1[[#This Row],[Kode BARANG Win2]],2),'Form Fix'!$A$6:$H$663,4,0),0) -> 0 | E11: =IFERROR(VLOOKUP(CONCATENATE(Table43_1[[#This Row],[Kode BARANG Win2]],3),'Form Fix'!$A$6:$H$663,4,0),0) -> 0 | F11: =IFERROR(VLOOKUP(CONCATENATE(Table43_1[[#This Row],[Kode BARANG Win2]],4),'Form Fix'!$A$6:$H$663,4,0),0) -> 0 | G11: =IFERROR(VLOOKUP(CONCATENATE(Table43_1[[#This Row],[Kode BARANG Win2]],5),'Form Fix'!$A$6:$H$663,4,0),0) -> 0
A12: G1031002000310 | B12: CAP GAJAH LEM LALAT KERTAS 3S X 120 PCS | C12: =IFERROR(VLOOKUP(CONCATENATE(Table43_1[[#This Row],[Kode BARANG Win2]],1),'Form Fix'!$A$6:$H$663,4,0),0) -> 0 | D12: =IFERROR(VLOOKUP(CONCATENATE(Table43_1[[#This Row],[Kode BARANG Win2]],2),'Form Fix'!$A$6:$H$663,4,0),0) -> 0 | E12: =IFERROR(VLOOKUP(CONCATENATE(Table43_1[[#This Row],[Kode BARANG Win2]],3),'Form Fix'!$A$6:$H$663,4,0),0) -> 0 | F12: =IFERROR(VLOOKUP(CONCATENATE(Table43_1[[#This Row],[Kode BARANG Win2]],4),'Form Fix'!$A$6:$H$663,4,0),0) -> 0 | G12: =IFERROR(VLOOKUP(CONCATENATE(Table43_1[[#This Row],[Kode BARANG Win2]],5),'Form Fix'!$A$6:$H$663,4,0),0) -> 0
A13: G1032000005010 | B13: CAP GAJAH LEM TIKUS 50ML X 144 TUBE | C13: =IFERROR(VLOOKUP(CONCATENATE(Table43_1[[#This Row],[Kode BARANG Win2]],1),'Form Fix'!$A$6:$H$663,4,0),0) -> 0 | D13: =IFERROR(VLOOKUP(CONCATENATE(Table43_1[[#This Row],[Kode BARANG Win2]],2),'Form Fix'!$A$6:$H$663,4,0),0) -> 0 | E13: =IFERROR(VLOOKUP(CONCATENATE(Table43_1[[#This Row],[Kode BARANG Win2]],3),'Form Fix'!$A$6:$H$663,4,0),0) -> 0 | F13: =IFERROR(VLOOKUP(CONCATENATE(Table43_1[[#This Row],[Kode BARANG Win2]],4),'Form Fix'!$A$6:$H$663,4,0),0) -> 0 | G13: =IFERROR(VLOOKUP(CONCATENATE(Table43_1[[#This Row],[Kode BARANG Win2]],5),'Form Fix'!$A$6:$H$663,4,0),0) -> 0
A14: G1032000010010 | B14: CAP GAJAH LEM TIKUS 100ML X 144 TUBE | C14: =IFERROR(VLOOKUP(CONCATENATE(Table43_1[[#This Row],[Kode BARANG Win2]],1),'Form Fix'!$A$6:$H$663,4,0),0) -> 0 | D14: =IFERROR(VLOOKUP(CONCATENATE(Table43_1[[#This Row],[Kode BARANG Win2]],2),'Form Fix'!$A$6:$H$663,4,0),0) -> 0 | E14: =IFERROR(VLOOKUP(CONCATENATE(Table43_1[[#This Row],[Kode BARANG Win2]],3),'Form Fix'!$A$6:$H$663,4,0),0) -> 0 | F14: =IFERROR(VLOOKUP(CONCATENATE(Table43_1[[#This Row],[Kode BARANG Win2]],4),'Form Fix'!$A$6:$H$663,4,0),0) -> 0 | G14: =IFERROR(VLOOKUP(CONCATENATE(Table43_1[[#This Row],[Kode BARANG Win2]],5),'Form Fix'!$A$6:$H$663,4,0),0) -> 0
... A388: G1303100000010 | B388: SUSEMI SABUT STAINLESS PAPAN X 432 PCS | C388: =IFERROR(VLOOKUP(CONCATENATE(Table43_1[[#This Row],[Kode BARANG Win2]],1),'Form Fix'!$A$6:$H$663,4,0),0) -> 0 | D388: =IFERROR(VLOOKUP(CONCATENATE(Table43_1[[#This Row],[Kode BARANG Win2]],2),'Form Fix'!$A$6:$H$663,4,0),0) -> 0 | E388: =IFERROR(VLOOKUP(CONCATENATE(Table43_1[[#This Row],[Kode BARANG Win2]],3),'Form Fix'!$A$6:$H$663,4,0),0) -> 0 | F388: =IFERROR(VLOOKUP(CONCATENATE(Table43_1[[#This Row],[Kode BARANG Win2]],4),'Form Fix'!$A$6:$H$663,4,0),0) -> 0 | G388: =IFERROR(VLOOKUP(CONCATENATE(Table43_1[[#This Row],[Kode BARANG Win2]],5),'Form Fix'!$A$6:$H$663,4,0),0) -> 0

Sheet Form Fix
C1: UPDATE TGL
Q2: =COUNTIF(Table43[LEN 50], ">50") -> 87
D3: PASTE NAMA DAN CODE PRINCIPLE (Buat Format seperti ini dan Ambil dari Daftar Harga Principle) | R3: CPI | AO3: Daftar Harga | BD3: Update Per
K4: ISI SESUAIKAN ANTARA DMS vs WIN | M4: HASIL CODE KELOMPOK, CODE BARANG & NAMA BARANG WIN | R4: Kolom Principle | AO4: Harga Beli | AS4: Harga Jual GT | AW4: Harga Jual MT | BA4: MARGIN | BI4: To Win, diisi oleh Admin
A5: CONCATENATE MAPPING | B5: No. Urut Item Sama | C5: NO | D5: Kode Pcpl | E5: Klp Brg Pcpl | F5: Column4 | G5: Column3 | H5: Nama Barang Principle | I5: ISI/CTN | J5: Ket. Tambahan / Pembantu | K5: SATUAN Fix Win | L5: Nama Kelompok Win | M5: Kode Kelompok Win | N5: Kode BARANG Win2 | O5: LEN 15 | P5: Nama Win | Q5: LEN 50 | R5: Nama Pcpl | S5: kode 2 Digit (hrf+No) | T5: Nama KLP | U5: kode 2 Digit (Nomor) | V5: Nama Sub KLP | W5: kode 1 Digit (Nomor) | X5: Nama Sub KLP2 | Y5: kode 1 Digit (Nomor)5 | Z5: Nama Aroma/ Rasa | AA5: kode 2 Digit (Nomor)2 | AB5: Nama Gramasi atau Jumlah Pack per CTN | AC5: kode 4 Digit (Nomor) | AD5: NamaJenisKemasan | AE5: kode 1 Digit (Nomor)3 | AF5: Nama Promo | AG5: kode 1 Digit (Nomor)4 | AH5: Gunakan ini apabila item tersebut sachet | AI5: kode 1 Digit (Nomor)32 | AJ5: KET TAMBAHAN2 | AK5: KET. GOLONGAN | AL5: kode 1 Digit (Nomor) | AM5: Tanda Kode Revisi | AN5: Column6 | AO5: Harga Beli Pcs (-PPN) | AP5: Harga Beli Krt (- PPN) | AQ5: Harga Beli Pcs (+PPN) | AR5: Harga Beli Krt (+PPN) | AS5: Harga Jual Pcs GT (-PPN) | AT5: Harga Jual Krt GT (- PPN) | AU5: Harga Jual Pcs GT (+PPN | AV5: Harga Jual Krt GT (+PPN) | AW5: Harga Jual Pcs MT (-PPN) | AX5: Harga Jual Krt MT (- PPN) | AY5: Harga Jual Pcs MT (+PPN) | AZ5: Harga Jual Krt MT (+PPN) | BA5: MARGIN | BB5: Column1 | BC5: Column2 | BD5: Efektif Pembuatan | BE5: Efektif Naik Harga | BF5: Status Pembuatan | BG5: Status Harga | BH5: Status Barang | BI5: Mata Uang | BJ5: Kode Golongan | BK5: Nama Golongan | BL5: Kode PCPL To Win | BM5: Kode Jenis Produk | BN5: SAT BSR | BO5: GD | BP5: Kode PRK | BQ5: Kode PRK SJ | BR5: Kode Job | BS5: Approval | BT5: Nama Principle | BU5: Column5
A6: =CONCATENATE(Table43[[#This Row],[Kode BARANG Win2]],Table43[[#This Row],[No. Urut Item Sama]]) | K6: =Table43[[#This Row],[NamaJenisKemasan]] -> 0 | L6: =TRIM(CONCATENATE(Table43[[#This Row],[Nama KLP]]," ",Table43[[#This Row],[Nama Sub KLP]])) | M6: =CONCATENATE(Table43[[#This Row],[kode 2 Digit (hrf+No)]],Table43[[#This Row],[kode 2 Digit (Nomor)]],Table43[[#This Row],[kode 1 Digit (Nomor)]]) | N6: =IF(AI6="",CONCATENATE(S6,U6,W6,Y6,AA6,AC6,AE6,AG6,Table43[[#This Row],[Tanda Kode Revisi]]),CONCATENATE(S6,U6,W6,Y6,AA6,AC6,AE6,AI6)) | O6: =LEN(N6) -> 0 | P6: =IF(AH6<>"",TRIM(UPPER(CONCATENATE(R6," ",T6," ",V6," ",X6," ",Z6," ",AB6," ","X"," ",Table43[[#This Row],[ISI/CTN]]," ",AH6," ",AD6," ",AF6," ",AJ6))),TRIM(UPPER(CONCATENATE(R6," ",T6," ",V6," ",X6," ",Z6," ",AB6," ","X"," ",Table43[[#This Row],[ISI/CTN]]," ",AD6," ",AF6," ",AJ6)))) -> X | Q6: =LEN(P6) -> 1 | AK6: =Table43[[#This Row],[Column4]] -> 0 | AN6: =Table43[[#This Row],[ISI/CTN]] -> 0 | AO6: =Table43[[#This Row],[Harga Jual Pcs GT (-PPN)]]-(Table43[[#This Row],[Harga Jual Pcs GT (-PPN)]]*6.5%) -> 0 | AP6: =Table43[[#This Row],[Harga Beli Pcs (-PPN)]]*Table43[[#This Row],[ISI/CTN]] -> 0 | AQ6: =Table43[[#This Row],[Harga Beli Pcs (-PPN)]]*1.11 -> 0 | AR6: =Table43[[#This Row],[Harga Beli Krt (- PPN)]]*1.11 -> 0 | AT6: =Table43[[#This Row],[Harga Jual Pcs GT (-PPN)]]*Table43[[#This Row],[ISI/CTN]] -> 0 | AU6: =Table43[[#This Row],[Harga Jual Pcs GT (-PPN)]]*1.11 -> 0 | AV6: =Table43[[#This Row],[Harga Jual Krt GT (- PPN)]]*1.11 -> 0 | AW6: =IFERROR(VLOOKUP(Table43[[#This Row],[Kode Pcpl]],'[1]FEB 2026'!$A$3:$X$312,24,0),0) -> 0 | AX6: =Table43[[#This Row],[Harga Jual Pcs MT (-PPN)]]*Table43[[#This Row],[ISI/CTN]] -> 0 | AY6: =Table43[[#This Row],[Harga Jual Pcs MT (-PPN)]]*1.11 -> 0 | AZ6: =Table43[[#This Row],[Harga Jual Pcs MT (+PPN)]]*Table43[[#This Row],[ISI/CTN]] -> 0 | BA6: =(Table43[[#This Row],[Harga Jual Pcs GT (-PPN)]]-Table43[[#This Row],[Harga Beli Pcs (-PPN)]])/Table43[[#This Row],[Harga Jual Pcs GT (-PPN)]] -> #DIV/0! | BB6: =Table43[[#This Row],[Harga Jual Pcs MT (-PPN)]]-Table43[[#This Row],[Harga Beli Pcs (-PPN)]] -> 0 | BC6: =Table43[[#This Row],[Column1]]/Table43[[#This Row],[Harga Jual Pcs MT (-PPN)]] -> #DIV/0! | BF6: =IF(TODAY()-Table43[[#This Row],[Efektif Pembuatan]]>60,"Lama","Baru") -> Lama | BG6: =IF(TODAY()-Table43[[#This Row],[Efektif Naik Harga]]<30,"Naik","Sama") -> Sama | BI6: =IF(Table43[[#This Row],[Kode BARANG Win2]]<>"","IDR","") | BJ6: =CONCATENATE(Table43[[#This Row],[kode 1 Digit (Nomor)]],Table43[[#This Row],[kode 4 Digit (Nomor)]]) | BK6: =Table43[[#This Row],[Nama Gramasi atau Jumlah Pack per CTN]] -> 0 | BN6: =IF(Table43[[#This Row],[SATUAN Fix Win]]<>"","KRT") -> KRT | BO6: =IF(Table43[[#This Row],[SATUAN Fix Win]]<>"","GD01") -> GD01 | BP6: =IF(Table43[[#This Row],[SATUAN Fix Win]]<>"",11611) -> 11611 | BQ6: =IF(Table43[[#This Row],[SATUAN Fix Win]]<>"",11612) -> 11612 | BS6: =IF(Table43[[#This Row],[SATUAN Fix Win]]<>"",1) -> 1 | BU6: =Table43[[#This Row],[ISI/CTN]] -> 0
A7: =CONCATENATE(Table43[[#This Row],[Kode BARANG Win2]],Table43[[#This Row],[No. Urut Item Sama]]) | K7: =Table43[[#This Row],[NamaJenisKemasan]] -> 0 | L7: =TRIM(CONCATENATE(Table43[[#This Row],[Nama KLP]]," ",Table43[[#This Row],[Nama Sub KLP]])) | M7: =CONCATENATE(Table43[[#This Row],[kode 2 Digit (hrf+No)]],Table43[[#This Row],[kode 2 Digit (Nomor)]],Table43[[#This Row],[kode 1 Digit (Nomor)]]) | N7: =IF(AI7="",CONCATENATE(S7,U7,W7,Y7,AA7,AC7,AE7,AG7,Table43[[#This Row],[Tanda Kode Revisi]]),CONCATENATE(S7,U7,W7,Y7,AA7,AC7,AE7,AI7)) | O7: =LEN(N7) -> 0 | P7: =IF(AH7<>"",TRIM(UPPER(CONCATENATE(R7," ",T7," ",V7," ",X7," ",Z7," ",AB7," ","X"," ",Table43[[#This Row],[ISI/CTN]]," ",AH7," ",AD7," ",AF7," ",AJ7))),TRIM(UPPER(CONCATENATE(R7," ",T7," ",V7," ",X7," ",Z7," ",AB7," ","X"," ",Table43[[#This Row],[ISI/CTN]]," ",AD7," ",AF7," ",AJ7)))) -> X | Q7: =LEN(P7) -> 1 | AK7: =Table43[[#This Row],[Column4]] -> 0 | AN7: =Table43[[#This Row],[ISI/CTN]] -> 0 | AO7: =Table43[[#This Row],[Harga Jual Pcs GT (-PPN)]]-(Table43[[#This Row],[Harga Jual Pcs GT (-PPN)]]*6.5%) -> 0 | AP7: =Table43[[#This Row],[Harga Beli Pcs (-PPN)]]*Table43[[#This Row],[ISI/CTN]] -> 0 | AQ7: =Table43[[#This Row],[Harga Beli Pcs (-PPN)]]*1.11 -> 0 | AR7: =Table43[[#This Row],[Harga Beli Krt (- PPN)]]*1.11 -> 0 | AT7: =Table43[[#This Row],[Harga Jual Pcs GT (-PPN)]]*Table43[[#This Row],[ISI/CTN]] -> 0 | AU7: =Table43[[#This Row],[Harga Jual Pcs GT (-PPN)]]*1.11 -> 0 | AV7: =Table43[[#This Row],[Harga Jual Krt GT (- PPN)]]*1.11 -> 0 | AW7: =IFERROR(VLOOKUP(Table43[[#This Row],[Kode Pcpl]],'[1]FEB 2026'!$A$3:$X$312,24,0),0) -> 0 | AX7: =Table43[[#This Row],[Harga Jual Pcs MT (-PPN)]]*Table43[[#This Row],[ISI/CTN]] -> 0 | AY7: =Table43[[#This Row],[Harga Jual Pcs MT (-PPN)]]*1.11 -> 0 | AZ7: =Table43[[#This Row],[Harga Jual Pcs MT (+PPN)]]*Table43[[#This Row],[ISI/CTN]] -> 0 | BA7: =(Table43[[#This Row],[Harga Jual Pcs GT (-PPN)]]-Table43[[#This Row],[Harga Beli Pcs (-PPN)]])/Table43[[#This Row],[Harga Jual Pcs GT (-PPN)]] -> #DIV/0! | BB7: =Table43[[#This Row],[Harga Jual Pcs MT (-PPN)]]-Table43[[#This Row],[Harga Beli Pcs (-PPN)]] -> 0 | BC7: =Table43[[#This Row],[Column1]]/Table43[[#This Row],[Harga Jual Pcs MT (-PPN)]] -> #DIV/0! | BF7: =IF(TODAY()-Table43[[#This Row],[Efektif Pembuatan]]>60,"Lama","Baru") -> Lama | BG7: =IF(TODAY()-Table43[[#This Row],[Efektif Naik Harga]]<30,"Naik","Sama") -> Sama | BI7: =IF(Table43[[#This Row],[Kode BARANG Win2]]<>"","IDR","") | BJ7: =CONCATENATE(Table43[[#This Row],[kode 1 Digit (Nomor)]],Table43[[#This Row],[kode 4 Digit (Nomor)]]) | BK7: =Table43[[#This Row],[Nama Gramasi atau Jumlah Pack per CTN]] -> 0 | BN7: =IF(Table43[[#This Row],[SATUAN Fix Win]]<>"","KRT") -> KRT | BO7: =IF(Table43[[#This Row],[SATUAN Fix Win]]<>"","GD01") -> GD01 | BP7: =IF(Table43[[#This Row],[SATUAN Fix Win]]<>"",11611) -> 11611 | BQ7: =IF(Table43[[#This Row],[SATUAN Fix Win]]<>"",11612) -> 11612 | BS7: =IF(Table43[[#This Row],[SATUAN Fix Win]]<>"",1) -> 1 | BU7: =Table43[[#This Row],[ISI/CTN]] -> 0
A8: =CONCATENATE(Table43[[#This Row],[Kode BARANG Win2]],Table43[[#This Row],[No. Urut Item Sama]]) -> G1011000001510 | C8: 30010010015000 | D8: 40008216 | E8: AUTOSOL METAL POLISH 144 TUBE X 15GR 8216 AS01 | F8: 30010010015000 | G8: 0 | H8: AUTOSOL Metal Polish 15 gr | I8: 144 | J8: 8992745730101 | K8: =Table43[[#This Row],[NamaJenisKemasan]] -> TUBE | L8: =TRIM(CONCATENATE(Table43[[#This Row],[Nama KLP]]," ",Table43[[#This Row],[Nama Sub KLP]])) -> AUTOSOL METAL POLISH | M8: =CONCATENATE(Table43[[#This Row],[kode 2 Digit (hrf+No)]],Table43[[#This Row],[kode 2 Digit (Nomor)]],Table43[[#This Row],[kode 1 Digit (Nomor)]]) -> G1011 | N8: =IF(AI8="",CONCATENATE(S8,U8,W8,Y8,AA8,AC8,AE8,AG8,Table43[[#This Row],[Tanda Kode Revisi]]),CONCATENATE(S8,U8,W8,Y8,AA8,AC8,AE8,AI8)) -> G1011000001510 | O8: =LEN(N8) -> 14 | P8: =IF(AH8<>"",TRIM(UPPER(CONCATENATE(R8," ",T8," ",V8," ",X8," ",Z8," ",AB8," ","X"," ",Table43[[#This Row],[ISI/CTN]]," ",AH8," ",AD8," ",AF8," ",AJ8))),TRIM(UPPER(CONCATENATE(R8," ",T8," ",V8," ",X8," ",Z8," ",AB8," ","X"," ",Table43[[#This Row],[ISI/CTN]]," ",AD8," ",AF8," ",AJ8)))) -> AUTOSOL METAL POLISH 15GR X 144 TUBE | Q8: =LEN(P8) -> 36 | S8: G1 | T8: AUTOSOL | U8: 01 | V8: METAL POLISH | W8: 1 | Y8: 0 | AA8: 00 | AB8: 15GR | AC8: 0015 | AD8: TUBE | AE8: 1 | AG8: 0 | AK8: =Table43[[#This Row],[Column4]] -> 30010010015000 | AN8: =Table43[[#This Row],[ISI/CTN]] -> 144 | AO8: =Table43[[#This Row],[Harga Jual Pcs GT (-PPN)]]-(Table43[[#This Row],[Harga Jual Pcs GT (-PPN)]]*6.5%) -> 9452.85 | AP8: =Table43[[#This Row],[Harga Beli Pcs (-PPN)]]*Table43[[#This Row],[ISI/CTN]] -> 1361210.4 | AQ8: =Table43[[#This Row],[Harga Beli Pcs (-PPN)]]*1.11 -> 10492.664 | AR8: =Table43[[#This Row],[Harga Beli Krt (- PPN)]]*1.11 -> 1510943.5 | AS8: 10110 | AT8: =Table43[[#This Row],[Harga Jual Pcs GT (-PPN)]]*Table43[[#This Row],[ISI/CTN]] -> 1455840 | AU8: =Table43[[#This Row],[Harga Jual Pcs GT (-PPN)]]*1.11 -> 11222.1 | AV8: =Table43[[#This Row],[Harga Jual Krt GT (- PPN)]]*1.11 -> 1615982.4 | AW8: =IFERROR(VLOOKUP(Table43[[#This Row],[Kode Pcpl]],'[1]FEB 2026'!$A$3:$X$312,24,0),0) -> 0 | AX8: =Table43[[#This Row],[Harga Jual Pcs MT (-PPN)]]*Table43[[#This Row],[ISI/CTN]] -> 0 | AY8: =Table43[[#This Row],[Harga Jual Pcs MT (-PPN)]]*1.11 -> 0 | AZ8: =Table43[[#This Row],[Harga Jual Pcs MT (+PPN)]]*Table43[[#This Row],[ISI/CTN]] -> 0 | BA8: =(Table43[[#This Row],[Harga Jual Pcs GT (-PPN)]]-Table43[[#This Row],[Harga Beli Pcs (-PPN)]])/Table43[[#This Row],[Harga Jual Pcs GT (-PPN)]] -> 0.065 | BB8: =Table43[[#This Row],[Harga Jual Pcs MT (-PPN)]]-Table43[[#This Row],[Harga Beli Pcs (-PPN)]] -> -9452.85 | BC8: =Table43[[#This Row],[Column1]]/Table43[[#This Row],[Harga Jual Pcs MT (-PPN)]] -> #DIV/0! | BF8: =IF(TODAY()-Table43[[#This Row],[Efektif Pembuatan]]>60,"Lama","Baru") -> Lama | BG8: =IF(TODAY()-Table43[[#This Row],[Efektif Naik Harga]]<30,"Naik","Sama") -> Sama | BI8: =IF(Table43[[#This Row],[Kode BARANG Win2]]<>"","IDR","") -> IDR | BJ8: =CONCATENATE(Table43[[#This Row],[kode 1 Digit (Nomor)]],Table43[[#This Row],[kode 4 Digit (Nomor)]]) -> 0015 | BK8: =Table43[[#This Row],[Nama Gramasi atau Jumlah Pack per CTN]] -> 15GR | BN8: =IF(Table43[[#This Row],[SATUAN Fix Win]]<>"","KRT") -> KRT | BO8: =IF(Table43[[#This Row],[SATUAN Fix Win]]<>"","GD01") -> GD01 | BP8: =IF(Table43[[#This Row],[SATUAN Fix Win]]<>"",11611) -> 11611 | BQ8: =IF(Table43[[#This Row],[SATUAN Fix Win]]<>"",11612) -> 11612 | BS8: =IF(Table43[[#This Row],[SATUAN Fix Win]]<>"",1) -> 1 | BU8: =Table43[[#This Row],[ISI/CTN]] -> 144
A9: =CONCATENATE(Table43[[#This Row],[Kode BARANG Win2]],Table43[[#This Row],[No. Urut Item Sama]]) -> G1011000005010 | C9: 30010010050000 | D9: 40008217 | E9: AUTOSOL METAL POLISH 48 TUBE X 50GR 8217 AS02 | F9: 30010010050000 | G9: 0 | H9: AUTOSOL Metal Polish 50 gr | I9: 48 | J9: 8992745730200 | K9: =Table43[[#This Row],[NamaJenisKemasan]] -> TUBE | L9: =TRIM(CONCATENATE(Table43[[#This Row],[Nama KLP]]," ",Table43[[#This Row],[Nama Sub KLP]])) -> AUTOSOL METAL POLISH | M9: =CONCATENATE(Table43[[#This Row],[kode 2 Digit (hrf+No)]],Table43[[#This Row],[kode 2 Digit (Nomor)]],Table43[[#This Row],[kode 1 Digit (Nomor)]]) -> G1011 | N9: =IF(AI9="",CONCATENATE(S9,U9,W9,Y9,AA9,AC9,AE9,AG9,Table43[[#This Row],[Tanda Kode Revisi]]),CONCATENATE(S9,U9,W9,Y9,AA9,AC9,AE9,AI9)) -> G1011000005010 | O9: =LEN(N9) -> 14 | P9: =IF(AH9<>"",TRIM(UPPER(CONCATENATE(R9," ",T9," ",V9," ",X9," ",Z9," ",AB9," ","X"," ",Table43[[#This Row],[ISI/CTN]]," ",AH9," ",AD9," ",AF9," ",AJ9))),TRIM(UPPER(CONCATENATE(R9," ",T9," ",V9," ",X9," ",Z9," ",AB9," ","X"," ",Table43[[#This Row],[ISI/CTN]]," ",AD9," ",AF9," ",AJ9)))) -> AUTOSOL METAL POLISH 50GR X 48 TUBE | Q9: =LEN(P9) -> 35 | S9: G1 | T9: AUTOSOL | U9: 01 | V9: METAL POLISH | W9: 1 | Y9: 0 | AA9: 00 | AB9: 50GR | AC9: 0050 | AD9: TUBE | AE9: 1 | AG9: 0 | AK9: =Table43[[#This Row],[Column4]] -> 30010010050000 | AN9: =Table43[[#This Row],[ISI/CTN]] -> 48 | AO9: =Table43[[#This Row],[Harga Jual Pcs GT (-PPN)]]-(Table43[[#This Row],[Harga Jual Pcs GT (-PPN)]]*6.5%) -> 18391.45 | AP9: =Table43[[#This Row],[Harga Beli Pcs (-PPN)]]*Table43[[#This Row],[ISI/CTN]] -> 882789.6 | AQ9: =Table43[[#This Row],[Harga Beli Pcs (-PPN)]]*1.11 -> 20414.51 | AR9: =Table43[[#This Row],[Harga Beli Krt (- PPN)]]*1.11 -> 979896.46 | AS9: 19670 | AT9: =Table43[[#This Row],[Harga Jual Pcs GT (-PPN)]]*Table43[[#This Row],[ISI/CTN]] -> 944160 | AU9: =Table43[[#This Row],[Harga Jual Pcs GT (-PPN)]]*1.11 -> 21833.7 | AV9: =Table43[[#This Row],[Harga Jual Krt GT (- PPN)]]*1.11 -> 1048017.6 | AW9: =IFERROR(VLOOKUP(Table43[[#This Row],[Kode Pcpl]],'[1]FEB 2026'!$A$3:$X$312,24,0),0) -> 0 | AX9: =Table43[[#This Row],[Harga Jual Pcs MT (-PPN)]]*Table43[[#This Row],[ISI/CTN]] -> 0 | AY9: =Table43[[#This Row],[Harga Jual Pcs MT (-PPN)]]*1.11 -> 0 | AZ9: =Table43[[#This Row],[Harga Jual Pcs MT (+PPN)]]*Table43[[#This Row],[ISI/CTN]] -> 0 | BA9: =(Table43[[#This Row],[Harga Jual Pcs GT (-PPN)]]-Table43[[#This Row],[Harga Beli Pcs (-PPN)]])/Table43[[#This Row],[Harga Jual Pcs GT (-PPN)]] -> 0.065 | BB9: =Table43[[#This Row],[Harga Jual Pcs MT (-PPN)]]-Table43[[#This Row],[Harga Beli Pcs (-PPN)]] -> -18391.45 | BC9: =Table43[[#This Row],[Column1]]/Table43[[#This Row],[Harga Jual Pcs MT (-PPN)]] -> #DIV/0! | BF9: =IF(TODAY()-Table43[[#This Row],[Efektif Pembuatan]]>60,"Lama","Baru") -> Lama | BG9: =IF(TODAY()-Table43[[#This Row],[Efektif Naik Harga]]<30,"Naik","Sama") -> Sama | BI9: =IF(Table43[[#This Row],[Kode BARANG Win2]]<>"","IDR","") -> IDR | BJ9: =CONCATENATE(Table43[[#This Row],[kode 1 Digit (Nomor)]],Table43[[#This Row],[kode 4 Digit (Nomor)]]) -> 0050 | BK9: =Table43[[#This Row],[Nama Gramasi atau Jumlah Pack per CTN]] -> 50GR | BN9: =IF(Table43[[#This Row],[SATUAN Fix Win]]<>"","KRT") -> KRT | BO9: =IF(Table43[[#This Row],[SATUAN Fix Win]]<>"","GD01") -> GD01 | BP9: =IF(Table43[[#This Row],[SATUAN Fix Win]]<>"",11611) -> 11611 | BQ9: =IF(Table43[[#This Row],[SATUAN Fix Win]]<>"",11612) -> 11612 | BS9: =IF(Table43[[#This Row],[SATUAN Fix Win]]<>"",1) -> 1 | BU9: =Table43[[#This Row],[ISI/CTN]] -> 48
A10: =CONCATENATE(Table43[[#This Row],[Kode BARANG Win2]],Table43[[#This Row],[No. Urut Item Sama]]) -> G1020000002010 | C10: 30020000700000 | D10: 40014370 | E10: BIOSOL 144 SCH X 20ML 14370 35630 BS01 | F10: 30020000020000 | G10: 0 | H10: BIOSOL SACHET 20 ML+5 ML | I10: 144 | J10: 8992745540892 | K10: =Table43[[#This Row],[NamaJenisKemasan]] -> SCH | L10: =TRIM(CONCATENATE(Table43[[#This Row],[Nama KLP]]," ",Table43[[#This Row],[Nama Sub KLP]])) -> BIOSOL | M10: =CONCATENATE(Table43[[#This Row],[kode 2 Digit (hrf+No)]],Table43[[#This Row],[kode 2 Digit (Nomor)]],Table43[[#This Row],[kode 1 Digit (Nomor)]]) -> G1020 | N10: =IF(AI10="",CONCATENATE(S10,U10,W10,Y10,AA10,AC10,AE10,AG10,Table43[[#This Row],[Tanda Kode Revisi]]),CONCATENATE(S10,U10,W10,Y10,AA10,AC10,AE10,AI10)) -> G1020000002010 | O10: =LEN(N10) -> 14 | P10: =IF(AH10<>"",TRIM(UPPER(CONCATENATE(R10," ",T10," ",V10," ",X10," ",Z10," ",AB10," ","X"," ",Table43[[#This Row],[ISI/CTN]]," ",AH10," ",AD10," ",AF10," ",AJ10))),TRIM(UPPER(CONCATENATE(R10," ",T10," ",V10," ",X10," ",Z10," ",AB10," ","X"," ",Table43[[#This Row],[ISI/CTN]]," ",AD10," ",AF10," ",AJ10)))) -> BIOSOL 20ML X 144 SCH | Q10: =LEN(P10) -> 21 | S10: G1 | T10: BIOSOL | U10: 02 | W10: 0 | Y10: 0 | AA10: 00 | AB10: 20ML | AC10: 0020 | AD10: SCH | AE10: 1 | AG10: 0 | AK10: =Table43[[#This Row],[Column4]] -> 30020000020000 | AN10: =Table43[[#This Row],[ISI/CTN]] -> 144 | AO10: =Table43[[#This Row],[Harga Jual Pcs GT (-PPN)]]-(Table43[[#This Row],[Harga Jual Pcs GT (-PPN)]]*6.5%) -> 317.9 | AP10: =Table43[[#This Row],[Harga Beli Pcs (-PPN)]]*Table43[[#This Row],[ISI/CTN]] -> 45777.6 | AQ10: =Table43[[#This Row],[Harga Beli Pcs (-PPN)]]*1.11 -> 352.869 | AR10: =Table43[[#This Row],[Harga Beli Krt (- PPN)]]*1.11 -> 50813.136 | AS10: 340 | AT10: =Table43[[#This Row],[Harga Jual Pcs GT (-PPN)]]*Table43[[#This Row],[ISI/CTN]] -> 48960 | AU10: =Table43[[#This Row],[Harga Jual Pcs GT (-PPN)]]*1.11 -> 377.4 | AV10: =Table43[[#This Row],[Harga Jual Krt GT (- PPN)]]*1.11 -> 54345.6 | AW10: =IFERROR(VLOOKUP(Table43[[#This Row],[Kode Pcpl]],'[1]FEB 2026'!$A$3:$X$312,24,0),0) -> 0 | AX10: =Table43[[#This Row],[Harga Jual Pcs MT (-PPN)]]*Table43[[#This Row],[ISI/CTN]] -> 0 | AY10: =Table43[[#This Row],[Harga Jual Pcs MT (-PPN)]]*1.11 -> 0 | AZ10: =Table43[[#This Row],[Harga Jual Pcs MT (+PPN)]]*Table43[[#This Row],[ISI/CTN]] -> 0 | BA10: =(Table43[[#This Row],[Harga Jual Pcs GT (-PPN)]]-Table43[[#This Row],[Harga Beli Pcs (-PPN)]])/Table43[[#This Row],[Harga Jual Pcs GT (-PPN)]] -> 0.065 | BB10: =Table43[[#This Row],[Harga Jual Pcs MT (-PPN)]]-Table43[[#This Row],[Harga Beli Pcs (-PPN)]] -> -317.9 | BC10: =Table43[[#This Row],[Column1]]/Table43[[#This Row],[Harga Jual Pcs MT (-PPN)]] -> #DIV/0! | BF10: =IF(TODAY()-Table43[[#This Row],[Efektif Pembuatan]]>60,"Lama","Baru") -> Lama | BG10: =IF(TODAY()-Table43[[#This Row],[Efektif Naik Harga]]<30,"Naik","Sama") -> Sama | BI10: =IF(Table43[[#This Row],[Kode BARANG Win2]]<>"","IDR","") -> IDR | BJ10: =CONCATENATE(Table43[[#This Row],[kode 1 Digit (Nomor)]],Table43[[#This Row],[kode 4 Digit (Nomor)]]) -> 0020 | BK10: =Table43[[#This Row],[Nama Gramasi atau Jumlah Pack per CTN]] -> 20ML | BN10: =IF(Table43[[#This Row],[SATUAN Fix Win]]<>"","KRT") -> KRT | BO10: =IF(Table43[[#This Row],[SATUAN Fix Win]]<>"","GD01") -> GD01 | BP10: =IF(Table43[[#This Row],[SATUAN Fix Win]]<>"",11611) -> 11611 | BQ10: =IF(Table43[[#This Row],[SATUAN Fix Win]]<>"",11612) -> 11612 | BS10: =IF(Table43[[#This Row],[SATUAN Fix Win]]<>"",1) -> 1 | BU10: =Table43[[#This Row],[ISI/CTN]] -> 144
A11: =CONCATENATE(Table43[[#This Row],[Kode BARANG Win2]],Table43[[#This Row],[No. Urut Item Sama]]) -> G1020000002010 | C11: 30020000700001 | D11: 40035630 | E11: BIOSOL 144 SCH X 20ML 14370 35630 BS01 | F11: 30020000020000 | G11: 0 | H11: BIOSOL SACHET 20 ML+5 ML PROMO 12+1 | I11: 144 | J11: 8992745540892 | K11: =Table43[[#This Row],[NamaJenisKemasan]] -> SCH | L11: =TRIM(CONCATENATE(Table43[[#This Row],[Nama KLP]]," ",Table43[[#This Row],[Nama Sub KLP]])) -> BIOSOL | M11: =CONCATENATE(Table43[[#This Row],[kode 2 Digit (hrf+No)]],Table43[[#This Row],[kode 2 Digit (Nomor)]],Table43[[#This Row],[kode 1 Digit (Nomor)]]) -> G1020 | N11: =IF(AI11="",CONCATENATE(S11,U11,W11,Y11,AA11,AC11,AE11,AG11,Table43[[#This Row],[Tanda Kode Revisi]]),CONCATENATE(S11,U11,W11,Y11,AA11,AC11,AE11,AI11)) -> G1020000002010 | O11: =LEN(N11) -> 14 | P11: =IF(AH11<>"",TRIM(UPPER(CONCATENATE(R11," ",T11," ",V11," ",X11," ",Z11," ",AB11," ","X"," ",Table43[[#This Row],[ISI/CTN]]," ",AH11," ",AD11," ",AF11," ",AJ11))),TRIM(UPPER(CONCATENATE(R11," ",T11," ",V11," ",X11," ",Z11," ",AB11," ","X"," ",Table43[[#This Row],[ISI/CTN]]," ",AD11," ",AF11," ",AJ11)))) -> BIOSOL 20ML X 144 SCH | Q11: =LEN(P11) -> 21 | S11: G1 | T11: BIOSOL | U11: 02 | W11: 0 | Y11: 0 | AA11: 00 | AB11: 20ML | AC11: 0020 | AD11: SCH | AE11: 1 | AG11: 0 | AK11: =Table43[[#This Row],[Column4]] -> 30020000020000 | AN11: =Table43[[#This Row],[ISI/CTN]] -> 144 | AO11: =Table43[[#This Row],[Harga Jual Pcs GT (-PPN)]]-(Table43[[#This Row],[Harga Jual Pcs GT (-PPN)]]*6.5%) -> 317.9 | AP11: =Table43[[#This Row],[Harga Beli Pcs (-PPN)]]*Table43[[#This Row],[ISI/CTN]] -> 45777.6 | AQ11: =Table43[[#This Row],[Harga Beli Pcs (-PPN)]]*1.11 -> 352.869 | AR11: =Table43[[#This Row],[Harga Beli Krt (- PPN)]]*1.11 -> 50813.136 | AS11: 340 | AT11: =Table43[[#This Row],[Harga Jual Pcs GT (-PPN)]]*Table43[[#This Row],[ISI/CTN]] -> 48960 | AU11: =Table43[[#This Row],[Harga Jual Pcs GT (-PPN)]]*1.11 -> 377.4 | AV11: =Table43[[#This Row],[Harga Jual Krt GT (- PPN)]]*1.11 -> 54345.6 | AW11: =IFERROR(VLOOKUP(Table43[[#This Row],[Kode Pcpl]],'[1]FEB 2026'!$A$3:$X$312,24,0),0) -> 0 | AX11: =Table43[[#This Row],[Harga Jual Pcs MT (-PPN)]]*Table43[[#This Row],[ISI/CTN]] -> 0 | AY11: =Table43[[#This Row],[Harga Jual Pcs MT (-PPN)]]*1.11 -> 0 | AZ11: =Table43[[#This Row],[Harga Jual Pcs MT (+PPN)]]*Table43[[#This Row],[ISI/CTN]] -> 0 | BA11: =(Table43[[#This Row],[Harga Jual Pcs GT (-PPN)]]-Table43[[#This Row],[Harga Beli Pcs (-PPN)]])/Table43[[#This Row],[Harga Jual Pcs GT (-PPN)]] -> 0.065 | BB11: =Table43[[#This Row],[Harga Jual Pcs MT (-PPN)]]-Table43[[#This Row],[Harga Beli Pcs (-PPN)]] -> -317.9 | BC11: =Table43[[#This Row],[Column1]]/Table43[[#This Row],[Harga Jual Pcs MT (-PPN)]] -> #DIV/0! | BF11: =IF(TODAY()-Table43[[#This Row],[Efektif Pembuatan]]>60,"Lama","Baru") -> Lama | BG11: =IF(TODAY()-Table43[[#This Row],[Efektif Naik Harga]]<30,"Naik","Sama") -> Sama | BI11: =IF(Table43[[#This Row],[Kode BARANG Win2]]<>"","IDR","") -> IDR | BJ11: =CONCATENATE(Table43[[#This Row],[kode 1 Digit (Nomor)]],Table43[[#This Row],[kode 4 Digit (Nomor)]]) -> 0020 | BK11: =Table43[[#This Row],[Nama Gramasi atau Jumlah Pack per CTN]] -> 20ML | BN11: =IF(Table43[[#This Row],[SATUAN Fix Win]]<>"","KRT") -> KRT | BO11: =IF(Table43[[#This Row],[SATUAN Fix Win]]<>"","GD01") -> GD01 | BP11: =IF(Table43[[#This Row],[SATUAN Fix Win]]<>"",11611) -> 11611 | BQ11: =IF(Table43[[#This Row],[SATUAN Fix Win]]<>"",11612) -> 11612 | BS11: =IF(Table43[[#This Row],[SATUAN Fix Win]]<>"",1) -> 1 | BU11: =Table43[[#This Row],[ISI/CTN]] -> 144
A12: =CONCATENATE(Table43[[#This Row],[Kode BARANG Win2]],Table43[[#This Row],[No. Urut Item Sama]]) -> G1020000040020 | C12: 30020000020000 | D12: 40008247 | E12: BIOSOL 12 POUCH X 400ML 8247 BS02 | F12: 30020000400000 | G12: 0 | H12: BIOSOL POUCH 400 ML | I12: 12 | J12: 8992745730118 | K12: =Table43[[#This Row],[NamaJenisKemasan]] -> PCH | L12: =TRIM(CONCATENATE(Table43[[#This Row],[Nama KLP]]," ",Table43[[#This Row],[Nama Sub KLP]])) -> BIOSOL | M12: =CONCATENATE(Table43[[#This Row],[kode 2 Digit (hrf+No)]],Table43[[#This Row],[kode 2 Digit (Nomor)]],Table43[[#This Row],[kode 1 Digit (Nomor)]]) -> G1020 | N12: =IF(AI12="",CONCATENATE(S12,U12,W12,Y12,AA12,AC12,AE12,AG12,Table43[[#This Row],[Tanda Kode Revisi]]),CONCATENATE(S12,U12,W12,Y12,AA12,AC12,AE12,AI12)) -> G1020000040020 | O12: =LEN(N12) -> 14 | P12: =IF(AH12<>"",TRIM(UPPER(CONCATENATE(R12," ",T12," ",V12," ",X12," ",Z12," ",AB12," ","X"," ",Table43[[#This Row],[ISI/CTN]]," ",AH12," ",AD12," ",AF12," ",AJ12))),TRIM(UPPER(CONCATENATE(R12," ",T12," ",V12," ",X12," ",Z12," ",AB12," ","X"," ",Table43[[#This Row],[ISI/CTN]]," ",AD12," ",AF12," ",AJ12)))) -> BIOSOL 400ML X 12 PCH | Q12: =LEN(P12) -> 21 | S12: G1 | T12: BIOSOL | U12: 02 | W12: 0 | Y12: 0 | AA12: 00 | AB12: 400ML | AC12: 0400 | AD12: PCH | AE12: 2 | AG12: 0 | AK12: =Table43[[#This Row],[Column4]] -> 30020000400000 | AN12: =Table43[[#This Row],[ISI/CTN]] -> 12 | AO12: =Table43[[#This Row],[Harga Jual Pcs GT (-PPN)]]-(Table43[[#This Row],[Harga Jual Pcs GT (-PPN)]]*6.5%) -> 8078.4 | AP12: =Table43[[#This Row],[Harga Beli Pcs (-PPN)]]*Table43[[#This Row],[ISI/CTN]] -> 96940.8 | AQ12: =Table43[[#This Row],[Harga Beli Pcs (-PPN)]]*1.11 -> 8967.024 | AR12: =Table43[[#This Row],[Harga Beli Krt (- PPN)]]*1.11 -> 107604.29 | AS12: 8640 | AT12: =Table43[[#This Row],[Harga Jual Pcs GT (-PPN)]]*Table43[[#This Row],[ISI/CTN]] -> 103680 | AU12: =Table43[[#This Row],[Harga Jual Pcs GT (-PPN)]]*1.11 -> 9590.4 | AV12: =Table43[[#This Row],[Harga Jual Krt GT (- PPN)]]*1.11 -> 115084.8 | AW12: =IFERROR(VLOOKUP(Table43[[#This Row],[Kode Pcpl]],'[1]FEB 2026'!$A$3:$X$312,24,0),0) -> 0 | AX12: =Table43[[#This Row],[Harga Jual Pcs MT (-PPN)]]*Table43[[#This Row],[ISI/CTN]] -> 0 | AY12: =Table43[[#This Row],[Harga Jual Pcs MT (-PPN)]]*1.11 -> 0 | AZ12: =Table43[[#This Row],[Harga Jual Pcs MT (+PPN)]]*Table43[[#This Row],[ISI/CTN]] -> 0 | BA12: =(Table43[[#This Row],[Harga Jual Pcs GT (-PPN)]]-Table43[[#This Row],[Harga Beli Pcs (-PPN)]])/Table43[[#This Row],[Harga Jual Pcs GT (-PPN)]] -> 0.065 | BB12: =Table43[[#This Row],[Harga Jual Pcs MT (-PPN)]]-Table43[[#This Row],[Harga Beli Pcs (-PPN)]] -> -8078.4 | BC12: =Table43[[#This Row],[Column1]]/Table43[[#This Row],[Harga Jual Pcs MT (-PPN)]] -> #DIV/0! | BF12: =IF(TODAY()-Table43[[#This Row],[Efektif Pembuatan]]>60,"Lama","Baru") -> Lama | BG12: =IF(TODAY()-Table43[[#This Row],[Efektif Naik Harga]]<30,"Naik","Sama") -> Sama | BI12: =IF(Table43[[#This Row],[Kode BARANG Win2]]<>"","IDR","") -> IDR | BJ12: =CONCATENATE(Table43[[#This Row],[kode 1 Digit (Nomor)]],Table43[[#This Row],[kode 4 Digit (Nomor)]]) -> 0400 | BK12: =Table43[[#This Row],[Nama Gramasi atau Jumlah Pack per CTN]] -> 400ML | BN12: =IF(Table43[[#This Row],[SATUAN Fix Win]]<>"","KRT") -> KRT | BO12: =IF(Table43[[#This Row],[SATUAN Fix Win]]<>"","GD01") -> GD01 | BP12: =IF(Table43[[#This Row],[SATUAN Fix Win]]<>"",11611) -> 11611 | BQ12: =IF(Table43[[#This Row],[SATUAN Fix Win]]<>"",11612) -> 11612 | BS12: =IF(Table43[[#This Row],[SATUAN Fix Win]]<>"",1) -> 1 | BU12: =Table43[[#This Row],[ISI/CTN]] -> 12
A13: =CONCATENATE(Table43[[#This Row],[Kode BARANG Win2]],Table43[[#This Row],[No. Urut Item Sama]]) -> G1020000040021 | C13: 30020000020000 | D13: 40056288 | E13: BIOSOL 6 POUCH X 400ML BANDED 56288 BS04 | F13: 30020000400001 | G13: 0 | H13: BIOSOL POUCH 400 ML BUY 1 GET 1 | I13: 6 | J13: 8992745730118 | K13: =Table43[[#This Row],[NamaJenisKemasan]] -> PCH | L13: =TRIM(CONCATENATE(Table43[[#This Row],[Nama KLP]]," ",Table43[[#This Row],[Nama Sub KLP]])) -> BIOSOL | M13: =CONCATENATE(Table43[[#This Row],[kode 2 Digit (hrf+No)]],Table43[[#This Row],[kode 2 Digit (Nomor)]],Table43[[#This Row],[kode 1 Digit (Nomor)]]) -> G1020 | N13: =IF(AI13="",CONCATENATE(S13,U13,W13,Y13,AA13,AC13,AE13,AG13,Table43[[#This Row],[Tanda Kode Revisi]]),CONCATENATE(S13,U13,W13,Y13,AA13,AC13,AE13,AI13)) -> G1020000040021 | O13: =LEN(N13) -> 14 | P13: =IF(AH13<>"",TRIM(UPPER(CONCATENATE(R13," ",T13," ",V13," ",X13," ",Z13," ",AB13," ","X"," ",Table43[[#This Row],[ISI/CTN]]," ",AH13," ",AD13," ",AF13," ",AJ13))),TRIM(UPPER(CONCATENATE(R13," ",T13," ",V13," ",X13," ",Z13," ",AB13," ","X"," ",Table43[[#This Row],[ISI/CTN]]," ",AD13," ",AF13," ",AJ13)))) -> BIOSOL 400ML X 6 PCH BOGOF | Q13: =LEN(P13) -> 26 | S13: G1 | T13: BIOSOL | U13: 02 | W13: 0 | Y13: 0 | AA13: 00 | AB13: 400ML | AC13: 0400 | AD13: PCH | AE13: 2 | AF13: BOGOF | AG13: 1 | AK13: =Table43[[#This Row],[Column4]] -> 30020000400001 | AN13: =Table43[[#This Row],[ISI/CTN]] -> 6 | AO13: =Table43[[#This Row],[Harga Jual Pcs GT (-PPN)]]-(Table43[[#This Row],[Harga Jual Pcs GT (-PPN)]]*6.5%) -> 9069.5 | AP13: =Table43[[#This Row],[Harga Beli Pcs (-PPN)]]*Table43[[#This Row],[ISI/CTN]] -> 54417 | AQ13: =Table43[[#This Row],[Harga Beli Pcs (-PPN)]]*1.11 -> 10067.145 | AR13: =Table43[[#This Row],[Harga Beli Krt (- PPN)]]*1.11 -> 60402.87 | AS13: 9700 | AT13: =Table43[[#This Row],[Harga Jual Pcs GT (-PPN)]]*Table43[[#This Row],[ISI/CTN]] -> 58200 | AU13: =Table43[[#This Row],[Harga Jual Pcs GT (-PPN)]]*1.11 -> 10767 | AV13: =Table43[[#This Row],[Harga Jual Krt GT (- PPN)]]*1.11 -> 64602 | AW13: =IFERROR(VLOOKUP(Table43[[#This Row],[Kode Pcpl]],'[1]FEB 2026'!$A$3:$X$312,24,0),0) -> 0 | AX13: =Table43[[#This Row],[Harga Jual Pcs MT (-PPN)]]*Table43[[#This Row],[ISI/CTN]] -> 0 | AY13: =Table43[[#This Row],[Harga Jual Pcs MT (-PPN)]]*1.11 -> 0 | AZ13: =Table43[[#This Row],[Harga Jual Pcs MT (+PPN)]]*Table43[[#This Row],[ISI/CTN]] -> 0 | BA13: =(Table43[[#This Row],[Harga Jual Pcs GT (-PPN)]]-Table43[[#This Row],[Harga Beli Pcs (-PPN)]])/Table43[[#This Row],[Harga Jual Pcs GT (-PPN)]] -> 0.065 | BB13: =Table43[[#This Row],[Harga Jual Pcs MT (-PPN)]]-Table43[[#This Row],[Harga Beli Pcs (-PPN)]] -> -9069.5 | BC13: =Table43[[#This Row],[Column1]]/Table43[[#This Row],[Harga Jual Pcs MT (-PPN)]] -> #DIV/0! | BF13: =IF(TODAY()-Table43[[#This Row],[Efektif Pembuatan]]>60,"Lama","Baru") -> Lama | BG13: =IF(TODAY()-Table43[[#This Row],[Efektif Naik Harga]]<30,"Naik","Sama") -> Sama | BI13: =IF(Table43[[#This Row],[Kode BARANG Win2]]<>"","IDR","") -> IDR | BJ13: =CONCATENATE(Table43[[#This Row],[kode 1 Digit (Nomor)]],Table43[[#This Row],[kode 4 Digit (Nomor)]]) -> 0400 | BK13: =Table43[[#This Row],[Nama Gramasi atau Jumlah Pack per CTN]] -> 400ML | BN13: =IF(Table43[[#This Row],[SATUAN Fix Win]]<>"","KRT") -> KRT | BO13: =IF(Table43[[#This Row],[SATUAN Fix Win]]<>"","GD01") -> GD01 | BP13: =IF(Table43[[#This Row],[SATUAN Fix Win]]<>"",11611) -> 11611 | BQ13: =IF(Table43[[#This Row],[SATUAN Fix Win]]<>"",11612) -> 11612 | BS13: =IF(Table43[[#This Row],[SATUAN Fix Win]]<>"",1) -> 1 | BU13: =Table43[[#This Row],[ISI/CTN]] -> 6
A14: =CONCATENATE(Table43[[#This Row],[Kode BARANG Win2]],Table43[[#This Row],[No. Urut Item Sama]]) -> G1020000070020 | C14: 30020000400001 | D14: 40013979 | E14: BIOSOL 12 POUCH X 700ML 13979 BS03 | F14: 30020000700000 | G14: 0 | H14: BIOSOL POUCH REGULAR 700ML | I14: 12 | J14: 8992745730217 | K14: =Table43[[#This Row],[NamaJenisKemasan]] -> PCH | L14: =TRIM(CONCATENATE(Table43[[#This Row],[Nama KLP]]," ",Table43[[#This Row],[Nama Sub KLP]])) -> BIOSOL | M14: =CONCATENATE(Table43[[#This Row],[kode 2 Digit (hrf+No)]],Table43[[#This Row],[kode 2 Digit (Nomor)]],Table43[[#This Row],[kode 1 Digit (Nomor)]]) -> G1020 | N14: =IF(AI14="",CONCATENATE(S14,U14,W14,Y14,AA14,AC14,AE14,AG14,Table43[[#This Row],[Tanda Kode Revisi]]),CONCATENATE(S14,U14,W14,Y14,AA14,AC14,AE14,AI14)) -> G1020000070020 | O14: =LEN(N14) -> 14 | P14: =IF(AH14<>"",TRIM(UPPER(CONCATENATE(R14," ",T14," ",V14," ",X14," ",Z14," ",AB14," ","X"," ",Table43[[#This Row],[ISI/CTN]]," ",AH14," ",AD14," ",AF14," ",AJ14))),TRIM(UPPER(CONCATENATE(R14," ",T14," ",V14," ",X14," ",Z14," ",AB14," ","X"," ",Table43[[#This Row],[ISI/CTN]]," ",AD14," ",AF14," ",AJ14)))) -> BIOSOL 700ML X 12 PCH | Q14: =LEN(P14) -> 21 | S14: G1 | T14: BIOSOL | U14: 02 | W14: 0 | Y14: 0 | AA14: 00 | AB14: 700ML | AC14: 0700 | AD14: PCH | AE14: 2 | AG14: 0 | AK14: =Table43[[#This Row],[Column4]] -> 30020000700000 | AN14: =Table43[[#This Row],[ISI/CTN]] -> 12 | AO14: =Table43[[#This Row],[Harga Jual Pcs GT (-PPN)]]-(Table43[[#This Row],[Harga Jual Pcs GT (-PPN)]]*6.5%) -> 13430.34 | AP14: =Table43[[#This Row],[Harga Beli Pcs (-PPN)]]*Table43[[#This Row],[ISI/CTN]] -> 161164.08 | AQ14: =Table43[[#This Row],[Harga Beli Pcs (-PPN)]]*1.11 -> 14907.677 | AR14: =Table43[[#This Row],[Harga Beli Krt (- PPN)]]*1.11 -> 178892.13 | AS14: 14364 | AT14: =Table43[[#This Row],[Harga Jual Pcs GT (-PPN)]]*Table43[[#This Row],[ISI/CTN]] -> 172368 | AU14: =Table43[[#This Row],[Harga Jual Pcs GT (-PPN)]]*1.11 -> 15944.04 | AV14: =Table43[[#This Row],[Harga Jual Krt GT (- PPN)]]*1.11 -> 191328.48 | AW14: =IFERROR(VLOOKUP(Table43[[#This Row],[Kode Pcpl]],'[1]FEB 2026'!$A$3:$X$312,24,0),0) -> 0 | AX14: =Table43[[#This Row],[Harga Jual Pcs MT (-PPN)]]*Table43[[#This Row],[ISI/CTN]] -> 0 | AY14: =Table43[[#This Row],[Harga Jual Pcs MT (-PPN)]]*1.11 -> 0 | AZ14: =Table43[[#This Row],[Harga Jual Pcs MT (+PPN)]]*Table43[[#This Row],[ISI/CTN]] -> 0 | BA14: =(Table43[[#This Row],[Harga Jual Pcs GT (-PPN)]]-Table43[[#This Row],[Harga Beli Pcs (-PPN)]])/Table43[[#This Row],[Harga Jual Pcs GT (-PPN)]] -> 0.065 | BB14: =Table43[[#This Row],[Harga Jual Pcs MT (-PPN)]]-Table43[[#This Row],[Harga Beli Pcs (-PPN)]] -> -13430.34 | BC14: =Table43[[#This Row],[Column1]]/Table43[[#This Row],[Harga Jual Pcs MT (-PPN)]] -> #DIV/0! | BF14: =IF(TODAY()-Table43[[#This Row],[Efektif Pembuatan]]>60,"Lama","Baru") -> Lama | BG14: =IF(TODAY()-Table43[[#This Row],[Efektif Naik Harga]]<30,"Naik","Sama") -> Sama | BI14: =IF(Table43[[#This Row],[Kode BARANG Win2]]<>"","IDR","") -> IDR | BJ14: =CONCATENATE(Table43[[#This Row],[kode 1 Digit (Nomor)]],Table43[[#This Row],[kode 4 Digit (Nomor)]]) -> 0700 | BK14: =Table43[[#This Row],[Nama Gramasi atau Jumlah Pack per CTN]] -> 700ML | BN14: =IF(Table43[[#This Row],[SATUAN Fix Win]]<>"","KRT") -> KRT | BO14: =IF(Table43[[#This Row],[SATUAN Fix Win]]<>"","GD01") -> GD01 | BP14: =IF(Table43[[#This Row],[SATUAN Fix Win]]<>"",11611) -> 11611 | BQ14: =IF(Table43[[#This Row],[SATUAN Fix Win]]<>"",11612) -> 11612 | BS14: =IF(Table43[[#This Row],[SATUAN Fix Win]]<>"",1) -> 1 | BU14: =Table43[[#This Row],[ISI/CTN]] -> 12
A15: =CONCATENATE(Table43[[#This Row],[Kode BARANG Win2]],Table43[[#This Row],[No. Urut Item Sama]]) -> G1020000070021 | C15: 30020000400000 | D15: 40056289 | E15: BIOSOL 6 PCH X 700ML BANDED 56289 BS05 | F15: 30020000700001 | G15: 0 | H15: BIOSOL POUCH 700 ML BUY 1 GET 1 | I15: 6 | J15: 8992745730217 | K15: =Table43[[#This Row],[NamaJenisKemasan]] -> PCH | L15: =TRIM(CONCATENATE(Table43[[#This Row],[Nama KLP]]," ",Table43[[#This Row],[Nama Sub KLP]])) -> BIOSOL | M15: =CONCATENATE(Table43[[#This Row],[kode 2 Digit (hrf+No)]],Table43[[#This Row],[kode 2 Digit (Nomor)]],Table43[[#This Row],[kode 1 Digit (Nomor)]]) -> G1020 | N15: =IF(AI15="",CONCATENATE(S15,U15,W15,Y15,AA15,AC15,AE15,AG15,Table43[[#This Row],[Tanda Kode Revisi]]),CONCATENATE(S15,U15,W15,Y15,AA15,AC15,AE15,AI15)) -> G1020000070021 | O15: =LEN(N15) -> 14 | P15: =IF(AH15<>"",TRIM(UPPER(CONCATENATE(R15," ",T15," ",V15," ",X15," ",Z15," ",AB15," ","X"," ",Table43[[#This Row],[ISI/CTN]]," ",AH15," ",AD15," ",AF15," ",AJ15))),TRIM(UPPER(CONCATENATE(R15," ",T15," ",V15," ",X15," ",Z15," ",AB15," ","X"," ",Table43[[#This Row],[ISI/CTN]]," ",AD15," ",AF15," ",AJ15)))) -> BIOSOL 700ML X 6 PCH BOGOF | Q15: =LEN(P15) -> 26 | S15: G1 | T15: BIOSOL | U15: 02 | W15: 0 | Y15: 0 | AA15: 00 | AB15: 700ML | AC15: 0700 | AD15: PCH | AE15: 2 | AF15: BOGOF | AG15: 1 | AK15: =Table43[[#This Row],[Column4]] -> 30020000700001 | AN15: =Table43[[#This Row],[ISI/CTN]] -> 6 | AO15: =Table43[[#This Row],[Harga Jual Pcs GT (-PPN)]]-(Table43[[#This Row],[Harga Jual Pcs GT (-PPN)]]*6.5%) -> 15081.55 | AP15: =Table43[[#This Row],[Harga Beli Pcs (-PPN)]]*Table43[[#This Row],[ISI/CTN]] -> 90489.3 | AQ15: =Table43[[#This Row],[Harga Beli Pcs (-PPN)]]*1.11 -> 16740.521 | AR15: =Table43[[#This Row],[Harga Beli Krt (- PPN)]]*1.11 -> 100443.12 | AS15: 16130 | AT15: =Table43[[#This Row],[Harga Jual Pcs GT (-PPN)]]*Table43[[#This Row],[ISI/CTN]] -> 96780 | AU15: =Table43[[#This Row],[Harga Jual Pcs GT (-PPN)]]*1.11 -> 17904.3 | AV15: =Table43[[#This Row],[Harga Jual Krt GT (- PPN)]]*1.11 -> 107425.8 | AW15: =IFERROR(VLOOKUP(Table43[[#This Row],[Kode Pcpl]],'[1]FEB 2026'!$A$3:$X$312,24,0),0) -> 0 | AX15: =Table43[[#This Row],[Harga Jual Pcs MT (-PPN)]]*Table43[[#This Row],[ISI/CTN]] -> 0 | AY15: =Table43[[#This Row],[Harga Jual Pcs MT (-PPN)]]*1.11 -> 0 | AZ15: =Table43[[#This Row],[Harga Jual Pcs MT (+PPN)]]*Table43[[#This Row],[ISI/CTN]] -> 0 | BA15: =(Table43[[#This Row],[Harga Jual Pcs GT (-PPN)]]-Table43[[#This Row],[Harga Beli Pcs (-PPN)]])/Table43[[#This Row],[Harga Jual Pcs GT (-PPN)]] -> 0.065 | BB15: =Table43[[#This Row],[Harga Jual Pcs MT (-PPN)]]-Table43[[#This Row],[Harga Beli Pcs (-PPN)]] -> -15081.55 | BC15: =Table43[[#This Row],[Column1]]/Table43[[#This Row],[Harga Jual Pcs MT (-PPN)]] -> #DIV/0! | BF15: =IF(TODAY()-Table43[[#This Row],[Efektif Pembuatan]]>60,"Lama","Baru") -> Lama | BG15: =IF(TODAY()-Table43[[#This Row],[Efektif Naik Harga]]<30,"Naik","Sama") -> Sama | BI15: =IF(Table43[[#This Row],[Kode BARANG Win2]]<>"","IDR","") -> IDR | BJ15: =CONCATENATE(Table43[[#This Row],[kode 1 Digit (Nomor)]],Table43[[#This Row],[kode 4 Digit (Nomor)]]) -> 0700 | BK15: =Table43[[#This Row],[Nama Gramasi atau Jumlah Pack per CTN]] -> 700ML | BN15: =IF(Table43[[#This Row],[SATUAN Fix Win]]<>"","KRT") -> KRT | BO15: =IF(Table43[[#This Row],[SATUAN Fix Win]]<>"","GD01") -> GD01 | BP15: =IF(Table43[[#This Row],[SATUAN Fix Win]]<>"",11611) -> 11611 | BQ15: =IF(Table43[[#This Row],[SATUAN Fix Win]]<>"",11612) -> 11612 | BS15: =IF(Table43[[#This Row],[SATUAN Fix Win]]<>"",1) -> 1 | BU15: =Table43[[#This Row],[ISI/CTN]] -> 6
