Workbook
Name Consol: "Error"

Sheet PRICE LIST Motasa
A3: KELOMPOK PRODUK | B3: KODE PRODUK PRINSIPAL | C3: NAMA ITEM | D3: ISI/CTN | E3: SATUAN | F3: HARGA INCLUDE PPN 11% IN CTN | G3: HARGA/PCS | H3: Column1 | I3: Column2 | J3: Column3
A4: LADAKU | B4: 1106FG-LDK33 | C4: LADAKU SACHET | D4: 576 | E4: SACHET | F4: 460000 | G4: =F4/D4 -> 798.61111 | H4: 419287 | I4: =Table3[[#This Row],[Column1]]/Table3[[#This Row],[ISI/CTN]] -> 727.92882 | J4: =Table3[[#This Row],[Column2]]/1.11 -> 655.79173
A5: DESAKU SPICES | B5: 1106FG-DSK07 | C5: DESAKU KETUMBAR BUBUK | D5: 192 | E5: SACHET | F5: 156000 | G5: =F5/D5 -> 812.5 | H5: 142193 | I5: =Table3[[#This Row],[Column1]]/Table3[[#This Row],[ISI/CTN]] -> 740.58854 | J5: =Table3[[#This Row],[Column2]]/1.11 -> 667.19688
A6: DESAKU SPICES | B6: 1106FG-DKU02 | C6: DESAKU KUNYIT BUBUK | D6: 432 | E6: SACHET | F6: 351000 | G6: =F6/D6 -> 812.5 | H6: 319934 | I6: =Table3[[#This Row],[Column1]]/Table3[[#This Row],[ISI/CTN]] -> 740.58796 | J6: =Table3[[#This Row],[Column2]]/1.11 -> 667.19636
A7: DESAKU SPICES | B7: 1106FG-DCB02 | C7: DESAKU CABE BUBUK | D7: 120 | E7: SACHET | F7: 234000 | G7: =F7/D7 -> 1950 | H7: 213289 | I7: =Table3[[#This Row],[Column1]]/Table3[[#This Row],[ISI/CTN]] -> 1777.4083 | J7: =Table3[[#This Row],[Column2]]/1.11 -> 1601.2688
A8: DESAKU SPICES | B8: 1106FG-DBP01 | C8: DESAKU BAWANG PUTIH | D8: 432 | E8: SACHET | F8: 351000 | G8: =F8/D8 -> 812.5 | H8: 319934 | I8: =Table3[[#This Row],[Column1]]/Table3[[#This Row],[ISI/CTN]] -> 740.58796 | J8: =Table3[[#This Row],[Column2]]/1.11 -> 667.19636
A9: DESAKU SPICES | B9: 1106FG-DMR01 | C9: DESAKU MARINASI | D9: 432 | E9: SACHET | F9: 351000 | G9: =F9/D9 -> 812.5 | H9: 319934 | I9: =Table3[[#This Row],[Column1]]/Table3[[#This Row],[ISI/CTN]] -> 740.58796 | J9: =Table3[[#This Row],[Column2]]/1.11 -> 667.19636
A10: DESAKU SEASONING | B10: 1106FG-DBL01 | C10: DESAKU BALADO | D10: 120 | E10: SACHET | F10: 216000 | G10: =F10/D10 -> 1800 | H10: 196882 | I10: =Table3[[#This Row],[Column1]]/Table3[[#This Row],[ISI/CTN]] -> 1640.6833 | J10: =Table3[[#This Row],[Column2]]/1.11 -> 1478.0931
A11: DESAKU SEASONING | B11: 1106FG-DKR01 | C11: DESAKU KARI NUSANTARA | D11: 120 | E11: SACHET | F11: 216000 | G11: =F11/D11 -> 1800 | H11: 196882 | I11: =Table3[[#This Row],[Column1]]/Table3[[#This Row],[ISI/CTN]] -> 1640.6833 | J11: =Table3[[#This Row],[Column2]]/1.11 -> 1478.0931
A12: DESAKU SEASONING | B12: 1106FG-DSG02 | C12: DESAKU SAMBAL GORENG | D12: 120 | E12: SACHET | F12: 216000 | G12: =F12/D12 -> 1800 | H12: 196882 | I12: =Table3[[#This Row],[Column1]]/Table3[[#This Row],[ISI/CTN]] -> 1640.6833 | J12: =Table3[[#This Row],[Column2]]/1.11 -> 1478.0931
A13: DESAKU SEASONING | B13: 1106FG-DGL01 | C13: DESAKU GULAI PADANG | D13: 120 | E13: SACHET | F13: 216000 | G13: =F13/D13 -> 1800 | H13: 196882 | I13: =Table3[[#This Row],[Column1]]/Table3[[#This Row],[ISI/CTN]] -> 1640.6833 | J13: =Table3[[#This Row],[Column2]]/1.11 -> 1478.0931
A14: DESAKU SEASONING | B14: 1106FG-DSO01 | C14: DESAKU OPOR | D14: 120 | E14: SACHET | F14: 216000 | G14: =F14/D14 -> 1800 | H14: 196882 | I14: =Table3[[#This Row],[Column1]]/Table3[[#This Row],[ISI/CTN]] -> 1640.6833 | J14: =Table3[[#This Row],[Column2]]/1.11 -> 1478.0931

Sheet FORM DASAR KLP
A3: KODE PRODUK PRINSIPAL | B3: KELOMPOK PRODUK By Principle | C3: NAMA ITEM | D3: ISI/CTN | E3: SATUAN | F3: HARGA INCLUDE PPN 11% IN CTN | G3: HARGA/PCS
A4: 1106FG-LDK33 | B4: LADAKU | C4: LADAKU SACHET | D4: 576 | E4: SACHET | F4: 460000 | G4: 798.61111 | I4: 8 | J4: 6 | K4: 12 | L4: =I4*J4*K4 -> 576
A5: 1106FG-DSK07 | B5: DESAKU SPICES | C5: DESAKU KETUMBAR BUBUK | D5: 192 | E5: SACHET | F5: 156000 | G5: 812.5 | I5: 8 | J5: 2 | K5: 12 | L5: =I5*J5*K5 -> 192
A6: 1106FG-DKU02 | B6: DESAKU SPICES | C6: DESAKU KUNYIT BUBUK | D6: 432 | E6: SACHET | F6: 351000 | G6: 812.5 | I6: 18 | J6: 2 | K6: 12 | L6: =I6*J6*K6 -> 432
A7: 1106FG-DCB02 | B7: DESAKU SPICES | C7: DESAKU CABE BUBUK | D7: 120 | E7: SACHET | F7: 234000 | G7: 1950 | I7: 12 | J7: 1 | K7: 10 | L7: =I7*J7*K7 -> 120
A8: 1106FG-DBP01 | B8: DESAKU SPICES | C8: DESAKU BAWANG PUTIH | D8: 432 | E8: SACHET | F8: 351000 | G8: 812.5 | I8: 36 | J8: 1 | K8: 12 | L8: =I8*J8*K8 -> 432
A9: 1106FG-DMR01 | B9: DESAKU SPICES | C9: DESAKU MARINASI | D9: 432 | E9: SACHET | F9: 351000 | G9: 812.5 | I9: 36 | J9: 1 | K9: 12 | L9: =I9*J9*K9 -> 432
A10: 1106FG-DBL01 | B10: DESAKU SEASONING | C10: DESAKU BALADO | D10: 120 | E10: SACHET | F10: 216000 | G10: 1800 | I10: 12 | J10: 1 | K10: 10 | L10: =I10*J10*K10 -> 120
A11: 1106FG-DKR01 | B11: DESAKU SEASONING | C11: DESAKU KARI NUSANTARA | D11: 120 | E11: SACHET | F11: 216000 | G11: 1800 | I11: 12 | J11: 1 | K11: 10 | L11: =I11*J11*K11 -> 120
A12: 1106FG-DSG02 | B12: DESAKU SEASONING | C12: DESAKU SAMBAL GORENG | D12: 120 | E12: SACHET | F12: 216000 | G12: 1800 | I12: 12 | J12: 1 | K12: 10 | L12: =I12*J12*K12 -> 120
A13: 1106FG-DGL01 | B13: DESAKU SEASONING | C13: DESAKU GULAI PADANG | D13: 120 | E13: SACHET | F13: 216000 | G13: 1800 | I13: 12 | J13: 1 | K13: 10 | L13: =I13*J13*K13 -> 120
A14: 1106FG-DSO01 | B14: DESAKU SEASONING | C14: DESAKU OPOR | D14: 120 | E14: SACHET | F14: 216000 | G14: 1800 | I14: 12 | J14: 1 | K14: 10 | L14: =I14*J14*K14 -> 120
G187: =F187/D187 -> #DIV/0!
G188: =F188/D188 -> #DIV/0!
G189: =F189/D189 -> #DIV/0!
G190: =F190/D190 -> #DIV/0!
G191: =F191/D191 -> #DIV/0!
G192: =F192/D192 -> #DIV/0!
G193: =F193/D193 -> #DIV/0!
G194: =F194/D194 -> #DIV/0!
G195: =F195/D195 -> #DIV/0!
G196: =F196/D196 -> #DIV/0!
G197: =F197/D197 -> #DIV/0!
G198: =F198/D198 -> #DIV/0!
... G1082: =F1082/D1082 -> #DIV/0!

Sheet Cara Buat
A3: 1 | B3: Sortir Daftar Produk Principle sesuai Nama lalu sortir lagi by kelompok | D3: 1 | E3: Buat satu folder master barang, master kelompok, price list, mapping produk win to pcpl dan mapping produk pcpl to win
A4: 2 | B4: Copy dan Paste kan ke Sheet Form Master (sesuaikan kolom nya) | D4: 2 | E4: Master barang, master kelompok, price list, mapping produk win to pcpl dan mapping produk pcpl to win berdiri sendiri dalam satu book
A5: 3 | B5: Sheet kuning adalah rumus, jangan diganggu

Sheet Pvt Map 1
A3: Kode BARANG Win2 | B3: SATUAN Fix Win | C3: Kode Pcpl | D3: Ket. Tambahan / Pembantu | E3: ISI/CTN | F3: Sum of No. Urut Item Sama
A4: A1011001062010 | B4: BTL | C4: 100191 | D4: 7000003082 | E4: 12 | F4: 1
A5: A1011001062010 | B5: BTL | C5: 100191 | D5: 7000003792 | E5: 12 | F5: 2
A6: A1011001052010 | B6: PCH | C6: 100156 | D6: 7000003063 | E6: 12 | F6: 1
A7: A1011001052010 | B7: PCH | C7: (blank) | D7: 7000003778 | E7: 12
A8: A1011002052010 | B8: PCH | C8: 100180 | D8: 7000003075 | E8: 12 | F8: 1
A9: A1011003065010 | B9: PCH | C9: 100151 | D9: 0 | E9: 12 | F9: 1
A10: A1011004065010 | B10: PCH | C10: 100174 | D10: 0 | E10: 12 | F10: 1
A11: A1011005013510 | B11: BTL | C11: 100192 | D11: 7000003083 | E11: 48 | F11: 1
A12: A1011005013510 | B12: BTL | C12: 100201 | D12: 7000003090 | E12: 48 | F12: 2
A13: A1011006013520 | B13: BTL | C13: 100194 | D13: 7000003085 | E13: 48 | F13: 1
A14: A1011006013520 | B14: BTL | C14: 100203 | D14: 7000003092 | E14: 48 | F14: 2
A15: A1011006013520 | B15: BTL | C15: 100215 | D15: 7000003100 | E15: 48 | F15: 3
A16: A1011005027510 | B16: BTL | C16: 100193 | D16: 7000003084 | E16: 24 | F16: 1
A17: A1011005027510 | B17: BTL | C17: 100202 | D17: 7000003091 | E17: 24 | F17: 2
A18: A1011005027510 | B18: BTL | C18: 100231 | D18: 7000003109 | E18: 24 | F18: 3
A19: A1011006007510 | B19: PCH | C19: 100204 | D19: 7000003093 | E19: 48 | F19: 1
A20: A1011000006210 | B20: PCH | C20: 100189 | D20: 7000003080 | E20: 48 | F20: 1
A21: A1011000006210 | B21: PCH | C21: 100222 | D21: 7000003102 | E21: 48 | F21: 2
A22: A1011000006210 | B22: PCH | C22: 100240 | D22: 7000003116 | E22: 48 | F22: 3
A23: A1011000006211 | B23: PCH | C23: 100986 | D23: 7000003134 | E23: 48 | F23: 1
A24: A1011000008010 | B24: PCH | C24: 100179 | D24: 0 | E24: 48 | F24: 1
A25: A1011000030010 | B25: PCH | C25: 100158 | D25: 7000003064 | E25: 24 | F25: 1
A26: A1011000030010 | B26: PCH | C26: 100172 | D26: 7000003071 | E26: 24 | F26: 2
A27: A1011000025010 | B27: PCH | C27: 100220 | D27: 7000003101 | E27: 24 | F27: 1
A28: A1011000025010 | B28: PCH | C28: 100238 | D28: 7000003114 | E28: 24 | F28: 2
A29: A1011000068510 | B29: PCH | C29: 100165 | D29: 7000003067 | E29: 12 | F29: 2
A30: A1011000068510 | B30: PCH | C30: 100187 | D30: 0 | E30: 12 | F30: 1
A31: A1011000068512 | B31: PCH | C31: 100976 | D31: 0 | E31: 12 | F31: 1
A32: A1011000068512 | B32: PCH | C32: 100981 | D32: 0 | E32: 12 | F32: 2
A33: A1011000060010 | B33: PCH | C33: 100225 | D33: 7000003104 | E33: 12 | F33: 1
A34: A1011000060010 | B34: PCH | C34: 100242 | D34: 7000003118 | E34: 12 | F34: 2
A35: A1011000092510 | B35: PCH | C35: 100176 | D35: 7000003072 | E35: 12 | F35: 1
A36: A1011000092510 | B36: PCH | C36: 100188 | D36: 7000003079 | E36: 12 | F36: 2
A37: A1011000082510 | B37: PCH | C37: 100221 | D37: 0 | E37: 12 | F37: 1
A38: A1011000082510 | B38: PCH | C38: 100252 | D38: 7000003121 | E38: 12 | F38: 2
A39: A1011000082510 | B39: PCH | C39: 100239 | D39: 7000003115 | E39: 12 | F39: 3
A40: A1011000082510 | B40: PCH | C40: 100267 | D40: 7000003125 | E40: 12 | F40: 4
A41: A1011000102510 | B41: JRG | C41: 100181 | D41: 7000003076 | E41: 1 | F41: 1
A42: A1011000102510 | B42: JRG | C42: 100228 | D42: 7000003107 | E42: 1 | F42: 2
...

Sheet Table Pvt 1
A1: Kode Barang Win | B1: Kode Pcpl | C1: SATUAN Fix Win | D1: ISI/CTN | E1: Kode PCPL yang sama
A2: A1011001062010 | B2: 100191 | C2: BTL | D2: 12 | E2: 1
A3: A1011001062010 | B3: 100191 | C3: BTL | D3: 12 | E3: 2
A4: A1011001052010 | B4: 100156 | C4: PCH | D4: 12 | E4: 1
A5: A1011001052010 | B5: (blank) | C5: PCH | D5: 12
A6: A1011002052010 | B6: 100180 | C6: PCH | D6: 12 | E6: 1
A7: A1011003065010 | B7: 100151 | C7: PCH | D7: 12 | E7: 1
A8: A1011004065010 | B8: 100174 | C8: PCH | D8: 12 | E8: 1
A9: A1011005013510 | B9: 100192 | C9: BTL | D9: 48 | E9: 1
A10: A1011005013510 | B10: 100201 | C10: BTL | D10: 48 | E10: 2
A11: A1011006013520 | B11: 100194 | C11: BTL | D11: 48 | E11: 1
A12: A1011006013520 | B12: 100203 | C12: BTL | D12: 48 | E12: 2
A13: A1011006013520 | B13: 100215 | C13: BTL | D13: 48 | E13: 3
A14: A1011005027510 | B14: 100193 | C14: BTL | D14: 24 | E14: 1
A15: A1011005027510 | B15: 100202 | C15: BTL | D15: 24 | E15: 2
A16: A1011005027510 | B16: 100231 | C16: BTL | D16: 24 | E16: 3
A17: A1011006007510 | B17: 100204 | C17: PCH | D17: 48 | E17: 1
... A110: A1100001042510 | B110: 612042 | C110: KLG | D110: 24 | E110: 1
A111: A1100001042510 | B111: 612149 | C111: KLG | D111: 24
A112: A1100002015510 | B112: 612046 | C112: KLG | D112: 60 | E112: 1
A113: A1100002042510 | B113: 612043 | C113: KLG | D113: 24 | E113: 1
A114: A1100002042510 | B114: 612150 | C114: KLG | D114: 24 | E114: 1
A115: A1100003030010 | B115: 612141 | C115: KLG | D115: 24 | E115: 1
A116: A1100003030010 | B116: 612148 | C116: KLG | D116: 24 | E116: 2
A117: A1100003030010 | B117: 612155 | C117: KLG | D117: 24 | E117: 3
A118: A1100004015510 | B118: 612047 | C118: KLG | D118: 60 | E118: 1
A119: A1100004015510 | B119: 612154 | C119: KLG | D119: 60 | E119: 2
A120: A1100004042510 | B120: 612044 | C120: KLG | D120: 24 | E120: 1
A121: A1100004042510 | B121: 612151 | C121: KLG | D121: 24 | E121: 2
A122: A1100005015510 | B122: 612134 | C122: KLG | D122: 60 | E122: 1
A123: A1100005040010 | B123: 612091 | C123: KLG | D123: 24 | E123: 1
... A240: A1120008013010 | B240: 150374 | C240: BTL | D240: 48 | E240: 2
A241: A1120008013010 | B241: 150363 | C241: BTL | D241: 48
A242: A1120008013011 | B242: 150976 | C242: BTL | D242: 48 | E242: 1
A243: A1120008013510 | B243: 150191 | C243: BTL | D243: 48 | E243: 1
A244: A1120008013510 | B244: 150234 | C244: BTL | D244: 48 | E244: 2
A245: A1120008027010 | B245: 150192 | C245: BTL | D245: 24 | E245: 1
A246: A1120008027010 | B246: 150235 | C246: BTL | D246: 24 | E246: 2
A247: A1120008027010 | B247: 150350 | C247: BTL | D247: 24 | E247: 3
A248: A1120008027010 | B248: 150343 | C248: BTL | D248: 24 | E248: 4
...

Sheet Fix Mapping
A1: KODE BARANG | B1: NAMA BARANG | C1: ISI/CTN | D1: SATUAN | E1: NAMA KELOMPOK | F1: Harga Beli Pcs (-PPN) | G1: Harga Beli Krt (- PPN) | H1: Harga Beli Pcs (+PPN) | I1: Harga Beli Krt (+PPN) | J1: Harga Jual Pcs GT (-PPN) | K1: Harga Jual Krt GT (- PPN) | L1: Harga Jual Pcs GT (+PPN | M1: Harga Jual Krt GT (+PPN) | N1: Harga Jual Pcs MT (-PPN) | O1: Harga Jual Krt MT (- PPN) | P1: Harga Jual Pcs MT (+PPN) | Q1: Harga Jual Krt MT (+PPN) | R1: NAMA PRINCIPLE | S1: PCPL KODE 1 | T1: PCPL KODE 2 | U1: PCPL KODE 3 | V1: PCPL KODE 4 | W1: PCPL KODE 5
A2: A1011000006210 | B2: ABC KECAP MANIS 62 GR X 48 PCH | C2: 48 | D2: PCH | E2: KECAP MANIS | F2: 1354.9536 | G2: 65037.773 | H2: 1503.9985 | I2: 72191.928 | J2: 1441.44 | K2: 69189.12 | L2: 1599.9984 | M2: 76799.923 | N2: 1556.76 | O2: 74724.48 | P2: 1728.0036 | Q2: 82944.173 | R2: PT. HEINZ ABC INDONESIA | S2: =IFERROR(VLOOKUP(CONCATENATE(Fix_Mapping[[#This Row],[KODE BARANG]],1),'Form Fix'!$A$6:$F$1063,4,0),0) -> 100189 | T2: =IFERROR(VLOOKUP(CONCATENATE(Fix_Mapping[[#This Row],[KODE BARANG]],2),'Form Fix'!$A$6:$F$1063,4,0),0) -> 100222 | U2: =IFERROR(VLOOKUP(CONCATENATE(Fix_Mapping[[#This Row],[KODE BARANG]],3),'Form Fix'!$A$6:$F$1063,4,0),0) -> 100240 | V2: =IFERROR(VLOOKUP(CONCATENATE(Fix_Mapping[[#This Row],[KODE BARANG]],4),'Form Fix'!$A$6:$F$1063,4,0),0) -> 0 | W2: =IFERROR(VLOOKUP(CONCATENATE(Fix_Mapping[[#This Row],[KODE BARANG]],5),'Form Fix'!$A$6:$F$1063,4,0),0) -> 0
A3: A1011000006211 | B3: ABC KECAP MANIS 62 GR X 48 PCH B5G1 | C3: 48 | D3: PCH | E3: KECAP MANIS | F3: 1129.128 | G3: 54198.144 | H3: 1253.3321 | I3: 60159.94 | J3: 1201.2 | K3: 57657.6 | L3: 1333.332 | M3: 63999.936 | N3: 1297.3 | O3: 62270.4 | P3: 1440.003 | Q3: 69120.144 | R3: PT. HEINZ ABC INDONESIA | S3: =IFERROR(VLOOKUP(CONCATENATE(Fix_Mapping[[#This Row],[KODE BARANG]],1),'Form Fix'!$A$6:$F$1063,4,0),0) -> 100986 | T3: =IFERROR(VLOOKUP(CONCATENATE(Fix_Mapping[[#This Row],[KODE BARANG]],2),'Form Fix'!$A$6:$F$1063,4,0),0) -> 0 | U3: =IFERROR(VLOOKUP(CONCATENATE(Fix_Mapping[[#This Row],[KODE BARANG]],3),'Form Fix'!$A$6:$F$1063,4,0),0) -> 0 | V3: =IFERROR(VLOOKUP(CONCATENATE(Fix_Mapping[[#This Row],[KODE BARANG]],4),'Form Fix'!$A$6:$F$1063,4,0),0) -> 0 | W3: =IFERROR(VLOOKUP(CONCATENATE(Fix_Mapping[[#This Row],[KODE BARANG]],5),'Form Fix'!$A$6:$F$1063,4,0),0) -> 0
A4: A1011000008010 | B4: ABC KECAP MANIS 80 ML X 48 PCH | C4: 48 | D4: PCH | E4: KECAP MANIS | F4: 1990.0928 | G4: 95524.454 | H4: 2209.003 | I4: 106032.14 | J4: 2117.12 | K4: 101621.76 | L4: 2350.0032 | M4: 112800.15 | N4: 2286.4865 | O4: 109751.35 | P4: 2538 | Q4: 121824 | R4: PT. HEINZ ABC INDONESIA | S4: =IFERROR(VLOOKUP(CONCATENATE(Fix_Mapping[[#This Row],[KODE BARANG]],1),'Form Fix'!$A$6:$F$1063,4,0),0) -> 100179 | T4: =IFERROR(VLOOKUP(CONCATENATE(Fix_Mapping[[#This Row],[KODE BARANG]],2),'Form Fix'!$A$6:$F$1063,4,0),0) -> 0 | U4: =IFERROR(VLOOKUP(CONCATENATE(Fix_Mapping[[#This Row],[KODE BARANG]],3),'Form Fix'!$A$6:$F$1063,4,0),0) -> 0 | V4: =IFERROR(VLOOKUP(CONCATENATE(Fix_Mapping[[#This Row],[KODE BARANG]],4),'Form Fix'!$A$6:$F$1063,4,0),0) -> 0 | W4: =IFERROR(VLOOKUP(CONCATENATE(Fix_Mapping[[#This Row],[KODE BARANG]],5),'Form Fix'!$A$6:$F$1063,4,0),0) -> 0
A5: A1011000013010 | B5: ABC KECAP MANIS 135 ML X 48 BTL | C5: 48 | D5: BTL | E5: KECAP MANIS | F5: 6382.6 | G5: 306364.8 | H5: 7084.686 | I5: 340064.93 | J5: 6790 | K5: 325920 | L5: 7536.9 | M5: 361771.2 | N5: 0 | O5: 0 | P5: 0 | Q5: 0 | R5: PT. HEINZ ABC INDONESIA | S5: =IFERROR(VLOOKUP(CONCATENATE(Fix_Mapping[[#This Row],[KODE BARANG]],1),'Form Fix'!$A$6:$F$1063,4,0),0) -> 100234 | T5: =IFERROR(VLOOKUP(CONCATENATE(Fix_Mapping[[#This Row],[KODE BARANG]],2),'Form Fix'!$A$6:$F$1063,4,0),0) -> 0 | U5: =IFERROR(VLOOKUP(CONCATENATE(Fix_Mapping[[#This Row],[KODE BARANG]],3),'Form Fix'!$A$6:$F$1063,4,0),0) -> 0 | V5: =IFERROR(VLOOKUP(CONCATENATE(Fix_Mapping[[#This Row],[KODE BARANG]],4),'Form Fix'!$A$6:$F$1063,4,0),0) -> 0 | W5: =IFERROR(VLOOKUP(CONCATENATE(Fix_Mapping[[#This Row],[KODE BARANG]],5),'Form Fix'!$A$6:$F$1063,4,0),0) -> 0
A6: A1011000013510 | B6: ABC KECAP MANIS 135 ML X 48 BTL | C6: 48 | D6: BTL | E6: KECAP MANIS | F6: 7181.2616 | G6: 344700.56 | H6: 7971.2004 | I6: 382617.62 | J6: 7639.64 | K6: 366702.72 | L6: 8480.0004 | M6: 407040.02 | N6: 8250.81 | O6: 396038.88 | P6: 9158.3991 | Q6: 439603.16 | R6: PT. HEINZ ABC INDONESIA | S6: =IFERROR(VLOOKUP(CONCATENATE(Fix_Mapping[[#This Row],[KODE BARANG]],1),'Form Fix'!$A$6:$F$1063,4,0),0) -> 100161 | T6: =IFERROR(VLOOKUP(CONCATENATE(Fix_Mapping[[#This Row],[KODE BARANG]],2),'Form Fix'!$A$6:$F$1063,4,0),0) -> 0 | U6: =IFERROR(VLOOKUP(CONCATENATE(Fix_Mapping[[#This Row],[KODE BARANG]],3),'Form Fix'!$A$6:$F$1063,4,0),0) -> 0 | V6: =IFERROR(VLOOKUP(CONCATENATE(Fix_Mapping[[#This Row],[KODE BARANG]],4),'Form Fix'!$A$6:$F$1063,4,0),0) -> 0 | W6: =IFERROR(VLOOKUP(CONCATENATE(Fix_Mapping[[#This Row],[KODE BARANG]],5),'Form Fix'!$A$6:$F$1063,4,0),0) -> 0
A7: A1011000025010 | B7: ABC KECAP MANIS 250 GR X 24 PCH | C7: 24 | D7: PCH | E7: KECAP MANIS | F7: 6117.285 | G7: 146814.84 | H7: 6790.1864 | I7: 162964.47 | J7: 6507.75 | K7: 156186 | L7: 7223.6025 | M7: 173366.46 | N7: 7028.37 | O7: 168680.88 | P7: 7801.4907 | Q7: 187235.78 | R7: PT. HEINZ ABC INDONESIA | S7: =IFERROR(VLOOKUP(CONCATENATE(Fix_Mapping[[#This Row],[KODE BARANG]],1),'Form Fix'!$A$6:$F$1063,4,0),0) -> 100220 | T7: =IFERROR(VLOOKUP(CONCATENATE(Fix_Mapping[[#This Row],[KODE BARANG]],2),'Form Fix'!$A$6:$F$1063,4,0),0) -> 100238 | U7: =IFERROR(VLOOKUP(CONCATENATE(Fix_Mapping[[#This Row],[KODE BARANG]],3),'Form Fix'!$A$6:$F$1063,4,0),0) -> 0 | V7: =IFERROR(VLOOKUP(CONCATENATE(Fix_Mapping[[#This Row],[KODE BARANG]],4),'Form Fix'!$A$6:$F$1063,4,0),0) -> 0 | W7: =IFERROR(VLOOKUP(CONCATENATE(Fix_Mapping[[#This Row],[KODE BARANG]],5),'Form Fix'!$A$6:$F$1063,4,0),0) -> 0
A8: A1011000025011 | B8: ABC KECAP MANIS 250 GR X 24 PCH BANDED | C8: 24 | D8: PCH | E8: KECAP MANIS | F8: 6117.285 | G8: 146814.84 | H8: 6790.1864 | I8: 162964.47 | J8: 6507.75 | K8: 156186 | L8: 7223.6025 | M8: 173366.46 | N8: 7028.37 | O8: 168680.88 | P8: 7801.4907 | Q8: 187235.78 | R8: PT. HEINZ ABC INDONESIA | S8: =IFERROR(VLOOKUP(CONCATENATE(Fix_Mapping[[#This Row],[KODE BARANG]],1),'Form Fix'!$A$6:$F$1063,4,0),0) -> 100992 | T8: =IFERROR(VLOOKUP(CONCATENATE(Fix_Mapping[[#This Row],[KODE BARANG]],2),'Form Fix'!$A$6:$F$1063,4,0),0) -> 0 | U8: =IFERROR(VLOOKUP(CONCATENATE(Fix_Mapping[[#This Row],[KODE BARANG]],3),'Form Fix'!$A$6:$F$1063,4,0),0) -> 0 | V8: =IFERROR(VLOOKUP(CONCATENATE(Fix_Mapping[[#This Row],[KODE BARANG]],4),'Form Fix'!$A$6:$F$1063,4,0),0) -> 0 | W8: =IFERROR(VLOOKUP(CONCATENATE(Fix_Mapping[[#This Row],[KODE BARANG]],5),'Form Fix'!$A$6:$F$1063,4,0),0) -> 0
A9: A1011000027520 | B9: ABC KECAP MANIS 275 ML X 24 BTL | C9: 24 | D9: BTL | E9: KECAP MANIS | F9: 15649.731 | G9: 375593.54 | H9: 17371.201 | I9: 416908.83 | J9: 16648.65 | K9: 399567.6 | L9: 18480.002 | M9: 443520.04 | N9: 17980.54 | O9: 431532.96 | P9: 19958.399 | Q9: 479001.59 | R9: PT. HEINZ ABC INDONESIA | S9: =IFERROR(VLOOKUP(CONCATENATE(Fix_Mapping[[#This Row],[KODE BARANG]],1),'Form Fix'!$A$6:$F$1063,4,0),0) -> 100162 | T9: =IFERROR(VLOOKUP(CONCATENATE(Fix_Mapping[[#This Row],[KODE BARANG]],2),'Form Fix'!$A$6:$F$1063,4,0),0) -> 100236 | U9: =IFERROR(VLOOKUP(CONCATENATE(Fix_Mapping[[#This Row],[KODE BARANG]],3),'Form Fix'!$A$6:$F$1063,4,0),0) -> 0 | V9: =IFERROR(VLOOKUP(CONCATENATE(Fix_Mapping[[#This Row],[KODE BARANG]],4),'Form Fix'!$A$6:$F$1063,4,0),0) -> 0 | W9: =IFERROR(VLOOKUP(CONCATENATE(Fix_Mapping[[#This Row],[KODE BARANG]],5),'Form Fix'!$A$6:$F$1063,4,0),0) -> 0
A10: A1011000030010 | B10: ABC KECAP MANIS 300 GR X 24 PCH | C10: 24 | D10: PCH | E10: KECAP MANIS | F10: 8383.7848 | G10: 201210.84 | H10: 9306.0011 | I10: 223344.03 | J10: 8918.92 | K10: 214054.08 | L10: 9900.0012 | M10: 237600.03 | N10: 9632.43 | O10: 231178.32 | P10: 10691.997 | Q10: 256607.94 | R10: PT. HEINZ ABC INDONESIA | S10: =IFERROR(VLOOKUP(CONCATENATE(Fix_Mapping[[#This Row],[KODE BARANG]],1),'Form Fix'!$A$6:$F$1063,4,0),0) -> 100158 | T10: =IFERROR(VLOOKUP(CONCATENATE(Fix_Mapping[[#This Row],[KODE BARANG]],2),'Form Fix'!$A$6:$F$1063,4,0),0) -> 100172 | U10: =IFERROR(VLOOKUP(CONCATENATE(Fix_Mapping[[#This Row],[KODE BARANG]],3),'Form Fix'!$A$6:$F$1063,4,0),0) -> 0 | V10: =IFERROR(VLOOKUP(CONCATENATE(Fix_Mapping[[#This Row],[KODE BARANG]],4),'Form Fix'!$A$6:$F$1063,4,0),0) -> 0 | W10: =IFERROR(VLOOKUP(CONCATENATE(Fix_Mapping[[#This Row],[KODE BARANG]],5),'Form Fix'!$A$6:$F$1063,4,0),0) -> 0
A11: A1011000030012 | B11: ABC KECAP MANIS 600 GR X 12 PCH BANDED | C11: 12 | D11: PCH | E11: KECAP MANIS | F11: 16126.875 | G11: 193522.5 | H11: 17900.831 | I11: 214809.98 | J11: 17156.25 | K11: 205875 | L11: 19043.438 | M11: 228521.25 | N11: 0 | O11: 0 | P11: 0 | Q11: 0 | R11: PT. HEINZ ABC INDONESIA | S11: =IFERROR(VLOOKUP(CONCATENATE(Fix_Mapping[[#This Row],[KODE BARANG]],1),'Form Fix'!$A$6:$F$1063,4,0),0) -> 100991 | T11: =IFERROR(VLOOKUP(CONCATENATE(Fix_Mapping[[#This Row],[KODE BARANG]],2),'Form Fix'!$A$6:$F$1063,4,0),0) -> 109002 | U11: =IFERROR(VLOOKUP(CONCATENATE(Fix_Mapping[[#This Row],[KODE BARANG]],3),'Form Fix'!$A$6:$F$1063,4,0),0) -> 109001 | V11: =IFERROR(VLOOKUP(CONCATENATE(Fix_Mapping[[#This Row],[KODE BARANG]],4),'Form Fix'!$A$6:$F$1063,4,0),0) -> 0 | W11: =IFERROR(VLOOKUP(CONCATENATE(Fix_Mapping[[#This Row],[KODE BARANG]],5),'Form Fix'!$A$6:$F$1063,4,0),0) -> 0
A12: A1011000060010 | B12: ABC KECAP MANIS 600 GR X 12 PCH | C12: 12 | D12: PCH | E12: KECAP MANIS | F12: 16126.922 | G12: 193523.06 | H12: 17900.883 | I12: 214810.6 | J12: 17156.3 | K12: 205875.6 | L12: 19043.493 | M12: 228521.92 | N12: 18528.804 | O12: 222345.65 | P12: 20566.972 | Q12: 246803.67 | R12: PT. HEINZ ABC INDONESIA | S12: =IFERROR(VLOOKUP(CONCATENATE(Fix_Mapping[[#This Row],[KODE BARANG]],1),'Form Fix'!$A$6:$F$1063,4,0),0) -> 100225 | T12: =IFERROR(VLOOKUP(CONCATENATE(Fix_Mapping[[#This Row],[KODE BARANG]],2),'Form Fix'!$A$6:$F$1063,4,0),0) -> 100242 | U12: =IFERROR(VLOOKUP(CONCATENATE(Fix_Mapping[[#This Row],[KODE BARANG]],3),'Form Fix'!$A$6:$F$1063,4,0),0) -> 0 | V12: =IFERROR(VLOOKUP(CONCATENATE(Fix_Mapping[[#This Row],[KODE BARANG]],4),'Form Fix'!$A$6:$F$1063,4,0),0) -> 0 | W12: =IFERROR(VLOOKUP(CONCATENATE(Fix_Mapping[[#This Row],[KODE BARANG]],5),'Form Fix'!$A$6:$F$1063,4,0),0) -> 0
A13: A1011000060020 | B13: ABC KECAP MANIS 600 ML X 12 BTL | C13: 12 | D13: BTL | E13: KECAP MANIS | F13: 23525.408 | G13: 282304.9 | H13: 26113.203 | I13: 313358.44 | J13: 25027.03 | K13: 300324.36 | L13: 27780.003 | M13: 333360.04 | N13: 27029.19 | O13: 324350.28 | P13: 30002.401 | Q13: 360028.81 | R13: PT. HEINZ ABC INDONESIA | S13: =IFERROR(VLOOKUP(CONCATENATE(Fix_Mapping[[#This Row],[KODE BARANG]],1),'Form Fix'!$A$6:$F$1063,4,0),0) -> 100163 | T13: =IFERROR(VLOOKUP(CONCATENATE(Fix_Mapping[[#This Row],[KODE BARANG]],2),'Form Fix'!$A$6:$F$1063,4,0),0) -> 100226 | U13: =IFERROR(VLOOKUP(CONCATENATE(Fix_Mapping[[#This Row],[KODE BARANG]],3),'Form Fix'!$A$6:$F$1063,4,0),0) -> 0 | V13: =IFERROR(VLOOKUP(CONCATENATE(Fix_Mapping[[#This Row],[KODE BARANG]],4),'Form Fix'!$A$6:$F$1063,4,0),0) -> 0 | W13: =IFERROR(VLOOKUP(CONCATENATE(Fix_Mapping[[#This Row],[KODE BARANG]],5),'Form Fix'!$A$6:$F$1063,4,0),0) -> 0
... A44: A1020004019510 | B44: ABC SAUCE KCP INGGRIS 195 ML X 24 BTL | C44: 24 | D44: BTL | E44: SAUCE | F44: 10990.378 | G44: 263769.08 | H44: 12199.32 | I44: 292783.68 | J44: 11691.892 | K44: 280605.41 | L44: 12978 | M44: 311472 | N44: 12627.243 | O44: 303053.84 | P44: 14016.24 | Q44: 336389.76 | R44: PT. HEINZ ABC INDONESIA | S44: =IFERROR(VLOOKUP(CONCATENATE(Fix_Mapping[[#This Row],[KODE BARANG]],1),'Form Fix'!$A$6:$F$1063,4,0),0) -> 120028 | T44: =IFERROR(VLOOKUP(CONCATENATE(Fix_Mapping[[#This Row],[KODE BARANG]],2),'Form Fix'!$A$6:$F$1063,4,0),0) -> 120043 | U44: =IFERROR(VLOOKUP(CONCATENATE(Fix_Mapping[[#This Row],[KODE BARANG]],3),'Form Fix'!$A$6:$F$1063,4,0),0) -> 0 | V44: =IFERROR(VLOOKUP(CONCATENATE(Fix_Mapping[[#This Row],[KODE BARANG]],4),'Form Fix'!$A$6:$F$1063,4,0),0) -> 0 | W44: =IFERROR(VLOOKUP(CONCATENATE(Fix_Mapping[[#This Row],[KODE BARANG]],5),'Form Fix'!$A$6:$F$1063,4,0),0) -> 0
A45: A1020102001820 | B45: ABC SAUCE SACHET TIRAM 18GR X 12 PCSX10 | C45: 12 | D45: PCSX10 | E45: SAUCE | F45: 10824.57 | G45: 129894.84 | H45: 12015.273 | I45: 144183.27 | J45: 11515.5 | K45: 138186 | L45: 12782.205 | M45: 153386.46 | N45: 11515.5 | O45: 138186 | P45: 12782.205 | Q45: 153386.46 | S45: =IFERROR(VLOOKUP(CONCATENATE(Fix_Mapping[[#This Row],[KODE BARANG]],1),'Form Fix'!$A$6:$F$1063,4,0),0) -> 120045 | T45: =IFERROR(VLOOKUP(CONCATENATE(Fix_Mapping[[#This Row],[KODE BARANG]],2),'Form Fix'!$A$6:$F$1063,4,0),0) -> 0 | U45: =IFERROR(VLOOKUP(CONCATENATE(Fix_Mapping[[#This Row],[KODE BARANG]],3),'Form Fix'!$A$6:$F$1063,4,0),0) -> 0 | V45: =IFERROR(VLOOKUP(CONCATENATE(Fix_Mapping[[#This Row],[KODE BARANG]],4),'Form Fix'!$A$6:$F$1063,4,0),0) -> 0 | W45: =IFERROR(VLOOKUP(CONCATENATE(Fix_Mapping[[#This Row],[KODE BARANG]],5),'Form Fix'!$A$6:$F$1063,4,0),0) -> 0
A46: A1030100000310 | B46: ABC TERASI SACHET 3,8 GR X 36 PACK PCSX20 | C46: 36 | D46: PCSX20 | E46: TERASI | F46: 5922.5928 | G46: 213213.34 | H46: 6574.078 | I46: 236666.81 | J46: 6300.6306 | K46: 226822.7 | L46: 6993.7 | M46: 251773.2 | N46: 6615.6622 | O46: 238163.84 | P46: 7343.385 | Q46: 264361.86 | R46: PT. HEINZ ABC INDONESIA | S46: =IFERROR(VLOOKUP(CONCATENATE(Fix_Mapping[[#This Row],[KODE BARANG]],1),'Form Fix'!$A$6:$F$1063,4,0),0) -> 612087 | T46: =IFERROR(VLOOKUP(CONCATENATE(Fix_Mapping[[#This Row],[KODE BARANG]],2),'Form Fix'!$A$6:$F$1063,4,0),0) -> 612137 | U46: =IFERROR(VLOOKUP(CONCATENATE(Fix_Mapping[[#This Row],[KODE BARANG]],3),'Form Fix'!$A$6:$F$1063,4,0),0) -> 612147 | V46: =IFERROR(VLOOKUP(CONCATENATE(Fix_Mapping[[#This Row],[KODE BARANG]],4),'Form Fix'!$A$6:$F$1063,4,0),0) -> 0 | W46: =IFERROR(VLOOKUP(CONCATENATE(Fix_Mapping[[#This Row],[KODE BARANG]],5),'Form Fix'!$A$6:$F$1063,4,0),0) -> 0
A47: A1041001009010 | B47: ABC MR JUSSIE MILKY GRAPE 90 ML X 48 PCS | C47: 48 | D47: PCS | E47: MR JUSSIE MILKY | F47: 1351.9926 | G47: 64895.645 | H47: 1500.7118 | I47: 72034.166 | J47: 1438.29 | K47: 69037.92 | L47: 1596.5019 | M47: 76632.091 | N47: 1510.2 | O47: 72489.6 | P47: 1676.322 | Q47: 80463.456 | R47: PT. HEINZ ABC INDONESIA | S47: =IFERROR(VLOOKUP(CONCATENATE(Fix_Mapping[[#This Row],[KODE BARANG]],1),'Form Fix'!$A$6:$F$1063,4,0),0) -> 460166 | T47: =IFERROR(VLOOKUP(CONCATENATE(Fix_Mapping[[#This Row],[KODE BARANG]],2),'Form Fix'!$A$6:$F$1063,4,0),0) -> 0 | U47: =IFERROR(VLOOKUP(CONCATENATE(Fix_Mapping[[#This Row],[KODE BARANG]],3),'Form Fix'!$A$6:$F$1063,4,0),0) -> 0 | V47: =IFERROR(VLOOKUP(CONCATENATE(Fix_Mapping[[#This Row],[KODE BARANG]],4),'Form Fix'!$A$6:$F$1063,4,0),0) -> 0 | W47: =IFERROR(VLOOKUP(CONCATENATE(Fix_Mapping[[#This Row],[KODE BARANG]],5),'Form Fix'!$A$6:$F$1063,4,0),0) -> 0
A48: A1041002009010 | B48: ABC MR JUSSIE MILKY STRAWBERRY 90 ML X 48 PCS | C48: 48 | D48: PCS | E48: MR JUSSIE MILKY | F48: 1351.9926 | G48: 64895.645 | H48: 1500.7118 | I48: 72034.166 | J48: 1438.29 | K48: 69037.92 | L48: 1596.5019 | M48: 76632.091 | N48: 1510.2 | O48: 72489.6 | P48: 1676.322 | Q48: 80463.456 | R48: PT. HEINZ ABC INDONESIA | S48: =IFERROR(VLOOKUP(CONCATENATE(Fix_Mapping[[#This Row],[KODE BARANG]],1),'Form Fix'!$A$6:$F$1063,4,0),0) -> 460167 | T48: =IFERROR(VLOOKUP(CONCATENATE(Fix_Mapping[[#This Row],[KODE BARANG]],2),'Form Fix'!$A$6:$F$1063,4,0),0) -> 0 | U48: =IFERROR(VLOOKUP(CONCATENATE(Fix_Mapping[[#This Row],[KODE BARANG]],3),'Form Fix'!$A$6:$F$1063,4,0),0) -> 0 | V48: =IFERROR(VLOOKUP(CONCATENATE(Fix_Mapping[[#This Row],[KODE BARANG]],4),'Form Fix'!$A$6:$F$1063,4,0),0) -> 0 | W48: =IFERROR(VLOOKUP(CONCATENATE(Fix_Mapping[[#This Row],[KODE BARANG]],5),'Form Fix'!$A$6:$F$1063,4,0),0) -> 0
A49: A1041003009010 | B49: ABC MR JUSSIE MILKY MANGO 90 ML X 48 PCS | C49: 48 | D49: PCS | E49: MR JUSSIE MILKY | F49: 1351.9926 | G49: 64895.645 | H49: 1500.7118 | I49: 72034.166 | J49: 1438.29 | K49: 69037.92 | L49: 1596.5019 | M49: 76632.091 | N49: 1510.2 | O49: 72489.6 | P49: 1676.322 | Q49: 80463.456 | R49: PT. HEINZ ABC INDONESIA | S49: =IFERROR(VLOOKUP(CONCATENATE(Fix_Mapping[[#This Row],[KODE BARANG]],1),'Form Fix'!$A$6:$F$1063,4,0),0) -> 460168 | T49: =IFERROR(VLOOKUP(CONCATENATE(Fix_Mapping[[#This Row],[KODE BARANG]],2),'Form Fix'!$A$6:$F$1063,4,0),0) -> 0 | U49: =IFERROR(VLOOKUP(CONCATENATE(Fix_Mapping[[#This Row],[KODE BARANG]],3),'Form Fix'!$A$6:$F$1063,4,0),0) -> 0 | V49: =IFERROR(VLOOKUP(CONCATENATE(Fix_Mapping[[#This Row],[KODE BARANG]],4),'Form Fix'!$A$6:$F$1063,4,0),0) -> 0 | W49: =IFERROR(VLOOKUP(CONCATENATE(Fix_Mapping[[#This Row],[KODE BARANG]],5),'Form Fix'!$A$6:$F$1063,4,0),0) -> 0
A50: A1041004009010 | B50: ABC MR JUSSIE MILKY ORANGE 90 ML X 48 PCS | C50: 48 | D50: PCS | E50: MR JUSSIE MILKY | F50: 1351.9926 | G50: 64895.645 | H50: 1500.7118 | I50: 72034.166 | J50: 1438.29 | K50: 69037.92 | L50: 1596.5019 | M50: 76632.091 | N50: 1510.2 | O50: 72489.6 | P50: 1676.322 | Q50: 80463.456 | R50: PT. HEINZ ABC INDONESIA | S50: =IFERROR(VLOOKUP(CONCATENATE(Fix_Mapping[[#This Row],[KODE BARANG]],1),'Form Fix'!$A$6:$F$1063,4,0),0) -> 460169 | T50: =IFERROR(VLOOKUP(CONCATENATE(Fix_Mapping[[#This Row],[KODE BARANG]],2),'Form Fix'!$A$6:$F$1063,4,0),0) -> 0 | U50: =IFERROR(VLOOKUP(CONCATENATE(Fix_Mapping[[#This Row],[KODE BARANG]],3),'Form Fix'!$A$6:$F$1063,4,0),0) -> 0 | V50: =IFERROR(VLOOKUP(CONCATENATE(Fix_Mapping[[#This Row],[KODE BARANG]],4),'Form Fix'!$A$6:$F$1063,4,0),0) -> 0 | W50: =IFERROR(VLOOKUP(CONCATENATE(Fix_Mapping[[#This Row],[KODE BARANG]],5),'Form Fix'!$A$6:$F$1063,4,0),0) -> 0
A51: A1041005009010 | B51: ABC MR JUSSIE MILKY COKLAT 90 ML X 48 PCS | C51: 48 | D51: PCS | E51: MR JUSSIE MILKY | F51: 1351.9926 | G51: 64895.645 | H51: 1500.7118 | I51: 72034.166 | J51: 1438.29 | K51: 69037.92 | L51: 1596.5019 | M51: 76632.091 | N51: 1510.2 | O51: 72489.6 | P51: 1676.322 | Q51: 80463.456 | R51: PT. HEINZ ABC INDONESIA | S51: =IFERROR(VLOOKUP(CONCATENATE(Fix_Mapping[[#This Row],[KODE BARANG]],1),'Form Fix'!$A$6:$F$1063,4,0),0) -> 460172 | T51: =IFERROR(VLOOKUP(CONCATENATE(Fix_Mapping[[#This Row],[KODE BARANG]],2),'Form Fix'!$A$6:$F$1063,4,0),0) -> 0 | U51: =IFERROR(VLOOKUP(CONCATENATE(Fix_Mapping[[#This Row],[KODE BARANG]],3),'Form Fix'!$A$6:$F$1063,4,0),0) -> 0 | V51: =IFERROR(VLOOKUP(CONCATENATE(Fix_Mapping[[#This Row],[KODE BARANG]],4),'Form Fix'!$A$6:$F$1063,4,0),0) -> 0 | W51: =IFERROR(VLOOKUP(CONCATENATE(Fix_Mapping[[#This Row],[KODE BARANG]],5),'Form Fix'!$A$6:$F$1063,4,0),0) -> 0
A52: A1042001009010 | B52: ABC MR JUSSIE FRUITY GUAVA 90 ML X 48 PCS | C52: 48 | D52: PCS | E52: MR JUSSIE FRUITY | F52: 1351.9926 | G52: 64895.645 | H52: 1500.7118 | I52: 72034.166 | J52: 1438.29 | K52: 69037.92 | L52: 1596.5019 | M52: 76632.091 | N52: 1510.2 | O52: 72489.6 | P52: 1676.322 | Q52: 80463.456 | R52: PT. HEINZ ABC INDONESIA | S52: =IFERROR(VLOOKUP(CONCATENATE(Fix_Mapping[[#This Row],[KODE BARANG]],1),'Form Fix'!$A$6:$F$1063,4,0),0) -> 460170 | T52: =IFERROR(VLOOKUP(CONCATENATE(Fix_Mapping[[#This Row],[KODE BARANG]],2),'Form Fix'!$A$6:$F$1063,4,0),0) -> 0 | U52: =IFERROR(VLOOKUP(CONCATENATE(Fix_Mapping[[#This Row],[KODE BARANG]],3),'Form Fix'!$A$6:$F$1063,4,0),0) -> 0 | V52: =IFERROR(VLOOKUP(CONCATENATE(Fix_Mapping[[#This Row],[KODE BARANG]],4),'Form Fix'!$A$6:$F$1063,4,0),0) -> 0 | W52: =IFERROR(VLOOKUP(CONCATENATE(Fix_Mapping[[#This Row],[KODE BARANG]],5),'Form Fix'!$A$6:$F$1063,4,0),0) -> 0
A53: A1042004009010 | B53: ABC MR JUSSIE FRUITY ORANGE 90 ML X 48 PCS | C53: 48 | D53: PCS | E53: MR JUSSIE FRUITY | F53: 1351.9926 | G53: 64895.645 | H53: 1500.7118 | I53: 72034.166 | J53: 1438.29 | K53: 69037.92 | L53: 1596.5019 | M53: 76632.091 | N53: 1510.2 | O53: 72489.6 | P53: 1676.322 | Q53: 80463.456 | R53: PT. HEINZ ABC INDONESIA | S53: =IFERROR(VLOOKUP(CONCATENATE(Fix_Mapping[[#This Row],[KODE BARANG]],1),'Form Fix'!$A$6:$F$1063,4,0),0) -> 460171 | T53: =IFERROR(VLOOKUP(CONCATENATE(Fix_Mapping[[#This Row],[KODE BARANG]],2),'Form Fix'!$A$6:$F$1063,4,0),0) -> 0 | U53: =IFERROR(VLOOKUP(CONCATENATE(Fix_Mapping[[#This Row],[KODE BARANG]],3),'Form Fix'!$A$6:$F$1063,4,0),0) -> 0 | V53: =IFERROR(VLOOKUP(CONCATENATE(Fix_Mapping[[#This Row],[KODE BARANG]],4),'Form Fix'!$A$6:$F$1063,4,0),0) -> 0 | W53: =IFERROR(VLOOKUP(CONCATENATE(Fix_Mapping[[#This Row],[KODE BARANG]],5),'Form Fix'!$A$6:$F$1063,4,0),0) -> 0
A54: A1050000010010 | B54: ABC KACANG HIJAU 100 ML X 48 PCS | C54: 48 | D54: PCS | E54: KACANG HIJAU | F54: 1422.7027 | G54: 68289.731 | H54: 1579.2 | I54: 75801.601 | J54: 1513.5135 | K54: 72648.65 | L54: 1680 | M54: 80640.001 | N54: 72648.65 | O54: 3487135.2 | P54: 80640.001 | Q54: 3870720.1 | S54: =IFERROR(VLOOKUP(CONCATENATE(Fix_Mapping[[#This Row],[KODE BARANG]],1),'Form Fix'!$A$6:$F$1063,4,0),0) -> 460197 | T54: =IFERROR(VLOOKUP(CONCATENATE(Fix_Mapping[[#This Row],[KODE BARANG]],2),'Form Fix'!$A$6:$F$1063,4,0),0) -> 0 | U54: =IFERROR(VLOOKUP(CONCATENATE(Fix_Mapping[[#This Row],[KODE BARANG]],3),'Form Fix'!$A$6:$F$1063,4,0),0) -> 0 | V54: =IFERROR(VLOOKUP(CONCATENATE(Fix_Mapping[[#This Row],[KODE BARANG]],4),'Form Fix'!$A$6:$F$1063,4,0),0) -> 0 | W54: =IFERROR(VLOOKUP(CONCATENATE(Fix_Mapping[[#This Row],[KODE BARANG]],5),'Form Fix'!$A$6:$F$1063,4,0),0) -> 0
A55: A1050000020010 | B55: ABC KACANG HIJAU 200 ML X 24 PCS | C55: 24 | D55: PCS | E55: KACANG HIJAU | F55: 2930.7696 | G55: 70338.47 | H55: 3253.1543 | I55: 78075.702 | J55: 3117.84 | K55: 74828.16 | L55: 3460.8024 | M55: 83059.258 | N55: 3273.7297 | O55: 78569.514 | P55: 3633.84 | Q55: 87212.16 | R55: PT. HEINZ ABC INDONESIA | S55: =IFERROR(VLOOKUP(CONCATENATE(Fix_Mapping[[#This Row],[KODE BARANG]],1),'Form Fix'!$A$6:$F$1063,4,0),0) -> 460056 | T55: =IFERROR(VLOOKUP(CONCATENATE(Fix_Mapping[[#This Row],[KODE BARANG]],2),'Form Fix'!$A$6:$F$1063,4,0),0) -> 460178 | U55: =IFERROR(VLOOKUP(CONCATENATE(Fix_Mapping[[#This Row],[KODE BARANG]],3),'Form Fix'!$A$6:$F$1063,4,0),0) -> 0 | V55: =IFERROR(VLOOKUP(CONCATENATE(Fix_Mapping[[#This Row],[KODE BARANG]],4),'Form Fix'!$A$6:$F$1063,4,0),0) -> 0 | W55: =IFERROR(VLOOKUP(CONCATENATE(Fix_Mapping[[#This Row],[KODE BARANG]],5),'Form Fix'!$A$6:$F$1063,4,0),0) -> 0
A56: A1050000025010 | B56: ABC KACANG HIJAU 250 ML X 24 PCS | C56: 24 | D56: PCS | E56: KACANG HIJAU | F56: 3446.6698 | G56: 82720.075 | H56: 3825.8035 | I56: 91819.283 | J56: 3666.67 | K56: 88000.08 | L56: 4070.0037 | M56: 97680.089 | N56: 3850 | O56: 92400 | P56: 4273.5 | Q56: 102564 | R56: PT. HEINZ ABC INDONESIA | S56: =IFERROR(VLOOKUP(CONCATENATE(Fix_Mapping[[#This Row],[KODE BARANG]],1),'Form Fix'!$A$6:$F$1063,4,0),0) -> 460179 | T56: =IFERROR(VLOOKUP(CONCATENATE(Fix_Mapping[[#This Row],[KODE BARANG]],2),'Form Fix'!$A$6:$F$1063,4,0),0) -> 0 | U56: =IFERROR(VLOOKUP(CONCATENATE(Fix_Mapping[[#This Row],[KODE BARANG]],3),'Form Fix'!$A$6:$F$1063,4,0),0) -> 0 | V56: =IFERROR(VLOOKUP(CONCATENATE(Fix_Mapping[[#This Row],[KODE BARANG]],4),'Form Fix'!$A$6:$F$1063,4,0),0) -> 0 | W56: =IFERROR(VLOOKUP(CONCATENATE(Fix_Mapping[[#This Row],[KODE BARANG]],5),'Form Fix'!$A$6:$F$1063,4,0),0) -> 0
A57: A1050000025011 | B57: ABC KACANG HIJAU 250 ML X 24 PCS EXTRA 50 ML | C57: 24 | D57: PCS | E57: KACANG HIJAU | F57: 2930.7696 | G57: 70338.47 | H57: 3253.1543 | I57: 78075.702 | J57: 3117.84 | K57: 74828.16 | L57: 3460.8024 | M57: 83059.258 | N57: 3117.84 | O57: 74828.16 | P57: 3460.8024 | Q57: 83059.258 | R57: PT. HEINZ ABC INDONESIA | S57: =IFERROR(VLOOKUP(CONCATENATE(Fix_Mapping[[#This Row],[KODE BARANG]],1),'Form Fix'!$A$6:$F$1063,4,0),0) -> 460918 | T57: =IFERROR(VLOOKUP(CONCATENATE(Fix_Mapping[[#This Row],[KODE BARANG]],2),'Form Fix'!$A$6:$F$1063,4,0),0) -> 0 | U57: =IFERROR(VLOOKUP(CONCATENATE(Fix_Mapping[[#This Row],[KODE BARANG]],3),'Form Fix'!$A$6:$F$1063,4,0),0) -> 0 | V57: =IFERROR(VLOOKUP(CONCATENATE(Fix_Mapping[[#This Row],[KODE BARANG]],4),'Form Fix'!$A$6:$F$1063,4,0),0) -> 0 | W57: =IFERROR(VLOOKUP(CONCATENATE(Fix_Mapping[[#This Row],[KODE BARANG]],5),'Form Fix'!$A$6:$F$1063,4,0),0) -> 0
A58: A1050000025020 | B58: ABC KACANG HIJAU 250 ML X 8 PACK PCSX3 | C58: 8 | D58: PCSX3 | E58: KACANG HIJAU | F58: 6893.3302 | G58: 55146.642 | H58: 7651.5965 | I58: 61212.772 | J58: 7333.33 | K58: 58666.64 | L58: 8139.9963 | M58: 65119.97 | N58: 7700 | O58: 61600 | P58: 8547 | Q58: 68376 | R58: PT. HEINZ ABC INDONESIA | S58: =IFERROR(VLOOKUP(CONCATENATE(Fix_Mapping[[#This Row],[KODE BARANG]],1),'Form Fix'!$A$6:$F$1063,4,0),0) -> 460917 | T58: =IFERROR(VLOOKUP(CONCATENATE(Fix_Mapping[[#This Row],[KODE BARANG]],2),'Form Fix'!$A$6:$F$1063,4,0),0) -> 460921 | U58: =IFERROR(VLOOKUP(CONCATENATE(Fix_Mapping[[#This Row],[KODE BARANG]],3),'Form Fix'!$A$6:$F$1063,4,0),0) -> 0 | V58: =IFERROR(VLOOKUP(CONCATENATE(Fix_Mapping[[#This Row],[KODE BARANG]],4),'Form Fix'!$A$6:$F$1063,4,0),0) -> 0 | W58: =IFERROR(VLOOKUP(CONCATENATE(Fix_Mapping[[#This Row],[KODE BARANG]],5),'Form Fix'!$A$6:$F$1063,4,0),0) -> 0
A59: A1061000020010 | B59: ABC SARI KEDELAI MILK 200 ML X 24 PCS | C59: 24 | D59: PCS | E59: SARI KEDELAI MILK | F59: 2752.2542 | G59: 66054.101 | H59: 3055.0022 | I59: 73320.052 | J59: 2927.93 | K59: 70270.32 | L59: 3250.0023 | M59: 78000.055 | N59: 1859.1173 | O59: 44618.815 | P59: 2063.6202 | Q59: 49526.885 | R59: PT. HEINZ ABC INDONESIA | S59: =IFERROR(VLOOKUP(CONCATENATE(Fix_Mapping[[#This Row],[KODE BARANG]],1),'Form Fix'!$A$6:$F$1063,4,0),0) -> 460183 | T59: =IFERROR(VLOOKUP(CONCATENATE(Fix_Mapping[[#This Row],[KODE BARANG]],2),'Form Fix'!$A$6:$F$1063,4,0),0) -> 460174 | U59: =IFERROR(VLOOKUP(CONCATENATE(Fix_Mapping[[#This Row],[KODE BARANG]],3),'Form Fix'!$A$6:$F$1063,4,0),0) -> 0 | V59: =IFERROR(VLOOKUP(CONCATENATE(Fix_Mapping[[#This Row],[KODE BARANG]],4),'Form Fix'!$A$6:$F$1063,4,0),0) -> 0 | W59: =IFERROR(VLOOKUP(CONCATENATE(Fix_Mapping[[#This Row],[KODE BARANG]],5),'Form Fix'!$A$6:$F$1063,4,0),0) -> 0
A60: A1061001020010 | B60: ABC SARI KEDELAI MILK COKLAT 200 ML X 24 PCS | C60: 24 | D60: PCS | E60: SARI KEDELAI MILK | F60: 3556.772 | G60: 85362.528 | H60: 3948.0169 | I60: 94752.406 | J60: 3783.8 | K60: 90811.2 | L60: 4200.018 | M60: 100800.43 | N60: 4086.5 | O60: 98076 | P60: 4536.015 | Q60: 108864.36 | R60: PT. HEINZ ABC INDONESIA | S60: =IFERROR(VLOOKUP(CONCATENATE(Fix_Mapping[[#This Row],[KODE BARANG]],1),'Form Fix'!$A$6:$F$1063,4,0),0) -> 460194 | T60: =IFERROR(VLOOKUP(CONCATENATE(Fix_Mapping[[#This Row],[KODE BARANG]],2),'Form Fix'!$A$6:$F$1063,4,0),0) -> 0 | U60: =IFERROR(VLOOKUP(CONCATENATE(Fix_Mapping[[#This Row],[KODE BARANG]],3),'Form Fix'!$A$6:$F$1063,4,0),0) -> 0 | V60: =IFERROR(VLOOKUP(CONCATENATE(Fix_Mapping[[#This Row],[KODE BARANG]],4),'Form Fix'!$A$6:$F$1063,4,0),0) -> 0 | W60: =IFERROR(VLOOKUP(CONCATENATE(Fix_Mapping[[#This Row],[KODE BARANG]],5),'Form Fix'!$A$6:$F$1063,4,0),0) -> 0
A61: A1061002020010 | B61: ABC SARI KEDELAI MILK STRAWBERRY 200 ML X 24 PCS | C61: 24 | D61: PCS | E61: SARI KEDELAI MILK | F61: 3556.772 | G61: 85362.528 | H61: 3948.0169 | I61: 94752.406 | J61: 3783.8 | K61: 90811.2 | L61: 4200.018 | M61: 100800.43 | N61: 4086.5 | O61: 98076 | P61: 4536.015 | Q61: 108864.36 | R61: PT. HEINZ ABC INDONESIA | S61: =IFERROR(VLOOKUP(CONCATENATE(Fix_Mapping[[#This Row],[KODE BARANG]],1),'Form Fix'!$A$6:$F$1063,4,0),0) -> 460195 | T61: =IFERROR(VLOOKUP(CONCATENATE(Fix_Mapping[[#This Row],[KODE BARANG]],2),'Form Fix'!$A$6:$F$1063,4,0),0) -> 0 | U61: =IFERROR(VLOOKUP(CONCATENATE(Fix_Mapping[[#This Row],[KODE BARANG]],3),'Form Fix'!$A$6:$F$1063,4,0),0) -> 0 | V61: =IFERROR(VLOOKUP(CONCATENATE(Fix_Mapping[[#This Row],[KODE BARANG]],4),'Form Fix'!$A$6:$F$1063,4,0),0) -> 0 | W61: =IFERROR(VLOOKUP(CONCATENATE(Fix_Mapping[[#This Row],[KODE BARANG]],5),'Form Fix'!$A$6:$F$1063,4,0),0) -> 0
A62: A1070001025010 | B62: ABC JUICE GUAVA 250 ML X 24 PCS | C62: 24 | D62: PCS | E62: JUICE | F62: 6140.6534 | G62: 147375.68 | H62: 6816.1253 | I62: 163587.01 | J62: 6532.61 | K62: 156782.64 | L62: 7251.1971 | M62: 174028.73 | N62: 7055.2216 | O62: 169325.32 | P62: 7831.296 | Q62: 187951.1 | R62: PT. HEINZ ABC INDONESIA | S62: =IFERROR(VLOOKUP(CONCATENATE(Fix_Mapping[[#This Row],[KODE BARANG]],1),'Form Fix'!$A$6:$F$1063,4,0),0) -> 460164 | T62: =IFERROR(VLOOKUP(CONCATENATE(Fix_Mapping[[#This Row],[KODE BARANG]],2),'Form Fix'!$A$6:$F$1063,4,0),0) -> 460190 | U62: =IFERROR(VLOOKUP(CONCATENATE(Fix_Mapping[[#This Row],[KODE BARANG]],3),'Form Fix'!$A$6:$F$1063,4,0),0) -> 0 | V62: =IFERROR(VLOOKUP(CONCATENATE(Fix_Mapping[[#This Row],[KODE BARANG]],4),'Form Fix'!$A$6:$F$1063,4,0),0) -> 0 | W62: =IFERROR(VLOOKUP(CONCATENATE(Fix_Mapping[[#This Row],[KODE BARANG]],5),'Form Fix'!$A$6:$F$1063,4,0),0) -> 0
A63: A1070001100110 | B63: ABC JUICE GUAVA 1 L X 12 PCS | C63: 12 | D63: PCS | E63: JUICE | F63: 20629.193 | G63: 247550.32 | H63: 22898.404 | I63: 274780.85 | J63: 21945.95 | K63: 263351.4 | L63: 24360.005 | M63: 292320.05 | N63: 23701.63 | O63: 284419.56 | P63: 26308.809 | Q63: 315705.71 | R63: PT. HEINZ ABC INDONESIA | S63: =IFERROR(VLOOKUP(CONCATENATE(Fix_Mapping[[#This Row],[KODE BARANG]],1),'Form Fix'!$A$6:$F$1063,4,0),0) -> 460165 | T63: =IFERROR(VLOOKUP(CONCATENATE(Fix_Mapping[[#This Row],[KODE BARANG]],2),'Form Fix'!$A$6:$F$1063,4,0),0) -> 460191 | U63: =IFERROR(VLOOKUP(CONCATENATE(Fix_Mapping[[#This Row],[KODE BARANG]],3),'Form Fix'!$A$6:$F$1063,4,0),0) -> 0 | V63: =IFERROR(VLOOKUP(CONCATENATE(Fix_Mapping[[#This Row],[KODE BARANG]],4),'Form Fix'!$A$6:$F$1063,4,0),0) -> 0 | W63: =IFERROR(VLOOKUP(CONCATENATE(Fix_Mapping[[#This Row],[KODE BARANG]],5),'Form Fix'!$A$6:$F$1063,4,0),0) -> 0
A64: A1070002025010 | B64: ABC JUICE ORANGE 250 ML X 24 PCS | C64: 24 | D64: PCS | E64: JUICE | F64: 6140.6534 | G64: 147375.68 | H64: 6816.1253 | I64: 163587.01 | J64: 6532.61 | K64: 156782.64 | L64: 7251.1971 | M64: 174028.73 | N64: 7055.2216 | O64: 169325.32 | P64: 7831.296 | Q64: 187951.1 | R64: PT. HEINZ ABC INDONESIA | S64: =IFERROR(VLOOKUP(CONCATENATE(Fix_Mapping[[#This Row],[KODE BARANG]],1),'Form Fix'!$A$6:$F$1063,4,0),0) -> 460061 | T64: =IFERROR(VLOOKUP(CONCATENATE(Fix_Mapping[[#This Row],[KODE BARANG]],2),'Form Fix'!$A$6:$F$1063,4,0),0) -> 460188 | U64: =IFERROR(VLOOKUP(CONCATENATE(Fix_Mapping[[#This Row],[KODE BARANG]],3),'Form Fix'!$A$6:$F$1063,4,0),0) -> 0 | V64: =IFERROR(VLOOKUP(CONCATENATE(Fix_Mapping[[#This Row],[KODE BARANG]],4),'Form Fix'!$A$6:$F$1063,4,0),0) -> 0 | W64: =IFERROR(VLOOKUP(CONCATENATE(Fix_Mapping[[#This Row],[KODE BARANG]],5),'Form Fix'!$A$6:$F$1063,4,0),0) -> 0
A65: A1070002100110 | B65: ABC JUICE ORANGE 1 L X 12 PCS | C65: 12 | D65: PCS | E65: JUICE | F65: 20629.193 | G65: 247550.32 | H65: 22898.404 | I65: 274780.85 | J65: 21945.95 | K65: 263351.4 | L65: 24360.005 | M65: 292320.05 | N65: 23701.63 | O65: 284419.56 | P65: 26308.809 | Q65: 315705.71 | R65: PT. HEINZ ABC INDONESIA | S65: =IFERROR(VLOOKUP(CONCATENATE(Fix_Mapping[[#This Row],[KODE BARANG]],1),'Form Fix'!$A$6:$F$1063,4,0),0) -> 460189 | T65: =IFERROR(VLOOKUP(CONCATENATE(Fix_Mapping[[#This Row],[KODE BARANG]],2),'Form Fix'!$A$6:$F$1063,4,0),0) -> 0 | U65: =IFERROR(VLOOKUP(CONCATENATE(Fix_Mapping[[#This Row],[KODE BARANG]],3),'Form Fix'!$A$6:$F$1063,4,0),0) -> 0 | V65: =IFERROR(VLOOKUP(CONCATENATE(Fix_Mapping[[#This Row],[KODE BARANG]],4),'Form Fix'!$A$6:$F$1063,4,0),0) -> 0 | W65: =IFERROR(VLOOKUP(CONCATENATE(Fix_Mapping[[#This Row],[KODE BARANG]],5),'Form Fix'!$A$6:$F$1063,4,0),0) -> 0
A66: A1070003025010 | B66: ABC JUICE APPLE 250 ML X 24 PCS | C66: 24 | D66: PCS | E66: JUICE | F66: 6140.6534 | G66: 147375.68 | H66: 6816.1253 | I66: 163587.01 | J66: 6532.61 | K66: 156782.64 | L66: 7251.1971 | M66: 174028.73 | N66: 7055.2216 | O66: 169325.32 | P66: 7831.296 | Q66: 187951.1 | R66: PT. HEINZ ABC INDONESIA | S66: =IFERROR(VLOOKUP(CONCATENATE(Fix_Mapping[[#This Row],[KODE BARANG]],1),'Form Fix'!$A$6:$F$1063,4,0),0) -> 460192 | T66: =IFERROR(VLOOKUP(CONCATENATE(Fix_Mapping[[#This Row],[KODE BARANG]],2),'Form Fix'!$A$6:$F$1063,4,0),0) -> 0 | U66: =IFERROR(VLOOKUP(CONCATENATE(Fix_Mapping[[#This Row],[KODE BARANG]],3),'Form Fix'!$A$6:$F$1063,4,0),0) -> 0 | V66: =IFERROR(VLOOKUP(CONCATENATE(Fix_Mapping[[#This Row],[KODE BARANG]],4),'Form Fix'!$A$6:$F$1063,4,0),0) -> 0 | W66: =IFERROR(VLOOKUP(CONCATENATE(Fix_Mapping[[#This Row],[KODE BARANG]],5),'Form Fix'!$A$6:$F$1063,4,0),0) -> 0
... A81: A1100001015511 | B81: ABC SARDINES TOMAT 155 GR X 30 KLG BANDED | C81: 30 | D81: KLG | E81: SARDINES | F81: 18291.892 | G81: 548756.77 | H81: 20304.001 | I81: 609120.02 | J81: 19459.46 | K81: 583783.8 | L81: 21600.001 | M81: 648000.02 | N81: 20432.43 | O81: 612972.9 | P81: 22679.997 | Q81: 680399.92 | R81: PT. HEINZ ABC INDONESIA | S81: =IFERROR(VLOOKUP(CONCATENATE(Fix_Mapping[[#This Row],[KODE BARANG]],1),'Form Fix'!$A$6:$F$1063,4,0),0) -> 612953 | T81: =IFERROR(VLOOKUP(CONCATENATE(Fix_Mapping[[#This Row],[KODE BARANG]],2),'Form Fix'!$A$6:$F$1063,4,0),0) -> 0 | U81: =IFERROR(VLOOKUP(CONCATENATE(Fix_Mapping[[#This Row],[KODE BARANG]],3),'Form Fix'!$A$6:$F$1063,4,0),0) -> 0 | V81: =IFERROR(VLOOKUP(CONCATENATE(Fix_Mapping[[#This Row],[KODE BARANG]],4),'Form Fix'!$A$6:$F$1063,4,0),0) -> 0 | W81: =IFERROR(VLOOKUP(CONCATENATE(Fix_Mapping[[#This Row],[KODE BARANG]],5),'Form Fix'!$A$6:$F$1063,4,0),0) -> 0
A82: A1100001015512 | B82: ABC SARDINES TOMAT 155 GR X 60 KLG PROMO | C82: 60 | D82: KLG | E82: SARDINES | F82: 7775.7477 | G82: 466544.86 | H82: 8631.08 | I82: 517864.8 | J82: 8272.0721 | K82: 496324.32 | L82: 9182 | M82: 550920 | N82: 0 | O82: 0 | P82: 0 | Q82: 0 | S82: =IFERROR(VLOOKUP(CONCATENATE(Fix_Mapping[[#This Row],[KODE BARANG]],1),'Form Fix'!$A$6:$F$1063,4,0),0) -> 612157 | T82: =IFERROR(VLOOKUP(CONCATENATE(Fix_Mapping[[#This Row],[KODE BARANG]],2),'Form Fix'!$A$6:$F$1063,4,0),0) -> 612961 | U82: =IFERROR(VLOOKUP(CONCATENATE(Fix_Mapping[[#This Row],[KODE BARANG]],3),'Form Fix'!$A$6:$F$1063,4,0),0) -> 0 | V82: =IFERROR(VLOOKUP(CONCATENATE(Fix_Mapping[[#This Row],[KODE BARANG]],4),'Form Fix'!$A$6:$F$1063,4,0),0) -> 0 | W82: =IFERROR(VLOOKUP(CONCATENATE(Fix_Mapping[[#This Row],[KODE BARANG]],5),'Form Fix'!$A$6:$F$1063,4,0),0) -> 0
A83: A1100001042510 | B83: ABC SARDINES TOMAT 425 GR X 24 KLG | C83: 24 | D83: KLG | E83: SARDINES | F83: 20705.408 | G83: 496929.8 | H83: 22983.003 | I83: 551592.07 | J83: 22027.03 | K83: 528648.72 | L83: 24450.003 | M83: 586800.08 | N83: 23128.38 | O83: 555081.12 | P83: 25672.502 | Q83: 616140.04 | R83: PT. HEINZ ABC INDONESIA | S83: =IFERROR(VLOOKUP(CONCATENATE(Fix_Mapping[[#This Row],[KODE BARANG]],1),'Form Fix'!$A$6:$F$1063,4,0),0) -> 612042 | T83: =IFERROR(VLOOKUP(CONCATENATE(Fix_Mapping[[#This Row],[KODE BARANG]],2),'Form Fix'!$A$6:$F$1063,4,0),0) -> 0 | U83: =IFERROR(VLOOKUP(CONCATENATE(Fix_Mapping[[#This Row],[KODE BARANG]],3),'Form Fix'!$A$6:$F$1063,4,0),0) -> 0 | V83: =IFERROR(VLOOKUP(CONCATENATE(Fix_Mapping[[#This Row],[KODE BARANG]],4),'Form Fix'!$A$6:$F$1063,4,0),0) -> 0 | W83: =IFERROR(VLOOKUP(CONCATENATE(Fix_Mapping[[#This Row],[KODE BARANG]],5),'Form Fix'!$A$6:$F$1063,4,0),0) -> 0
A84: A1100002015510 | B84: ABC SARDINES CHILI DW 155 GR X 60 KLG | C84: 60 | D84: KLG | E84: SARDINES | F84: 9145.9462 | G84: 548756.77 | H84: 10152 | I84: 609120.02 | J84: 9729.73 | K84: 583783.8 | L84: 10800 | M84: 648000.02 | N84: 10216.22 | O84: 612973.2 | P84: 11340.004 | Q84: 680400.25 | R84: PT. HEINZ ABC INDONESIA | S84: =IFERROR(VLOOKUP(CONCATENATE(Fix_Mapping[[#This Row],[KODE BARANG]],1),'Form Fix'!$A$6:$F$1063,4,0),0) -> 612046 | T84: =IFERROR(VLOOKUP(CONCATENATE(Fix_Mapping[[#This Row],[KODE BARANG]],2),'Form Fix'!$A$6:$F$1063,4,0),0) -> 0 | U84: =IFERROR(VLOOKUP(CONCATENATE(Fix_Mapping[[#This Row],[KODE BARANG]],3),'Form Fix'!$A$6:$F$1063,4,0),0) -> 0 | V84: =IFERROR(VLOOKUP(CONCATENATE(Fix_Mapping[[#This Row],[KODE BARANG]],4),'Form Fix'!$A$6:$F$1063,4,0),0) -> 0 | W84: =IFERROR(VLOOKUP(CONCATENATE(Fix_Mapping[[#This Row],[KODE BARANG]],5),'Form Fix'!$A$6:$F$1063,4,0),0) -> 0
...

Sheet Query Map.BrgDoubleDms
A1: Kode BARANG Win2 | B1: Nama Win | C1: PCPL KODE 1 | D1: PCPL KODE 2 | E1: PCPL KODE 3 | F1: PCPL KODE 4 | G1: PCPL KODE 5
A2: A1011000006210 | B2: ABC KECAP MANIS 62 GR X 48 PCH | C2: =IFERROR(VLOOKUP(CONCATENATE(Table43_1[[#This Row],[Kode BARANG Win2]],1),'Form Fix'!$A$6:$F$310,4,0),0) -> 100189 | D2: =IFERROR(VLOOKUP(CONCATENATE(Table43_1[[#This Row],[Kode BARANG Win2]],2),'Form Fix'!$A$6:$F$310,4,0),0) -> 100222 | E2: =IFERROR(VLOOKUP(CONCATENATE(Table43_1[[#This Row],[Kode BARANG Win2]],3),'Form Fix'!$A$6:$F$310,4,0),0) -> 100240 | F2: =IFERROR(VLOOKUP(CONCATENATE(Table43_1[[#This Row],[Kode BARANG Win2]],4),'Form Fix'!$A$6:$F$310,4,0),0) -> 0 | G2: =IFERROR(VLOOKUP(CONCATENATE(Table43_1[[#This Row],[Kode BARANG Win2]],5),'Form Fix'!$A$6:$F$310,4,0),0) -> 0
A3: A1011000006211 | B3: ABC KECAP MANIS 62 GR X 48 PCH B5G1 | C3: =IFERROR(VLOOKUP(CONCATENATE(Table43_1[[#This Row],[Kode BARANG Win2]],1),'Form Fix'!$A$6:$F$310,4,0),0) -> 100986 | D3: =IFERROR(VLOOKUP(CONCATENATE(Table43_1[[#This Row],[Kode BARANG Win2]],2),'Form Fix'!$A$6:$F$310,4,0),0) -> 0 | E3: =IFERROR(VLOOKUP(CONCATENATE(Table43_1[[#This Row],[Kode BARANG Win2]],3),'Form Fix'!$A$6:$F$310,4,0),0) -> 0 | F3: =IFERROR(VLOOKUP(CONCATENATE(Table43_1[[#This Row],[Kode BARANG Win2]],4),'Form Fix'!$A$6:$F$310,4,0),0) -> 0 | G3: =IFERROR(VLOOKUP(CONCATENATE(Table43_1[[#This Row],[Kode BARANG Win2]],5),'Form Fix'!$A$6:$F$310,4,0),0) -> 0
A4: A1011000008010 | B4: ABC KECAP MANIS 80 ML X 48 PCH | C4: =IFERROR(VLOOKUP(CONCATENATE(Table43_1[[#This Row],[Kode BARANG Win2]],1),'Form Fix'!$A$6:$F$310,4,0),0) -> 100179 | D4: =IFERROR(VLOOKUP(CONCATENATE(Table43_1[[#This Row],[Kode BARANG Win2]],2),'Form Fix'!$A$6:$F$310,4,0),0) -> 0 | E4: =IFERROR(VLOOKUP(CONCATENATE(Table43_1[[#This Row],[Kode BARANG Win2]],3),'Form Fix'!$A$6:$F$310,4,0),0) -> 0 | F4: =IFERROR(VLOOKUP(CONCATENATE(Table43_1[[#This Row],[Kode BARANG Win2]],4),'Form Fix'!$A$6:$F$310,4,0),0) -> 0 | G4: =IFERROR(VLOOKUP(CONCATENATE(Table43_1[[#This Row],[Kode BARANG Win2]],5),'Form Fix'!$A$6:$F$310,4,0),0) -> 0
A5: A1011000013010 | B5: ABC KECAP MANIS 135 ML X 48 BTL | C5: =IFERROR(VLOOKUP(CONCATENATE(Table43_1[[#This Row],[Kode BARANG Win2]],1),'Form Fix'!$A$6:$F$310,4,0),0) -> 100234 | D5: =IFERROR(VLOOKUP(CONCATENATE(Table43_1[[#This Row],[Kode BARANG Win2]],2),'Form Fix'!$A$6:$F$310,4,0),0) -> 0 | E5: =IFERROR(VLOOKUP(CONCATENATE(Table43_1[[#This Row],[Kode BARANG Win2]],3),'Form Fix'!$A$6:$F$310,4,0),0) -> 0 | F5: =IFERROR(VLOOKUP(CONCATENATE(Table43_1[[#This Row],[Kode BARANG Win2]],4),'Form Fix'!$A$6:$F$310,4,0),0) -> 0 | G5: =IFERROR(VLOOKUP(CONCATENATE(Table43_1[[#This Row],[Kode BARANG Win2]],5),'Form Fix'!$A$6:$F$310,4,0),0) -> 0
A6: A1011000013510 | B6: ABC KECAP MANIS 135 ML X 48 BTL | C6: =IFERROR(VLOOKUP(CONCATENATE(Table43_1[[#This Row],[Kode BARANG Win2]],1),'Form Fix'!$A$6:$F$310,4,0),0) -> 100161 | D6: =IFERROR(VLOOKUP(CONCATENATE(Table43_1[[#This Row],[Kode BARANG Win2]],2),'Form Fix'!$A$6:$F$310,4,0),0) -> 0 | E6: =IFERROR(VLOOKUP(CONCATENATE(Table43_1[[#This Row],[Kode BARANG Win2]],3),'Form Fix'!$A$6:$F$310,4,0),0) -> 0 | F6: =IFERROR(VLOOKUP(CONCATENATE(Table43_1[[#This Row],[Kode BARANG Win2]],4),'Form Fix'!$A$6:$F$310,4,0),0) -> 0 | G6: =IFERROR(VLOOKUP(CONCATENATE(Table43_1[[#This Row],[Kode BARANG Win2]],5),'Form Fix'!$A$6:$F$310,4,0),0) -> 0
A7: A1011000025010 | B7: ABC KECAP MANIS 250 GR X 24 PCH | C7: =IFERROR(VLOOKUP(CONCATENATE(Table43_1[[#This Row],[Kode BARANG Win2]],1),'Form Fix'!$A$6:$F$310,4,0),0) -> 100220 | D7: =IFERROR(VLOOKUP(CONCATENATE(Table43_1[[#This Row],[Kode BARANG Win2]],2),'Form Fix'!$A$6:$F$310,4,0),0) -> 100238 | E7: =IFERROR(VLOOKUP(CONCATENATE(Table43_1[[#This Row],[Kode BARANG Win2]],3),'Form Fix'!$A$6:$F$310,4,0),0) -> 0 | F7: =IFERROR(VLOOKUP(CONCATENATE(Table43_1[[#This Row],[Kode BARANG Win2]],4),'Form Fix'!$A$6:$F$310,4,0),0) -> 0 | G7: =IFERROR(VLOOKUP(CONCATENATE(Table43_1[[#This Row],[Kode BARANG Win2]],5),'Form Fix'!$A$6:$F$310,4,0),0) -> 0
A8: A1011000025011 | B8: ABC KECAP MANIS 250 GR X 24 PCH BANDED | C8: =IFERROR(VLOOKUP(CONCATENATE(Table43_1[[#This Row],[Kode BARANG Win2]],1),'Form Fix'!$A$6:$F$310,4,0),0) -> 100992 | D8: =IFERROR(VLOOKUP(CONCATENATE(Table43_1[[#This Row],[Kode BARANG Win2]],2),'Form Fix'!$A$6:$F$310,4,0),0) -> 0 | E8: =IFERROR(VLOOKUP(CONCATENATE(Table43_1[[#This Row],[Kode BARANG Win2]],3),'Form Fix'!$A$6:$F$310,4,0),0) -> 0 | F8: =IFERROR(VLOOKUP(CONCATENATE(Table43_1[[#This Row],[Kode BARANG Win2]],4),'Form Fix'!$A$6:$F$310,4,0),0) -> 0 | G8: =IFERROR(VLOOKUP(CONCATENATE(Table43_1[[#This Row],[Kode BARANG Win2]],5),'Form Fix'!$A$6:$F$310,4,0),0) -> 0
A9: A1011000060011 | B9: ABC KECAP MANIS 600 GR X PCH BANDED | C9: =IFERROR(VLOOKUP(CONCATENATE(Table43_1[[#This Row],[Kode BARANG Win2]],1),'Form Fix'!$A$6:$F$310,4,0),0) -> 0 | D9: =IFERROR(VLOOKUP(CONCATENATE(Table43_1[[#This Row],[Kode BARANG Win2]],2),'Form Fix'!$A$6:$F$310,4,0),0) -> 0 | E9: =IFERROR(VLOOKUP(CONCATENATE(Table43_1[[#This Row],[Kode BARANG Win2]],3),'Form Fix'!$A$6:$F$310,4,0),0) -> 0 | F9: =IFERROR(VLOOKUP(CONCATENATE(Table43_1[[#This Row],[Kode BARANG Win2]],4),'Form Fix'!$A$6:$F$310,4,0),0) -> 0 | G9: =IFERROR(VLOOKUP(CONCATENATE(Table43_1[[#This Row],[Kode BARANG Win2]],5),'Form Fix'!$A$6:$F$310,4,0),0) -> 0
A10: A1011000027520 | B10: ABC KECAP MANIS 275 ML X 24 BTL | C10: =IFERROR(VLOOKUP(CONCATENATE(Table43_1[[#This Row],[Kode BARANG Win2]],1),'Form Fix'!$A$6:$F$310,4,0),0) -> 100162 | D10: =IFERROR(VLOOKUP(CONCATENATE(Table43_1[[#This Row],[Kode BARANG Win2]],2),'Form Fix'!$A$6:$F$310,4,0),0) -> 100236 | E10: =IFERROR(VLOOKUP(CONCATENATE(Table43_1[[#This Row],[Kode BARANG Win2]],3),'Form Fix'!$A$6:$F$310,4,0),0) -> 0 | F10: =IFERROR(VLOOKUP(CONCATENATE(Table43_1[[#This Row],[Kode BARANG Win2]],4),'Form Fix'!$A$6:$F$310,4,0),0) -> 0 | G10: =IFERROR(VLOOKUP(CONCATENATE(Table43_1[[#This Row],[Kode BARANG Win2]],5),'Form Fix'!$A$6:$F$310,4,0),0) -> 0
A11: A1011000030010 | B11: ABC KECAP MANIS 300 GR X 24 PCH | C11: =IFERROR(VLOOKUP(CONCATENATE(Table43_1[[#This Row],[Kode BARANG Win2]],1),'Form Fix'!$A$6:$F$310,4,0),0) -> 100158 | D11: =IFERROR(VLOOKUP(CONCATENATE(Table43_1[[#This Row],[Kode BARANG Win2]],2),'Form Fix'!$A$6:$F$310,4,0),0) -> 100172 | E11: =IFERROR(VLOOKUP(CONCATENATE(Table43_1[[#This Row],[Kode BARANG Win2]],3),'Form Fix'!$A$6:$F$310,4,0),0) -> 0 | F11: =IFERROR(VLOOKUP(CONCATENATE(Table43_1[[#This Row],[Kode BARANG Win2]],4),'Form Fix'!$A$6:$F$310,4,0),0) -> 0 | G11: =IFERROR(VLOOKUP(CONCATENATE(Table43_1[[#This Row],[Kode BARANG Win2]],5),'Form Fix'!$A$6:$F$310,4,0),0) -> 0
A12: A1011000030012 | B12: ABC KECAP MANIS 600 GR X 12 PCH BANDED | C12: =IFERROR(VLOOKUP(CONCATENATE(Table43_1[[#This Row],[Kode BARANG Win2]],1),'Form Fix'!$A$6:$F$310,4,0),0) -> 100991 | D12: =IFERROR(VLOOKUP(CONCATENATE(Table43_1[[#This Row],[Kode BARANG Win2]],2),'Form Fix'!$A$6:$F$310,4,0),0) -> 109002 | E12: =IFERROR(VLOOKUP(CONCATENATE(Table43_1[[#This Row],[Kode BARANG Win2]],3),'Form Fix'!$A$6:$F$310,4,0),0) -> 109001 | F12: =IFERROR(VLOOKUP(CONCATENATE(Table43_1[[#This Row],[Kode BARANG Win2]],4),'Form Fix'!$A$6:$F$310,4,0),0) -> 0 | G12: =IFERROR(VLOOKUP(CONCATENATE(Table43_1[[#This Row],[Kode BARANG Win2]],5),'Form Fix'!$A$6:$F$310,4,0),0) -> 0
A13: A1011000045010 | B13: ABC KECAP MANIS 450 GR X 12 PCH | C13: =IFERROR(VLOOKUP(CONCATENATE(Table43_1[[#This Row],[Kode BARANG Win2]],1),'Form Fix'!$A$6:$F$310,4,0),0) -> 100241 | D13: =IFERROR(VLOOKUP(CONCATENATE(Table43_1[[#This Row],[Kode BARANG Win2]],2),'Form Fix'!$A$6:$F$310,4,0),0) -> 0 | E13: =IFERROR(VLOOKUP(CONCATENATE(Table43_1[[#This Row],[Kode BARANG Win2]],3),'Form Fix'!$A$6:$F$310,4,0),0) -> 0 | F13: =IFERROR(VLOOKUP(CONCATENATE(Table43_1[[#This Row],[Kode BARANG Win2]],4),'Form Fix'!$A$6:$F$310,4,0),0) -> 0 | G13: =IFERROR(VLOOKUP(CONCATENATE(Table43_1[[#This Row],[Kode BARANG Win2]],5),'Form Fix'!$A$6:$F$310,4,0),0) -> 0
... A168: A1150001000011B | B168: B> ABC KAOS CORDIAL SACHET SG X 1 PCS | C168: =IFERROR(VLOOKUP(CONCATENATE(Table43_1[[#This Row],[Kode BARANG Win2]],1),'Form Fix'!$A$6:$F$310,4,0),0) -> 900044 | D168: =IFERROR(VLOOKUP(CONCATENATE(Table43_1[[#This Row],[Kode BARANG Win2]],2),'Form Fix'!$A$6:$F$310,4,0),0) -> 0 | E168: =IFERROR(VLOOKUP(CONCATENATE(Table43_1[[#This Row],[Kode BARANG Win2]],3),'Form Fix'!$A$6:$F$310,4,0),0) -> 0 | F168: =IFERROR(VLOOKUP(CONCATENATE(Table43_1[[#This Row],[Kode BARANG Win2]],4),'Form Fix'!$A$6:$F$310,4,0),0) -> 0 | G168: =IFERROR(VLOOKUP(CONCATENATE(Table43_1[[#This Row],[Kode BARANG Win2]],5),'Form Fix'!$A$6:$F$310,4,0),0) -> 0

Sheet Form Fix
C1: UPDATE TGL
O2: =COUNTIF(Table43[LEN 50], ">50") -> 1
D3: PASTE NAMA DAN CODE PRINCIPLE (Buat Format seperti ini dan Ambil dari Daftar Harga Principle) | P3: CPI | AL3: Daftar Harga | AY3: Update Per
I4: ISI SESUAIKAN ANTARA DMS vs WIN | K4: HASIL CODE KELOMPOK, CODE BARANG & NAMA BARANG WIN | P4: Kolom Principle | AL4: Harga Beli | AP4: Harga Jual GT | AT4: Harga Jual Motorist | AX4: MARGIN | BD4: To Win, diisi oleh Admin
A5: CONCATENATE MAPPING | B5: No. Urut Item Sama | C5: NO | D5: Kode Pcpl | E5: Klp Brg Pcpl | F5: Nama Barang Principle | G5: ISI/CTN | H5: Ket. Tambahan / Pembantu | I5: SATUAN Fix Win | J5: Nama Kelompok Win | K5: Kode Kelompok Win | L5: Kode BARANG Win2 | M5: LEN 15 | N5: Nama Win | O5: LEN 50 | P5: Nama Pcpl | Q5: kode 2 Digit (hrf+No) | R5: Nama KLP | S5: kode 2 Digit (Nomor) | T5: Nama Sub KLP | U5: kode 1 Digit (Nomor) | V5: Nama Sub KLP2 | W5: kode 1 Digit (Nomor)5 | X5: Nama Aroma/ Rasa | Y5: kode 2 Digit (Nomor)2 | Z5: Nama Gramasi atau Jumlah Pack per CTN | AA5: kode 4 Digit (Nomor) | AB5: Nama Jenis Kemasan | AC5: kode 1 Digit (Nomor)3 | AD5: Nama Promo | AE5: kode 1 Digit (Nomor)4 | AF5: Gunakan ini apabila item tersebut sachet | AG5: kode 1 Digit (Nomor)32 | AH5: KET TAMBAHAN2 | AI5: KET. GOLONGAN | AJ5: kode 1 Digit (Nomor) | AK5: Tanda Kode Revisi | AL5: Harga Beli Pcs (-PPN) | AM5: Harga Beli Krt (- PPN) | AN5: Harga Beli Pcs (+PPN) | AO5: Harga Beli Krt (+PPN) | AP5: Harga Jual Pcs GT (-PPN) | AQ5: Harga Jual Krt GT (- PPN) | AR5: Harga Jual Pcs GT (+PPN | AS5: Harga Jual Krt GT (+PPN) | AT5: Harga Jual Pcs MT (-PPN) | AU5: Harga Jual Krt MT (- PPN) | AV5: Harga Jual Pcs MT (+PPN) | AW5: Harga Jual Krt MT (+PPN) | AX5: MARGIN | AY5: Efektif Pembuatan | AZ5: Efektif Naik Harga | BA5: Status Pembuatan | BB5: Status Harga | BC5: Status Barang | BD5: Mata Uang | BE5: Kode Golongan | BF5: Nama Golongan | BG5: Kode PCPL To Win | BH5: Kode Jenis Produk | BI5: SAT BSR | BJ5: GD | BK5: Kode PRK | BL5: Kode PRK SJ | BM5: Kode Job | BN5: Approval | BO5: Nama Principle | BP5: HARGA NAIK GT | BQ5: CEK | BR5: FIX HARGA | BS5: HARGA NAIK GT | BT5: CEK | BU5: FIX HARGA | BV5: HARGA MOTORIS +PPN | BW5: FIX HARGA | BX5: HARGA MOTORIS -PPN
