Workbook
Name Consol: "Error"

Sheet PRICE LIST Motasa
A3: KELOMPOK PRODUK | B3: KODE PRODUK PRINSIPAL | C3: NAMA ITEM | D3: ISI/CTN | E3: SATUAN | F3: HARGA INCLUDE PPN 11% IN CTN | G3: HARGA/PCS
A4: ANTANGIN GROUP | B4: 10002 | C4: ANTANGIN JRG PLUS JAHE MERAH TD20 | D4: 1000 | E4: STRIP | F4: 3210000 | G4: =F4/D4 -> 3210
A5: ANTANGIN GROUP | B5: 10063 | C5: ANTANGIN JUNIORS SD5 | D5: 300 | E5: SACHET | F5: 600000 | G5: =F5/D5 -> 2000
A6: ANTANGIN GROUP | B6: 10074 | C6: ANTANGIN JRG + MADU SD12 | D6: 360 | E6: SACHET | F6: 1116000 | G6: =F6/D6 -> 3100
A7: ANTANGIN GROUP | B7: 10075 | C7: ANTANGIN MINT SD12 | D7: 360 | E7: SACHET | F7: 1116000 | G7: =F7/D7 -> 3100
A8: ANTANGIN GROUP | B8: 10077 | C8: ANTANGIN MINT SD5 | D8: 300 | E8: SACHET | F8: 930000 | G8: =F8/D8 -> 3100
A9: ANTANGIN GROUP | B9: 10110 | C9: ANTANGIN GOOD NIGTH TD20 | D9: 1000 | E9: STRIP | F9: 4036000 | G9: =F9/D9 -> 4036
A10: ANTANGIN GROUP | B10: 10112 | C10: ANTANGIN HABBATUSSAUDA SD12 | D10: 360 | E10: SACHET | F10: 1116000 | G10: =F10/D10 -> 3100
A11: ANTANGIN GROUP | B11: 10134 | C11: ANTANGIN HABBATUSSAUDA SD14 | D11: 420 | E11: SACHET | F11: 1115998.8 | G11: =F11/D11 -> 2657.14
A12: ANTANGIN GROUP | B12: 10135 | C12: ANTANGIN MINT SD14 | D12: 420 | E12: SACHET | F12: 1115998.8 | G12: =F12/D12 -> 2657.14
A13: CANDY GROUP | B13: 10039 | C13: OB HERBAL PERMEN HERBAL RASA MINT S5 | D13: 270 | E13: SACHET | F13: 558090 | G13: =F13/D13 -> 2067
A14: CANDY GROUP | B14: 10048 | C14: ANTANGIN PERMEN HERBAL RASA MADU MINT T30 | D14: 180 | E14: SACHET | F14: 372060 | G14: =F14/D14 -> 2067
A15: CANDY GROUP | B15: 10067 | C15: ANTANGIN PERMEN ANEKA RASA T250 | D15: 6 | E15: TOPLES | F15: 213666 | G15: =F15/D15 -> 35611
... A149: MADU GROUP | B149: 60108 | C149: MADU TJ STRAWBERRY D12 (DUS) | D149: 24 | E149: DUS | F149: 201531.6 | G149: =F149/D149 -> 8397.15

Sheet FORM DASAR KLP
A3: KODE PRODUK PRINSIPAL | B3: KELOMPOK PRODUK By Principle | C3: NAMA ITEM | D3: ISI/CTN | E3: SATUAN | F3: HARGA INCLUDE PPN 11% IN CTN | G3: HARGA/PCS
A4: 10002 | B4: ANTANGIN GROUP | C4: ANTANGIN JRG PLUS JAHE MERAH TD20 | D4: 1000 | E4: STRIP | F4: 3563100 | G4: =F4/D4 -> 3563.1
A5: 10063 | B5: ANTANGIN GROUP | C5: ANTANGIN JUNIORS SD5 | D5: 300 | E5: SACHET | F5: 666000 | G5: =F5/D5 -> 2220
A6: 10074 | B6: ANTANGIN GROUP | C6: ANTANGIN JRG + MADU SD12 | D6: 360 | E6: SACHET | F6: 1238760 | G6: =F6/D6 -> 3441
A7: 10075 | B7: ANTANGIN GROUP | C7: ANTANGIN MINT SD12 | D7: 360 | E7: SACHET | F7: 1238760 | G7: =F7/D7 -> 3441
A8: 10077 | B8: ANTANGIN GROUP | C8: ANTANGIN MINT SD5 | D8: 300 | E8: SACHET | F8: 1032300 | G8: =F8/D8 -> 3441
A9: 10110 | B9: ANTANGIN GROUP | C9: ANTANGIN GOOD NIGTH TD20 | D9: 1000 | E9: STRIP | F9: 4479960 | G9: =F9/D9 -> 4479.96
A10: 10112 | B10: ANTANGIN GROUP | C10: ANTANGIN HABBATUSSAUDA SD12 | D10: 360 | E10: SACHET | F10: 1238760 | G10: =F10/D10 -> 3441
A11: 10134 | B11: ANTANGIN GROUP | C11: ANTANGIN HABBATUSSAUDA SD14 | D11: 420 | E11: SACHET | F11: 1238758.7 | G11: =F11/D11 -> 2949.4254
A12: 10135 | B12: ANTANGIN GROUP | C12: ANTANGIN MINT SD14 | D12: 420 | E12: SACHET | F12: 1238758.7 | G12: =F12/D12 -> 2949.4254
A13: 10039 | B13: CANDY GROUP | C13: OB HERBAL PERMEN HERBAL RASA MINT S5 | D13: 270 | E13: SACHET | F13: 619479.9 | G13: =F13/D13 -> 2294.37
A14: 10048 | B14: CANDY GROUP | C14: ANTANGIN PERMEN HERBAL RASA MADU MINT T30 | D14: 180 | E14: SACHET | F14: 412986.6 | G14: =F14/D14 -> 2294.37
A15: 10067 | B15: CANDY GROUP | C15: ANTANGIN PERMEN ANEKA RASA T250 | D15: 6 | E15: TOPLES | F15: 237169.26 | G15: =F15/D15 -> 39528.21
... A149: 60108 | B149: MADU GROUP | C149: MADU TJ STRAWBERRY D12 (DUS) | D149: 24 | E149: DUS | F149: 223700.08 | G149: =F149/D149 -> 9320.8365

Sheet Cara Buat
A3: 1 | B3: Sortir Daftar Produk Principle sesuai Nama lalu sortir lagi by kelompok | D3: 1 | E3: Buat satu folder master barang, master kelompok, price list, mapping produk win to pcpl dan mapping produk pcpl to win
A4: 2 | B4: Copy dan Paste kan ke Sheet Form Master (sesuaikan kolom nya) | D4: 2 | E4: Master barang, master kelompok, price list, mapping produk win to pcpl dan mapping produk pcpl to win berdiri sendiri dalam satu book
A5: 3 | B5: Sheet kuning adalah rumus, jangan diganggu

Sheet Pvt Map 1
A3: Kode BARANG Win2 | B3: SATUAN Fix Win | C3: Kode Pcpl | D3: ISI/CTN | E3: Sum of No. Urut Item Sama
A4: R1054001000010 | B4: PCS | C4: 3300965 | D4: 576 | E4: 1
A5: R1054002000010 | B5: PCS | C5: 3300964 | D5: 576 | E5: 1
A6: R1071001001520 | B6: SCH | C6: 3239831 | D6: 144 | E6: 1
A7: R1071001001520 | B7: SCH | C7: 3120730 | D7: 144 | E7: 2
A8: R1071001001520 | B8: SCH | C8: 3090609 | D8: 144 | E8: 3
A9: R1052002000010 | B9: PCS | C9: 8021803 | D9: 576 | E9: 1
A10: R1052001000010 | B10: PCS | C10: 8021804 | D10: 576 | E10: 1
A11: R1072001003010 | B11: PCS | C11: 3301366 | D11: 72 | E11: 1
A12: R1021007006010 | B12: PCS | C12: 3193501 | D12: 144 | E12: 1
A13: R1021007006010 | B13: PCS | C13: 3337511 | D13: 144 | E13: 2
A14: R1021006006010 | B14: PCS | C14: 3193502 | D14: 144 | E14: 1
A15: R1021005006010 | B15: PCS | C15: 3166975 | D15: 144 | E15: 1
... A27: R1021001006010 | B27: PCS | C27: 3331432 | D27: 144 | E27: 4
A28: R1071002006020 | B28: SCH | C28: 3297500 | D28: 72
A29: R1071002006020 | B29: SCH | C29: 3239844 | D29: 72
A30: R1071002006020 | B30: SCH | C30: 3120741 | D30: 72
A31: R1071002006020 | B31: SCH | C31: 3052120 | D31: 72
A32: R1071002006020 | B32: SCH | C32: 3195853 | D32: 72
A33: R1071002006020 | B33: SCH | C33: 3108501 | D33: 72
A34: R1071001006020 | B34: SCH | C34: 3297499 | D34: 72
A35: R1071001006020 | B35: SCH | C35: 3120734 | D35: 72
A36: R1071001006020 | B36: SCH | C36: 3239832 | D36: 72
A37: R1071001006020 | B37: SCH | C37: 3017044 | D37: 72
A38: R1071001006020 | B38: SCH | C38: 3185296 | D38: 72
A39: R1071001006020 | B39: SCH | C39: 3090608 | D39: 72
... A42: R1063001000010 | B42: PCS | C42: 8204617 | D42: 60
A43: R1063001000010 | B43: PCS | C43: ID0365729 | D43: 60
A44: R1063001000010 | B44: PCS | C44: ID8153746 | D44: 60
A45: R1063001000010 | B45: PCS | C45: ID0143051 | D45: 60
A46: R1061001000010 | B46: PCS | C46: 8125396 | D46: 60
A47: R1061001000010 | B47: PCS | C47: 3056005 | D47: 60
A48: R1061001000010 | B48: PCS | C48: 8204616 | D48: 60
A49: R1061001000010 | B49: PCS | C49: ID0346825 | D49: 60
A50: R1061001000010 | B50: PCS | C50: ID8153744 | D50: 60
A51: R1061001000010 | B51: PCS | C51: ID0143020 | D51: 60
A52: R1062001000010 | B52: PCS | C52: 8125395 | D52: 60
A53: R1062001000010 | B53: PCS | C53: ID8153739 | D53: 60
A54: R1062001000010 | B54: PCS | C54: ID0143060 | D54: 60
A55: R1062001000010 | B55: PCS | C55: 8204615 | D55: 60
...

Sheet Table Pvt 1
A1: Kode Barang Win | B1: Kode Pcpl | C1: SATUAN Fix Win | D1: ISI/CTN | E1: Kode PCPL yang sama | F1: Column1
A2: R1054001000010 | B2: 3300965 | C2: PCS | D2: 576 | E2: 1 | F2: =Pvt_Map_1[[#This Row],[Kode Barang Win]] -> R1054001000010
A3: R1054002000010 | B3: 3300964 | C3: PCS | D3: 576 | E3: 1 | F3: =Pvt_Map_1[[#This Row],[Kode Barang Win]] -> R1054002000010
A4: R1071001001520 | B4: 3239831 | C4: SCH | D4: 144 | E4: 1 | F4: =Pvt_Map_1[[#This Row],[Kode Barang Win]] -> R1071001001520
A5: R1071001001520 | B5: 3120730 | C5: SCH | D5: 144 | E5: 2 | F5: =Pvt_Map_1[[#This Row],[Kode Barang Win]] -> R1071001001520
A6: R1071001001520 | B6: 3090609 | C6: SCH | D6: 144 | E6: 3 | F6: =Pvt_Map_1[[#This Row],[Kode Barang Win]] -> R1071001001520
A7: R1052002000010 | B7: 8021803 | C7: PCS | D7: 576 | E7: 1 | F7: =Pvt_Map_1[[#This Row],[Kode Barang Win]] -> R1052002000010
A8: R1052001000010 | B8: 8021804 | C8: PCS | D8: 576 | E8: 1 | F8: =Pvt_Map_1[[#This Row],[Kode Barang Win]] -> R1052001000010
A9: R1072001003010 | B9: 3301366 | C9: PCS | D9: 72 | E9: 1 | F9: =Pvt_Map_1[[#This Row],[Kode Barang Win]] -> R1072001003010
A10: R1021007006010 | B10: 3193501 | C10: PCS | D10: 144 | E10: 1 | F10: =Pvt_Map_1[[#This Row],[Kode Barang Win]] -> R1021007006010
A11: R1021007006010 | B11: 3337511 | C11: PCS | D11: 144 | E11: 2 | F11: =Pvt_Map_1[[#This Row],[Kode Barang Win]] -> R1021007006010
A12: R1021006006010 | B12: 3193502 | C12: PCS | D12: 144 | E12: 1 | F12: =Pvt_Map_1[[#This Row],[Kode Barang Win]] -> R1021006006010
A13: R1021005006010 | B13: 3166975 | C13: PCS | D13: 144 | E13: 1 | F13: =Pvt_Map_1[[#This Row],[Kode Barang Win]] -> R1021005006010
... A25: R1021001006010 | B25: 3331432 | C25: PCS | D25: 144 | E25: 4 | F25: =Pvt_Map_1[[#This Row],[Kode Barang Win]] -> R1021001006010
A26: R1071002006020 | B26: 3297500 | C26: SCH | D26: 72 | F26: =Pvt_Map_1[[#This Row],[Kode Barang Win]] -> R1071002006020
A27: R1071002006020 | B27: 3239844 | C27: SCH | D27: 72 | F27: =Pvt_Map_1[[#This Row],[Kode Barang Win]] -> R1071002006020
A28: R1071002006020 | B28: 3120741 | C28: SCH | D28: 72 | F28: =Pvt_Map_1[[#This Row],[Kode Barang Win]] -> R1071002006020
A29: R1071002006020 | B29: 3052120 | C29: SCH | D29: 72 | F29: =Pvt_Map_1[[#This Row],[Kode Barang Win]] -> R1071002006020
A30: R1071002006020 | B30: 3195853 | C30: SCH | D30: 72 | F30: =Pvt_Map_1[[#This Row],[Kode Barang Win]] -> R1071002006020
A31: R1071002006020 | B31: 3108501 | C31: SCH | D31: 72 | F31: =Pvt_Map_1[[#This Row],[Kode Barang Win]] -> R1071002006020
A32: R1071001006020 | B32: 3297499 | C32: SCH | D32: 72 | F32: =Pvt_Map_1[[#This Row],[Kode Barang Win]] -> R1071001006020
A33: R1071001006020 | B33: 3120734 | C33: SCH | D33: 72 | F33: =Pvt_Map_1[[#This Row],[Kode Barang Win]] -> R1071001006020
A34: R1071001006020 | B34: 3239832 | C34: SCH | D34: 72 | F34: =Pvt_Map_1[[#This Row],[Kode Barang Win]] -> R1071001006020
A35: R1071001006020 | B35: 3017044 | C35: SCH | D35: 72 | F35: =Pvt_Map_1[[#This Row],[Kode Barang Win]] -> R1071001006020
A36: R1071001006020 | B36: 3185296 | C36: SCH | D36: 72 | F36: =Pvt_Map_1[[#This Row],[Kode Barang Win]] -> R1071001006020
A37: R1071001006020 | B37: 3090608 | C37: SCH | D37: 72 | F37: =Pvt_Map_1[[#This Row],[Kode Barang Win]] -> R1071001006020
... A40: R1063001000010 | B40: 8204617 | C40: PCS | D40: 60 | F40: =Pvt_Map_1[[#This Row],[Kode Barang Win]] -> R1063001000010
A41: R1063001000010 | B41: ID0365729 | C41: PCS | D41: 60 | F41: =Pvt_Map_1[[#This Row],[Kode Barang Win]] -> R1063001000010
A42: R1063001000010 | B42: ID8153746 | C42: PCS | D42: 60 | F42: =Pvt_Map_1[[#This Row],[Kode Barang Win]] -> R1063001000010
A43: R1063001000010 | B43: ID0143051 | C43: PCS | D43: 60 | F43: =Pvt_Map_1[[#This Row],[Kode Barang Win]] -> R1063001000010
A44: R1061001000010 | B44: 8125396 | C44: PCS | D44: 60 | F44: =Pvt_Map_1[[#This Row],[Kode Barang Win]] -> R1061001000010
A45: R1061001000010 | B45: 3056005 | C45: PCS | D45: 60 | F45: =Pvt_Map_1[[#This Row],[Kode Barang Win]] -> R1061001000010
A46: R1061001000010 | B46: 8204616 | C46: PCS | D46: 60 | F46: =Pvt_Map_1[[#This Row],[Kode Barang Win]] -> R1061001000010
A47: R1061001000010 | B47: ID0346825 | C47: PCS | D47: 60 | F47: =Pvt_Map_1[[#This Row],[Kode Barang Win]] -> R1061001000010
A48: R1061001000010 | B48: ID8153744 | C48: PCS | D48: 60 | F48: =Pvt_Map_1[[#This Row],[Kode Barang Win]] -> R1061001000010
A49: R1061001000010 | B49: ID0143020 | C49: PCS | D49: 60 | F49: =Pvt_Map_1[[#This Row],[Kode Barang Win]] -> R1061001000010
A50: R1062001000010 | B50: 8125395 | C50: PCS | D50: 60 | F50: =Pvt_Map_1[[#This Row],[Kode Barang Win]] -> R1062001000010
A51: R1062001000010 | B51: ID8153739 | C51: PCS | D51: 60 | F51: =Pvt_Map_1[[#This Row],[Kode Barang Win]] -> R1062001000010
A52: R1062001000010 | B52: ID0143060 | C52: PCS | D52: 60 | F52: =Pvt_Map_1[[#This Row],[Kode Barang Win]] -> R1062001000010
A53: R1062001000010 | B53: 8204615 | C53: PCS | D53: 60 | F53: =Pvt_Map_1[[#This Row],[Kode Barang Win]] -> R1062001000010
...

Sheet Fix Mapping
A1: KODE BARANG | B1: NAMA BARANG | C1: ISI/CTN | D1: SATUAN | E1: NAMA KELOMPOK | F1: Harga Beli Pcs (-PPN) | G1: Harga Beli Krt (- PPN) | H1: Harga Beli Pcs (+PPN) | I1: Harga Beli Krt (+PPN) | J1: Harga Jual Pcs GT (-PPN) | K1: Harga Jual Krt GT (- PPN) | L1: Harga Jual Pcs GT (+PPN | M1: Harga Jual Krt GT (+PPN) | N1: Harga Jual Pcs MT (-PPN) | O1: Harga Jual Krt MT (- PPN) | P1: Harga Jual Pcs MT (+PPN) | Q1: Harga Jual Krt MT (+PPN) | R1: NAMA PRINCIPLE | S1: PCPL KODE 1 | T1: PCPL KODE 2 | U1: PCPL KODE 3 | V1: PCPL KODE 4 | W1: PCPL KODE 5
A2: R1011000010010 | B2: RB BRASSO METAL POOLISH 100ML X 48 PCS | C2: 48 | D2: PCS | E2: BRASSO METAL POOLISH | F2: 22749.168 | G2: 1091960.1 | H2: 25251.577 | I2: 1212075.7 | J2: 24862.479 | K2: 1193399 | L2: 27597.352 | M2: 1324672.9 | N2: 24862.479 | O2: 1193399 | P2: 27597.352 | Q2: 1324672.9 | S2: =IFERROR(VLOOKUP(CONCATENATE(Fix_Mapping[[#This Row],[KODE BARANG]],1),'Form Fix'!$A$6:$F$911,4,0),0) -> 3121445 | T2: =IFERROR(VLOOKUP(CONCATENATE(Fix_Mapping[[#This Row],[KODE BARANG]],2),'Form Fix'!$A$6:$F$911,4,0),0) -> 3055580 | U2: =IFERROR(VLOOKUP(CONCATENATE(Fix_Mapping[[#This Row],[KODE BARANG]],3),'Form Fix'!$A$6:$F$911,4,0),0) -> ID020064 | V2: =IFERROR(VLOOKUP(CONCATENATE(Fix_Mapping[[#This Row],[KODE BARANG]],4),'Form Fix'!$A$6:$F$911,4,0),0) -> 0 | W2: =IFERROR(VLOOKUP(CONCATENATE(Fix_Mapping[[#This Row],[KODE BARANG]],5),'Form Fix'!$A$6:$F$911,4,0),0) -> 0
A3: R1021001006010 | B3: RB DETTOL BODY SOAP COOL 60GR X 144 PCS | C3: 144 | D3: PCS | E3: DETTOL BODY SOAP | F3: 3048.78 | G3: 439024.32 | H3: 3384.1458 | I3: 487317 | J3: 3332 | K3: 479808 | L3: 3698.52 | M3: 532586.88 | N3: 3332 | O3: 479808 | P3: 3698.52 | Q3: 532586.88 | S3: =IFERROR(VLOOKUP(CONCATENATE(Fix_Mapping[[#This Row],[KODE BARANG]],1),'Form Fix'!$A$6:$F$911,4,0),0) -> 3171295 | T3: =IFERROR(VLOOKUP(CONCATENATE(Fix_Mapping[[#This Row],[KODE BARANG]],2),'Form Fix'!$A$6:$F$911,4,0),0) -> 3166934 | U3: =IFERROR(VLOOKUP(CONCATENATE(Fix_Mapping[[#This Row],[KODE BARANG]],3),'Form Fix'!$A$6:$F$911,4,0),0) -> 3119258 | V3: =IFERROR(VLOOKUP(CONCATENATE(Fix_Mapping[[#This Row],[KODE BARANG]],4),'Form Fix'!$A$6:$F$911,4,0),0) -> 3331432 | W3: =IFERROR(VLOOKUP(CONCATENATE(Fix_Mapping[[#This Row],[KODE BARANG]],5),'Form Fix'!$A$6:$F$911,4,0),0) -> 0
A4: R1021001010010 | B4: RB DETTOL BODY SOAP COOL 100GR X 144 PCS | C4: 144 | D4: PCS | E4: DETTOL BODY SOAP | F4: 5864.5654 | G4: 844497.42 | H4: 6509.6676 | I4: 937392.14 | J4: 6409.3611 | K4: 922948 | L4: 7114.3908 | M4: 1024472.3 | N4: 6409.3611 | O4: 922948 | P4: 7114.3908 | Q4: 1024472.3 | S4: =IFERROR(VLOOKUP(CONCATENATE(Fix_Mapping[[#This Row],[KODE BARANG]],1),'Form Fix'!$A$6:$F$911,4,0),0) -> 3171286 | T4: =IFERROR(VLOOKUP(CONCATENATE(Fix_Mapping[[#This Row],[KODE BARANG]],2),'Form Fix'!$A$6:$F$911,4,0),0) -> 3166924 | U4: =IFERROR(VLOOKUP(CONCATENATE(Fix_Mapping[[#This Row],[KODE BARANG]],3),'Form Fix'!$A$6:$F$911,4,0),0) -> 3060311 | V4: =IFERROR(VLOOKUP(CONCATENATE(Fix_Mapping[[#This Row],[KODE BARANG]],4),'Form Fix'!$A$6:$F$911,4,0),0) -> 3087451 | W4: =IFERROR(VLOOKUP(CONCATENATE(Fix_Mapping[[#This Row],[KODE BARANG]],5),'Form Fix'!$A$6:$F$911,4,0),0) -> ID8195121M
A5: R1021002010010 | B5: RB DETTOL BODY SOAP FAMILY PROTECT 100GR X 144 PCS | C5: 144 | D5: PCS | E5: DETTOL BODY SOAP | F5: 5864.5654 | G5: 844497.42 | H5: 6509.6676 | I5: 937392.14 | J5: 6409.3611 | K5: 922948 | L5: 7114.3908 | M5: 1024472.3 | N5: 6409.3611 | O5: 922948 | P5: 7114.3908 | Q5: 1024472.3 | S5: =IFERROR(VLOOKUP(CONCATENATE(Fix_Mapping[[#This Row],[KODE BARANG]],1),'Form Fix'!$A$6:$F$911,4,0),0) -> 3300517 | T5: =IFERROR(VLOOKUP(CONCATENATE(Fix_Mapping[[#This Row],[KODE BARANG]],2),'Form Fix'!$A$6:$F$911,4,0),0) -> 0 | U5: =IFERROR(VLOOKUP(CONCATENATE(Fix_Mapping[[#This Row],[KODE BARANG]],3),'Form Fix'!$A$6:$F$911,4,0),0) -> 0 | V5: =IFERROR(VLOOKUP(CONCATENATE(Fix_Mapping[[#This Row],[KODE BARANG]],4),'Form Fix'!$A$6:$F$911,4,0),0) -> 0 | W5: =IFERROR(VLOOKUP(CONCATENATE(Fix_Mapping[[#This Row],[KODE BARANG]],5),'Form Fix'!$A$6:$F$911,4,0),0) -> 0
A6: R1021003006010 | B6: RB DETTOL BODY SOAP FRESH 60GR X 144 PCS | C6: 144 | D6: PCS | E6: DETTOL BODY SOAP | F6: 3048.78 | G6: 439024.32 | H6: 3384.1458 | I6: 487317 | J6: 3332 | K6: 479808 | L6: 3698.52 | M6: 532586.88 | N6: 3332 | O6: 479808 | P6: 3698.52 | Q6: 532586.88 | S6: =IFERROR(VLOOKUP(CONCATENATE(Fix_Mapping[[#This Row],[KODE BARANG]],1),'Form Fix'!$A$6:$F$911,4,0),0) -> 3170933 | T6: =IFERROR(VLOOKUP(CONCATENATE(Fix_Mapping[[#This Row],[KODE BARANG]],2),'Form Fix'!$A$6:$F$911,4,0),0) -> 3147626 | U6: =IFERROR(VLOOKUP(CONCATENATE(Fix_Mapping[[#This Row],[KODE BARANG]],3),'Form Fix'!$A$6:$F$911,4,0),0) -> 0 | V6: =IFERROR(VLOOKUP(CONCATENATE(Fix_Mapping[[#This Row],[KODE BARANG]],4),'Form Fix'!$A$6:$F$911,4,0),0) -> 0 | W6: =IFERROR(VLOOKUP(CONCATENATE(Fix_Mapping[[#This Row],[KODE BARANG]],5),'Form Fix'!$A$6:$F$911,4,0),0) -> 0
A7: R1021003010010 | B7: RB DETTOL BODY SOAP FRESH 100GR X 144 PCS | C7: 144 | D7: PCS | E7: DETTOL BODY SOAP | F7: 5864.5654 | G7: 844497.42 | H7: 6509.6676 | I7: 937392.14 | J7: 6409.3611 | K7: 922948 | L7: 7114.3908 | M7: 1024472.3 | O7: 0 | P7: 0 | Q7: 0 | S7: =IFERROR(VLOOKUP(CONCATENATE(Fix_Mapping[[#This Row],[KODE BARANG]],1),'Form Fix'!$A$6:$F$911,4,0),0) -> 3170945 | T7: =IFERROR(VLOOKUP(CONCATENATE(Fix_Mapping[[#This Row],[KODE BARANG]],2),'Form Fix'!$A$6:$F$911,4,0),0) -> 0 | U7: =IFERROR(VLOOKUP(CONCATENATE(Fix_Mapping[[#This Row],[KODE BARANG]],3),'Form Fix'!$A$6:$F$911,4,0),0) -> 0 | V7: =IFERROR(VLOOKUP(CONCATENATE(Fix_Mapping[[#This Row],[KODE BARANG]],4),'Form Fix'!$A$6:$F$911,4,0),0) -> 0 | W7: =IFERROR(VLOOKUP(CONCATENATE(Fix_Mapping[[#This Row],[KODE BARANG]],5),'Form Fix'!$A$6:$F$911,4,0),0) -> 0
A8: R1021004006010 | B8: RB DETTOL BODY SOAP LASTING 60GR X 144 PCS | C8: 144 | D8: PCS | E8: DETTOL BODY SOAP | F8: 3048.78 | G8: 439024.32 | H8: 3384.1458 | I8: 487317 | J8: 3332 | K8: 479808 | L8: 3698.52 | M8: 532586.88 | N8: 3332 | O8: 479808 | P8: 3698.52 | Q8: 532586.88 | S8: =IFERROR(VLOOKUP(CONCATENATE(Fix_Mapping[[#This Row],[KODE BARANG]],1),'Form Fix'!$A$6:$F$911,4,0),0) -> 3166937 | T8: =IFERROR(VLOOKUP(CONCATENATE(Fix_Mapping[[#This Row],[KODE BARANG]],2),'Form Fix'!$A$6:$F$911,4,0),0) -> 3148248 | U8: =IFERROR(VLOOKUP(CONCATENATE(Fix_Mapping[[#This Row],[KODE BARANG]],3),'Form Fix'!$A$6:$F$911,4,0),0) -> 0 | V8: =IFERROR(VLOOKUP(CONCATENATE(Fix_Mapping[[#This Row],[KODE BARANG]],4),'Form Fix'!$A$6:$F$911,4,0),0) -> 0 | W8: =IFERROR(VLOOKUP(CONCATENATE(Fix_Mapping[[#This Row],[KODE BARANG]],5),'Form Fix'!$A$6:$F$911,4,0),0) -> 0
A9: R1021004010010 | B9: RB DETTOL BODY SOAP LASTING 100GR X 144 PCS | C9: 144 | D9: PCS | E9: DETTOL BODY SOAP | F9: 5864.5654 | G9: 844497.42 | H9: 6509.6676 | I9: 937392.14 | J9: 6409.3611 | K9: 922948 | L9: 7114.3908 | M9: 1024472.3 | N9: 6409.3611 | O9: 922948 | P9: 7114.3908 | Q9: 1024472.3 | S9: =IFERROR(VLOOKUP(CONCATENATE(Fix_Mapping[[#This Row],[KODE BARANG]],1),'Form Fix'!$A$6:$F$911,4,0),0) -> 3166942 | T9: =IFERROR(VLOOKUP(CONCATENATE(Fix_Mapping[[#This Row],[KODE BARANG]],2),'Form Fix'!$A$6:$F$911,4,0),0) -> 3060668 | U9: =IFERROR(VLOOKUP(CONCATENATE(Fix_Mapping[[#This Row],[KODE BARANG]],3),'Form Fix'!$A$6:$F$911,4,0),0) -> 3087594 | V9: =IFERROR(VLOOKUP(CONCATENATE(Fix_Mapping[[#This Row],[KODE BARANG]],4),'Form Fix'!$A$6:$F$911,4,0),0) -> ID8195069M | W9: =IFERROR(VLOOKUP(CONCATENATE(Fix_Mapping[[#This Row],[KODE BARANG]],5),'Form Fix'!$A$6:$F$911,4,0),0) -> 3031729
A10: R1021005006010 | B10: RB DETTOL BODY SOAP ORIGINAL 60GR X 144 PCS | C10: 144 | D10: PCS | E10: DETTOL BODY SOAP | F10: 3048.78 | G10: 439024.32 | H10: 3384.1458 | I10: 487317 | J10: 3332 | K10: 479808 | L10: 3698.52 | M10: 532586.88 | N10: 3332 | O10: 479808 | P10: 3698.52 | Q10: 532586.88 | S10: =IFERROR(VLOOKUP(CONCATENATE(Fix_Mapping[[#This Row],[KODE BARANG]],1),'Form Fix'!$A$6:$F$911,4,0),0) -> 3166975 | T10: =IFERROR(VLOOKUP(CONCATENATE(Fix_Mapping[[#This Row],[KODE BARANG]],2),'Form Fix'!$A$6:$F$911,4,0),0) -> 3331433 | U10: =IFERROR(VLOOKUP(CONCATENATE(Fix_Mapping[[#This Row],[KODE BARANG]],3),'Form Fix'!$A$6:$F$911,4,0),0) -> 3119259 | V10: =IFERROR(VLOOKUP(CONCATENATE(Fix_Mapping[[#This Row],[KODE BARANG]],4),'Form Fix'!$A$6:$F$911,4,0),0) -> 3238406 | W10: =IFERROR(VLOOKUP(CONCATENATE(Fix_Mapping[[#This Row],[KODE BARANG]],5),'Form Fix'!$A$6:$F$911,4,0),0) -> 3224742
A11: R1021005010010 | B11: RB DETTOL BODY SOAP ORIGINAL 100GR X 144 PCS | C11: 144 | D11: PCS | E11: DETTOL BODY SOAP | F11: 5864.5654 | G11: 844497.42 | H11: 6509.6676 | I11: 937392.14 | J11: 6409.3611 | K11: 922948 | L11: 7114.3908 | M11: 1024472.3 | N11: 6409.3611 | O11: 922948 | P11: 7114.3908 | Q11: 1024472.3 | S11: =IFERROR(VLOOKUP(CONCATENATE(Fix_Mapping[[#This Row],[KODE BARANG]],1),'Form Fix'!$A$6:$F$911,4,0),0) -> 3166958 | T11: =IFERROR(VLOOKUP(CONCATENATE(Fix_Mapping[[#This Row],[KODE BARANG]],2),'Form Fix'!$A$6:$F$911,4,0),0) -> 3083294 | U11: =IFERROR(VLOOKUP(CONCATENATE(Fix_Mapping[[#This Row],[KODE BARANG]],3),'Form Fix'!$A$6:$F$911,4,0),0) -> 3238701 | V11: =IFERROR(VLOOKUP(CONCATENATE(Fix_Mapping[[#This Row],[KODE BARANG]],4),'Form Fix'!$A$6:$F$911,4,0),0) -> 3061093 | W11: =IFERROR(VLOOKUP(CONCATENATE(Fix_Mapping[[#This Row],[KODE BARANG]],5),'Form Fix'!$A$6:$F$911,4,0),0) -> 3224745
A12: R1021006006010 | B12: RB DETTOL BODY SOAP RE-ENERGIZER 60GR X 144 PCS | C12: 144 | D12: PCS | E12: DETTOL BODY SOAP | F12: 3048.78 | G12: 439024.32 | H12: 3384.1458 | I12: 487317 | J12: 3332 | K12: 479808 | L12: 3698.52 | M12: 532586.88 | N12: 3332 | O12: 479808 | P12: 3698.52 | Q12: 532586.88 | S12: =IFERROR(VLOOKUP(CONCATENATE(Fix_Mapping[[#This Row],[KODE BARANG]],1),'Form Fix'!$A$6:$F$911,4,0),0) -> 3193502 | T12: =IFERROR(VLOOKUP(CONCATENATE(Fix_Mapping[[#This Row],[KODE BARANG]],2),'Form Fix'!$A$6:$F$911,4,0),0) -> 0 | U12: =IFERROR(VLOOKUP(CONCATENATE(Fix_Mapping[[#This Row],[KODE BARANG]],3),'Form Fix'!$A$6:$F$911,4,0),0) -> 0 | V12: =IFERROR(VLOOKUP(CONCATENATE(Fix_Mapping[[#This Row],[KODE BARANG]],4),'Form Fix'!$A$6:$F$911,4,0),0) -> 0 | W12: =IFERROR(VLOOKUP(CONCATENATE(Fix_Mapping[[#This Row],[KODE BARANG]],5),'Form Fix'!$A$6:$F$911,4,0),0) -> 0
A13: R1021007006010 | B13: RB DETTOL BODY SOAP SKINCARE 60GR X 144 PCS | C13: 144 | D13: PCS | E13: DETTOL BODY SOAP | F13: 3048.78 | G13: 439024.32 | H13: 3384.1458 | I13: 487317 | J13: 3332 | K13: 479808 | L13: 3698.52 | M13: 532586.88 | N13: 3332 | O13: 479808 | P13: 3698.52 | Q13: 532586.88 | S13: =IFERROR(VLOOKUP(CONCATENATE(Fix_Mapping[[#This Row],[KODE BARANG]],1),'Form Fix'!$A$6:$F$911,4,0),0) -> 3193501 | T13: =IFERROR(VLOOKUP(CONCATENATE(Fix_Mapping[[#This Row],[KODE BARANG]],2),'Form Fix'!$A$6:$F$911,4,0),0) -> 3337511 | U13: =IFERROR(VLOOKUP(CONCATENATE(Fix_Mapping[[#This Row],[KODE BARANG]],3),'Form Fix'!$A$6:$F$911,4,0),0) -> 0 | V13: =IFERROR(VLOOKUP(CONCATENATE(Fix_Mapping[[#This Row],[KODE BARANG]],4),'Form Fix'!$A$6:$F$911,4,0),0) -> 0 | W13: =IFERROR(VLOOKUP(CONCATENATE(Fix_Mapping[[#This Row],[KODE BARANG]],5),'Form Fix'!$A$6:$F$911,4,0),0) -> 0
A14: R1021008006010 | B14: RB DETTOL BODY SOAP 3SP LASTING FRESH 60GR X 48 PCS | C14: 48 | D14: PCS | E14: DETTOL BODY SOAP | F14: 8231.7022 | G14: 395121.71 | H14: 9137.1894 | I14: 438585.09 | J14: 8996.3958 | K14: 431827 | L14: 9985.9994 | M14: 479327.97 | O14: 0 | P14: 0 | Q14: 0 | S14: =IFERROR(VLOOKUP(CONCATENATE(Fix_Mapping[[#This Row],[KODE BARANG]],1),'Form Fix'!$A$6:$F$911,4,0),0) -> 3346278 | T14: =IFERROR(VLOOKUP(CONCATENATE(Fix_Mapping[[#This Row],[KODE BARANG]],2),'Form Fix'!$A$6:$F$911,4,0),0) -> 3347342 | U14: =IFERROR(VLOOKUP(CONCATENATE(Fix_Mapping[[#This Row],[KODE BARANG]],3),'Form Fix'!$A$6:$F$911,4,0),0) -> 0 | V14: =IFERROR(VLOOKUP(CONCATENATE(Fix_Mapping[[#This Row],[KODE BARANG]],4),'Form Fix'!$A$6:$F$911,4,0),0) -> 0 | W14: =IFERROR(VLOOKUP(CONCATENATE(Fix_Mapping[[#This Row],[KODE BARANG]],5),'Form Fix'!$A$6:$F$911,4,0),0) -> 0
A15: R1021101006510 | B15: RB DETTOL BODY SOAP 3SP COOL 65GR X 48 PCS | C15: 48 | D15: PCS | E15: DETTOL BODY SOAP | F15: 8232.255 | G15: 395148.24 | H15: 9137.8031 | I15: 438614.55 | J15: 8997 | K15: 431856 | L15: 9986.67 | M15: 479360.16 | N15: 8997 | O15: 431856 | P15: 9986.67 | Q15: 479360.16 | S15: =IFERROR(VLOOKUP(CONCATENATE(Fix_Mapping[[#This Row],[KODE BARANG]],1),'Form Fix'!$A$6:$F$911,4,0),0) -> 3205578 | T15: =IFERROR(VLOOKUP(CONCATENATE(Fix_Mapping[[#This Row],[KODE BARANG]],2),'Form Fix'!$A$6:$F$911,4,0),0) -> 3171290 | U15: =IFERROR(VLOOKUP(CONCATENATE(Fix_Mapping[[#This Row],[KODE BARANG]],3),'Form Fix'!$A$6:$F$911,4,0),0) -> 3166920 | V15: =IFERROR(VLOOKUP(CONCATENATE(Fix_Mapping[[#This Row],[KODE BARANG]],4),'Form Fix'!$A$6:$F$911,4,0),0) -> 3060315 | W15: =IFERROR(VLOOKUP(CONCATENATE(Fix_Mapping[[#This Row],[KODE BARANG]],5),'Form Fix'!$A$6:$F$911,4,0),0) -> 3087442
A16: R1021101010010 | B16: RB DETTOL BODY SOAP 3SP COOL 100GR X 48 PCS | C16: 48 | D16: PCS | E16: DETTOL BODY SOAP | F16: 16012.5 | G16: 768600 | H16: 17773.875 | I16: 853146 | J16: 17500 | K16: 840000 | L16: 19425 | M16: 932400 | N16: 17500 | O16: 840000 | P16: 19425 | Q16: 932400 | S16: =IFERROR(VLOOKUP(CONCATENATE(Fix_Mapping[[#This Row],[KODE BARANG]],1),'Form Fix'!$A$6:$F$911,4,0),0) -> 0 | T16: =IFERROR(VLOOKUP(CONCATENATE(Fix_Mapping[[#This Row],[KODE BARANG]],2),'Form Fix'!$A$6:$F$911,4,0),0) -> 0 | U16: =IFERROR(VLOOKUP(CONCATENATE(Fix_Mapping[[#This Row],[KODE BARANG]],3),'Form Fix'!$A$6:$F$911,4,0),0) -> 0 | V16: =IFERROR(VLOOKUP(CONCATENATE(Fix_Mapping[[#This Row],[KODE BARANG]],4),'Form Fix'!$A$6:$F$911,4,0),0) -> 0 | W16: =IFERROR(VLOOKUP(CONCATENATE(Fix_Mapping[[#This Row],[KODE BARANG]],5),'Form Fix'!$A$6:$F$911,4,0),0) -> 0
A17: R1021101010011 | B17: RB DETTOL BODY SOAP 3SP COOL 100GR X 36 PCS 3+1 | C17: 36 | D17: PCS | E17: DETTOL BODY SOAP | F17: 17593.696 | G17: 633373.06 | H17: 19529.003 | I17: 703044.1 | J17: 19228.083 | K17: 692211 | L17: 21343.173 | M17: 768354.21 | N17: 6409.3656 | O17: 230737.16 | P17: 7114.3958 | Q17: 256118.25 | S17: =IFERROR(VLOOKUP(CONCATENATE(Fix_Mapping[[#This Row],[KODE BARANG]],1),'Form Fix'!$A$6:$F$911,4,0),0) -> 0 | T17: =IFERROR(VLOOKUP(CONCATENATE(Fix_Mapping[[#This Row],[KODE BARANG]],2),'Form Fix'!$A$6:$F$911,4,0),0) -> 0 | U17: =IFERROR(VLOOKUP(CONCATENATE(Fix_Mapping[[#This Row],[KODE BARANG]],3),'Form Fix'!$A$6:$F$911,4,0),0) -> 0 | V17: =IFERROR(VLOOKUP(CONCATENATE(Fix_Mapping[[#This Row],[KODE BARANG]],4),'Form Fix'!$A$6:$F$911,4,0),0) -> 0 | W17: =IFERROR(VLOOKUP(CONCATENATE(Fix_Mapping[[#This Row],[KODE BARANG]],5),'Form Fix'!$A$6:$F$911,4,0),0) -> 0
A18: R1021102010010 | B18: RB DETTOL BODY SOAP 3SP FAMILY PROTECT 100GR X 48 PCS | C18: 48 | D18: PCS | E18: DETTOL BODY SOAP | F18: 16012.5 | G18: 768600 | H18: 17773.875 | I18: 853146 | J18: 17500 | K18: 840000 | L18: 19425 | M18: 932400 | N18: 17500 | O18: 840000 | P18: 19425 | Q18: 932400 | S18: =IFERROR(VLOOKUP(CONCATENATE(Fix_Mapping[[#This Row],[KODE BARANG]],1),'Form Fix'!$A$6:$F$911,4,0),0) -> 0 | T18: =IFERROR(VLOOKUP(CONCATENATE(Fix_Mapping[[#This Row],[KODE BARANG]],2),'Form Fix'!$A$6:$F$911,4,0),0) -> 0 | U18: =IFERROR(VLOOKUP(CONCATENATE(Fix_Mapping[[#This Row],[KODE BARANG]],3),'Form Fix'!$A$6:$F$911,4,0),0) -> 0 | V18: =IFERROR(VLOOKUP(CONCATENATE(Fix_Mapping[[#This Row],[KODE BARANG]],4),'Form Fix'!$A$6:$F$911,4,0),0) -> 0 | W18: =IFERROR(VLOOKUP(CONCATENATE(Fix_Mapping[[#This Row],[KODE BARANG]],5),'Form Fix'!$A$6:$F$911,4,0),0) -> 0
A19: R1021103006510 | B19: RB DETTOL BODY SOAP 3SP FRESH 65GR X 48 PCS | C19: 48 | D19: PCS | E19: DETTOL BODY SOAP | F19: 8232.255 | G19: 395148.24 | H19: 9137.8031 | I19: 438614.55 | J19: 8997 | K19: 431856 | L19: 9986.67 | M19: 479360.16 | N19: 8997 | O19: 431856 | P19: 9986.67 | Q19: 479360.16 | S19: =IFERROR(VLOOKUP(CONCATENATE(Fix_Mapping[[#This Row],[KODE BARANG]],1),'Form Fix'!$A$6:$F$911,4,0),0) -> 0 | T19: =IFERROR(VLOOKUP(CONCATENATE(Fix_Mapping[[#This Row],[KODE BARANG]],2),'Form Fix'!$A$6:$F$911,4,0),0) -> 0 | U19: =IFERROR(VLOOKUP(CONCATENATE(Fix_Mapping[[#This Row],[KODE BARANG]],3),'Form Fix'!$A$6:$F$911,4,0),0) -> 0 | V19: =IFERROR(VLOOKUP(CONCATENATE(Fix_Mapping[[#This Row],[KODE BARANG]],4),'Form Fix'!$A$6:$F$911,4,0),0) -> 0 | W19: =IFERROR(VLOOKUP(CONCATENATE(Fix_Mapping[[#This Row],[KODE BARANG]],5),'Form Fix'!$A$6:$F$911,4,0),0) -> 0
A20: R1021103010010 | B20: RB DETTOL BODY SOAP 3SP FRESH 100GR X 48 PCS | C20: 48 | D20: PCS | E20: DETTOL BODY SOAP | F20: 16012.5 | G20: 768600 | H20: 17773.875 | I20: 853146 | J20: 17500 | K20: 840000 | L20: 19425 | M20: 932400 | N20: 17500 | O20: 840000 | P20: 19425 | Q20: 932400 | S20: =IFERROR(VLOOKUP(CONCATENATE(Fix_Mapping[[#This Row],[KODE BARANG]],1),'Form Fix'!$A$6:$F$911,4,0),0) -> 0 | T20: =IFERROR(VLOOKUP(CONCATENATE(Fix_Mapping[[#This Row],[KODE BARANG]],2),'Form Fix'!$A$6:$F$911,4,0),0) -> 0 | U20: =IFERROR(VLOOKUP(CONCATENATE(Fix_Mapping[[#This Row],[KODE BARANG]],3),'Form Fix'!$A$6:$F$911,4,0),0) -> 0 | V20: =IFERROR(VLOOKUP(CONCATENATE(Fix_Mapping[[#This Row],[KODE BARANG]],4),'Form Fix'!$A$6:$F$911,4,0),0) -> 0 | W20: =IFERROR(VLOOKUP(CONCATENATE(Fix_Mapping[[#This Row],[KODE BARANG]],5),'Form Fix'!$A$6:$F$911,4,0),0) -> 0
A21: R1021103010011 | B21: RB DETTOL BODY SOAP 3SP FRESH 100GR X 36 PCS 3+1 | C21: 36 | D21: PCS | E21: DETTOL BODY SOAP | F21: 17593.696 | G21: 633373.06 | H21: 19529.003 | I21: 703044.1 | J21: 19228.083 | K21: 692211 | L21: 21343.173 | M21: 768354.21 | N21: 6409.3656 | O21: 230737.16 | P21: 7114.3958 | Q21: 256118.25 | S21: =IFERROR(VLOOKUP(CONCATENATE(Fix_Mapping[[#This Row],[KODE BARANG]],1),'Form Fix'!$A$6:$F$911,4,0),0) -> 0 | T21: =IFERROR(VLOOKUP(CONCATENATE(Fix_Mapping[[#This Row],[KODE BARANG]],2),'Form Fix'!$A$6:$F$911,4,0),0) -> 0 | U21: =IFERROR(VLOOKUP(CONCATENATE(Fix_Mapping[[#This Row],[KODE BARANG]],3),'Form Fix'!$A$6:$F$911,4,0),0) -> 0 | V21: =IFERROR(VLOOKUP(CONCATENATE(Fix_Mapping[[#This Row],[KODE BARANG]],4),'Form Fix'!$A$6:$F$911,4,0),0) -> 0 | W21: =IFERROR(VLOOKUP(CONCATENATE(Fix_Mapping[[#This Row],[KODE BARANG]],5),'Form Fix'!$A$6:$F$911,4,0),0) -> 0
A22: R1021104010010 | B22: RB DETTOL BODY SOAP 3SP LASTING 100GR X 48 PCS | C22: 48 | D22: PCS | E22: DETTOL BODY SOAP | F22: 16012.5 | G22: 768600 | H22: 17773.875 | I22: 853146 | J22: 17500 | K22: 840000 | L22: 19425 | M22: 932400 | N22: 17500 | O22: 840000 | P22: 19425 | Q22: 932400 | S22: =IFERROR(VLOOKUP(CONCATENATE(Fix_Mapping[[#This Row],[KODE BARANG]],1),'Form Fix'!$A$6:$F$911,4,0),0) -> 0 | T22: =IFERROR(VLOOKUP(CONCATENATE(Fix_Mapping[[#This Row],[KODE BARANG]],2),'Form Fix'!$A$6:$F$911,4,0),0) -> 0 | U22: =IFERROR(VLOOKUP(CONCATENATE(Fix_Mapping[[#This Row],[KODE BARANG]],3),'Form Fix'!$A$6:$F$911,4,0),0) -> 0 | V22: =IFERROR(VLOOKUP(CONCATENATE(Fix_Mapping[[#This Row],[KODE BARANG]],4),'Form Fix'!$A$6:$F$911,4,0),0) -> 0 | W22: =IFERROR(VLOOKUP(CONCATENATE(Fix_Mapping[[#This Row],[KODE BARANG]],5),'Form Fix'!$A$6:$F$911,4,0),0) -> 0
A23: R1021104010011 | B23: RB DETTOL BODY SOAP 3SP LASTING 100GR X 36 PCS 3+1 | C23: 36 | D23: PCS | E23: DETTOL BODY SOAP | F23: 17593.696 | G23: 633373.06 | H23: 19529.003 | I23: 703044.1 | J23: 19228.083 | K23: 692211 | L23: 21343.173 | M23: 768354.21 | N23: 6409.3656 | O23: 230737.16 | P23: 7114.3958 | Q23: 256118.25 | S23: =IFERROR(VLOOKUP(CONCATENATE(Fix_Mapping[[#This Row],[KODE BARANG]],1),'Form Fix'!$A$6:$F$911,4,0),0) -> 0 | T23: =IFERROR(VLOOKUP(CONCATENATE(Fix_Mapping[[#This Row],[KODE BARANG]],2),'Form Fix'!$A$6:$F$911,4,0),0) -> 0 | U23: =IFERROR(VLOOKUP(CONCATENATE(Fix_Mapping[[#This Row],[KODE BARANG]],3),'Form Fix'!$A$6:$F$911,4,0),0) -> 0 | V23: =IFERROR(VLOOKUP(CONCATENATE(Fix_Mapping[[#This Row],[KODE BARANG]],4),'Form Fix'!$A$6:$F$911,4,0),0) -> 0 | W23: =IFERROR(VLOOKUP(CONCATENATE(Fix_Mapping[[#This Row],[KODE BARANG]],5),'Form Fix'!$A$6:$F$911,4,0),0) -> 0
A24: R1021105006010 | B24: RB DETTOL BODY SOAP 3SP ORIGINAL 60GR X 48 PCS | C24: 48 | D24: PCS | E24: DETTOL BODY SOAP | F24: 8232.255 | G24: 395148.24 | H24: 9137.8031 | I24: 438614.55 | J24: 8997 | K24: 431856 | L24: 9986.67 | M24: 479360.16 | N24: 8997 | O24: 431856 | P24: 9986.67 | Q24: 479360.16 | S24: =IFERROR(VLOOKUP(CONCATENATE(Fix_Mapping[[#This Row],[KODE BARANG]],1),'Form Fix'!$A$6:$F$911,4,0),0) -> 0 | T24: =IFERROR(VLOOKUP(CONCATENATE(Fix_Mapping[[#This Row],[KODE BARANG]],2),'Form Fix'!$A$6:$F$911,4,0),0) -> 0 | U24: =IFERROR(VLOOKUP(CONCATENATE(Fix_Mapping[[#This Row],[KODE BARANG]],3),'Form Fix'!$A$6:$F$911,4,0),0) -> 0 | V24: =IFERROR(VLOOKUP(CONCATENATE(Fix_Mapping[[#This Row],[KODE BARANG]],4),'Form Fix'!$A$6:$F$911,4,0),0) -> 0 | W24: =IFERROR(VLOOKUP(CONCATENATE(Fix_Mapping[[#This Row],[KODE BARANG]],5),'Form Fix'!$A$6:$F$911,4,0),0) -> 0
A25: R1021105010010 | B25: RB DETTOL BODY SOAP 3SP ORIGINAL 100GR X 48 PCS | C25: 48 | D25: PCS | E25: DETTOL BODY SOAP | F25: 16012.5 | G25: 768600 | H25: 17773.875 | I25: 853146 | J25: 17500 | K25: 840000 | L25: 19425 | M25: 932400 | N25: 17500 | O25: 840000 | P25: 19425 | Q25: 932400 | S25: =IFERROR(VLOOKUP(CONCATENATE(Fix_Mapping[[#This Row],[KODE BARANG]],1),'Form Fix'!$A$6:$F$911,4,0),0) -> 0 | T25: =IFERROR(VLOOKUP(CONCATENATE(Fix_Mapping[[#This Row],[KODE BARANG]],2),'Form Fix'!$A$6:$F$911,4,0),0) -> 0 | U25: =IFERROR(VLOOKUP(CONCATENATE(Fix_Mapping[[#This Row],[KODE BARANG]],3),'Form Fix'!$A$6:$F$911,4,0),0) -> 0 | V25: =IFERROR(VLOOKUP(CONCATENATE(Fix_Mapping[[#This Row],[KODE BARANG]],4),'Form Fix'!$A$6:$F$911,4,0),0) -> 0 | W25: =IFERROR(VLOOKUP(CONCATENATE(Fix_Mapping[[#This Row],[KODE BARANG]],5),'Form Fix'!$A$6:$F$911,4,0),0) -> 0
A26: R1021105010011 | B26: RB DETTOL BODY SOAP 3SP ORIGINAL 100GR X 36 PCS 3+1 | C26: 36 | D26: PCS | E26: DETTOL BODY SOAP | F26: 17593.696 | G26: 633373.06 | H26: 19529.003 | I26: 703044.1 | J26: 19228.083 | K26: 692211 | L26: 21343.173 | M26: 768354.21 | N26: 6409.3656 | O26: 230737.16 | P26: 7114.3958 | Q26: 256118.25 | S26: =IFERROR(VLOOKUP(CONCATENATE(Fix_Mapping[[#This Row],[KODE BARANG]],1),'Form Fix'!$A$6:$F$911,4,0),0) -> 0 | T26: =IFERROR(VLOOKUP(CONCATENATE(Fix_Mapping[[#This Row],[KODE BARANG]],2),'Form Fix'!$A$6:$F$911,4,0),0) -> 0 | U26: =IFERROR(VLOOKUP(CONCATENATE(Fix_Mapping[[#This Row],[KODE BARANG]],3),'Form Fix'!$A$6:$F$911,4,0),0) -> 0 | V26: =IFERROR(VLOOKUP(CONCATENATE(Fix_Mapping[[#This Row],[KODE BARANG]],4),'Form Fix'!$A$6:$F$911,4,0),0) -> 0 | W26: =IFERROR(VLOOKUP(CONCATENATE(Fix_Mapping[[#This Row],[KODE BARANG]],5),'Form Fix'!$A$6:$F$911,4,0),0) -> 0
A27: R1021106006010 | B27: RB DETTOL BODY SOAP 3SP RE-ENERGIZER 60GR X 48 PCS | C27: 48 | D27: PCS | E27: DETTOL BODY SOAP | F27: 8231.7022 | G27: 395121.71 | H27: 9137.1894 | I27: 438585.09 | J27: 8996.3958 | K27: 431827 | L27: 9985.9994 | M27: 479327.97 | O27: 0 | P27: 0 | Q27: 0 | S27: =IFERROR(VLOOKUP(CONCATENATE(Fix_Mapping[[#This Row],[KODE BARANG]],1),'Form Fix'!$A$6:$F$911,4,0),0) -> 0 | T27: =IFERROR(VLOOKUP(CONCATENATE(Fix_Mapping[[#This Row],[KODE BARANG]],2),'Form Fix'!$A$6:$F$911,4,0),0) -> 0 | U27: =IFERROR(VLOOKUP(CONCATENATE(Fix_Mapping[[#This Row],[KODE BARANG]],3),'Form Fix'!$A$6:$F$911,4,0),0) -> 0 | V27: =IFERROR(VLOOKUP(CONCATENATE(Fix_Mapping[[#This Row],[KODE BARANG]],4),'Form Fix'!$A$6:$F$911,4,0),0) -> 0 | W27: =IFERROR(VLOOKUP(CONCATENATE(Fix_Mapping[[#This Row],[KODE BARANG]],5),'Form Fix'!$A$6:$F$911,4,0),0) -> 0
A28: R1021106010010 | B28: RB DETTOL BODY SOAP 3SP RE-ENERGIZER 100GR X 48 PCS | C28: 48 | D28: PCS | E28: DETTOL BODY SOAP | F28: 16012.5 | G28: 768600 | H28: 17773.875 | I28: 853146 | J28: 17500 | K28: 840000 | L28: 19425 | M28: 932400 | N28: 17500 | O28: 840000 | P28: 19425 | Q28: 932400 | S28: =IFERROR(VLOOKUP(CONCATENATE(Fix_Mapping[[#This Row],[KODE BARANG]],1),'Form Fix'!$A$6:$F$911,4,0),0) -> 0 | T28: =IFERROR(VLOOKUP(CONCATENATE(Fix_Mapping[[#This Row],[KODE BARANG]],2),'Form Fix'!$A$6:$F$911,4,0),0) -> 0 | U28: =IFERROR(VLOOKUP(CONCATENATE(Fix_Mapping[[#This Row],[KODE BARANG]],3),'Form Fix'!$A$6:$F$911,4,0),0) -> 0 | V28: =IFERROR(VLOOKUP(CONCATENATE(Fix_Mapping[[#This Row],[KODE BARANG]],4),'Form Fix'!$A$6:$F$911,4,0),0) -> 0 | W28: =IFERROR(VLOOKUP(CONCATENATE(Fix_Mapping[[#This Row],[KODE BARANG]],5),'Form Fix'!$A$6:$F$911,4,0),0) -> 0
A29: R1021107006010 | B29: RB DETTOL BODY SOAP 3SP SKINCARE 60GR X 48 PCS | C29: 48 | D29: PCS | E29: DETTOL BODY SOAP | F29: 8231.7022 | G29: 395121.71 | H29: 9137.1894 | I29: 438585.09 | J29: 8996.3958 | K29: 431827 | L29: 9985.9994 | M29: 479327.97 | O29: 0 | P29: 0 | Q29: 0 | S29: =IFERROR(VLOOKUP(CONCATENATE(Fix_Mapping[[#This Row],[KODE BARANG]],1),'Form Fix'!$A$6:$F$911,4,0),0) -> 0 | T29: =IFERROR(VLOOKUP(CONCATENATE(Fix_Mapping[[#This Row],[KODE BARANG]],2),'Form Fix'!$A$6:$F$911,4,0),0) -> 0 | U29: =IFERROR(VLOOKUP(CONCATENATE(Fix_Mapping[[#This Row],[KODE BARANG]],3),'Form Fix'!$A$6:$F$911,4,0),0) -> 0 | V29: =IFERROR(VLOOKUP(CONCATENATE(Fix_Mapping[[#This Row],[KODE BARANG]],4),'Form Fix'!$A$6:$F$911,4,0),0) -> 0 | W29: =IFERROR(VLOOKUP(CONCATENATE(Fix_Mapping[[#This Row],[KODE BARANG]],5),'Form Fix'!$A$6:$F$911,4,0),0) -> 0
A30: R1021107010010 | B30: RB DETTOL BODY SOAP 3SP SKINCARE 100GR X 48 PCS | C30: 48 | D30: PCS | E30: DETTOL BODY SOAP | F30: 16012.5 | G30: 768600 | H30: 17773.875 | I30: 853146 | J30: 17500 | K30: 840000 | L30: 19425 | M30: 932400 | N30: 17500 | O30: 840000 | P30: 19425 | Q30: 932400 | S30: =IFERROR(VLOOKUP(CONCATENATE(Fix_Mapping[[#This Row],[KODE BARANG]],1),'Form Fix'!$A$6:$F$911,4,0),0) -> 0 | T30: =IFERROR(VLOOKUP(CONCATENATE(Fix_Mapping[[#This Row],[KODE BARANG]],2),'Form Fix'!$A$6:$F$911,4,0),0) -> 0 | U30: =IFERROR(VLOOKUP(CONCATENATE(Fix_Mapping[[#This Row],[KODE BARANG]],3),'Form Fix'!$A$6:$F$911,4,0),0) -> 0 | V30: =IFERROR(VLOOKUP(CONCATENATE(Fix_Mapping[[#This Row],[KODE BARANG]],4),'Form Fix'!$A$6:$F$911,4,0),0) -> 0 | W30: =IFERROR(VLOOKUP(CONCATENATE(Fix_Mapping[[#This Row],[KODE BARANG]],5),'Form Fix'!$A$6:$F$911,4,0),0) -> 0
A31: R1021107010011 | B31: RB DETTOL BODY SOAP 3SP SKINCARE 100GR X 36 PCS 3+1 | C31: 36 | D31: PCS | E31: DETTOL BODY SOAP | F31: 17593.696 | G31: 633373.06 | H31: 19529.003 | I31: 703044.1 | J31: 19228.083 | K31: 692211 | L31: 21343.173 | M31: 768354.21 | N31: 17500 | O31: 630000 | P31: 19425 | Q31: 699300 | S31: =IFERROR(VLOOKUP(CONCATENATE(Fix_Mapping[[#This Row],[KODE BARANG]],1),'Form Fix'!$A$6:$F$911,4,0),0) -> 0 | T31: =IFERROR(VLOOKUP(CONCATENATE(Fix_Mapping[[#This Row],[KODE BARANG]],2),'Form Fix'!$A$6:$F$911,4,0),0) -> 0 | U31: =IFERROR(VLOOKUP(CONCATENATE(Fix_Mapping[[#This Row],[KODE BARANG]],3),'Form Fix'!$A$6:$F$911,4,0),0) -> 0 | V31: =IFERROR(VLOOKUP(CONCATENATE(Fix_Mapping[[#This Row],[KODE BARANG]],4),'Form Fix'!$A$6:$F$911,4,0),0) -> 0 | W31: =IFERROR(VLOOKUP(CONCATENATE(Fix_Mapping[[#This Row],[KODE BARANG]],5),'Form Fix'!$A$6:$F$911,4,0),0) -> 0
A32: R1021109010011 | B32: RB DETTOL BODY SOAP 3SP SKINCARE 100GR X 36 PCS 3+1 | C32: 36 | D32: PCS | E32: DETTOL BODY SOAP | F32: 17593.696 | G32: 633373.06 | H32: 19529.003 | I32: 703044.1 | J32: 19228.083 | K32: 692211 | L32: 21343.173 | M32: 768354.21 | N32: 6409.3656 | O32: 230737.16 | P32: 7114.3958 | Q32: 256118.25 | S32: =IFERROR(VLOOKUP(CONCATENATE(Fix_Mapping[[#This Row],[KODE BARANG]],1),'Form Fix'!$A$6:$F$911,4,0),0) -> 0 | T32: =IFERROR(VLOOKUP(CONCATENATE(Fix_Mapping[[#This Row],[KODE BARANG]],2),'Form Fix'!$A$6:$F$911,4,0),0) -> 0 | U32: =IFERROR(VLOOKUP(CONCATENATE(Fix_Mapping[[#This Row],[KODE BARANG]],3),'Form Fix'!$A$6:$F$911,4,0),0) -> 0 | V32: =IFERROR(VLOOKUP(CONCATENATE(Fix_Mapping[[#This Row],[KODE BARANG]],4),'Form Fix'!$A$6:$F$911,4,0),0) -> 0 | W32: =IFERROR(VLOOKUP(CONCATENATE(Fix_Mapping[[#This Row],[KODE BARANG]],5),'Form Fix'!$A$6:$F$911,4,0),0) -> 0
A33: R1021201010010 | B33: RB DETTOL BODY SOAP HK ALOE VERA 100GR X 144 PCS | C33: 144 | D33: PCS | E33: DETTOL BODY SOAP | F33: 5864.5695 | G33: 844498.01 | H33: 6509.6722 | I33: 937392.79 | J33: 6409.3656 | K33: 922948.65 | L33: 7114.3958 | M33: 1024473 | N33: 6409.3656 | O33: 922948.65 | P33: 7114.3958 | Q33: 1024473 | S33: =IFERROR(VLOOKUP(CONCATENATE(Fix_Mapping[[#This Row],[KODE BARANG]],1),'Form Fix'!$A$6:$F$911,4,0),0) -> 0 | T33: =IFERROR(VLOOKUP(CONCATENATE(Fix_Mapping[[#This Row],[KODE BARANG]],2),'Form Fix'!$A$6:$F$911,4,0),0) -> 0 | U33: =IFERROR(VLOOKUP(CONCATENATE(Fix_Mapping[[#This Row],[KODE BARANG]],3),'Form Fix'!$A$6:$F$911,4,0),0) -> 0 | V33: =IFERROR(VLOOKUP(CONCATENATE(Fix_Mapping[[#This Row],[KODE BARANG]],4),'Form Fix'!$A$6:$F$911,4,0),0) -> 0 | W33: =IFERROR(VLOOKUP(CONCATENATE(Fix_Mapping[[#This Row],[KODE BARANG]],5),'Form Fix'!$A$6:$F$911,4,0),0) -> 0
A34: R1021201010011 | B34: RB DETTOL BODY SOAP HK ALOE VERA 100GR X 36 PCS 3+1 | C34: 36 | D34: PCS | E34: DETTOL BODY SOAP | F34: 17593.696 | G34: 633373.06 | H34: 19529.003 | I34: 703044.1 | J34: 19228.083 | K34: 692211 | L34: 21343.173 | M34: 768354.21 | N34: 6409.3656 | O34: 230737.16 | P34: 7114.3958 | Q34: 256118.25 | S34: =IFERROR(VLOOKUP(CONCATENATE(Fix_Mapping[[#This Row],[KODE BARANG]],1),'Form Fix'!$A$6:$F$911,4,0),0) -> 0 | T34: =IFERROR(VLOOKUP(CONCATENATE(Fix_Mapping[[#This Row],[KODE BARANG]],2),'Form Fix'!$A$6:$F$911,4,0),0) -> 0 | U34: =IFERROR(VLOOKUP(CONCATENATE(Fix_Mapping[[#This Row],[KODE BARANG]],3),'Form Fix'!$A$6:$F$911,4,0),0) -> 0 | V34: =IFERROR(VLOOKUP(CONCATENATE(Fix_Mapping[[#This Row],[KODE BARANG]],4),'Form Fix'!$A$6:$F$911,4,0),0) -> 0 | W34: =IFERROR(VLOOKUP(CONCATENATE(Fix_Mapping[[#This Row],[KODE BARANG]],5),'Form Fix'!$A$6:$F$911,4,0),0) -> 0
A35: R1021202010010 | B35: RB DETTOL BODY SOAP HK COOL 100GR X 144 PCS | C35: 144 | D35: PCS | E35: DETTOL BODY SOAP | F35: 5864.5695 | G35: 844498.01 | H35: 6509.6722 | I35: 937392.79 | J35: 6409.3656 | K35: 922948.65 | L35: 7114.3958 | M35: 1024473 | N35: 6409.3656 | O35: 922948.65 | P35: 7114.3958 | Q35: 1024473 | S35: =IFERROR(VLOOKUP(CONCATENATE(Fix_Mapping[[#This Row],[KODE BARANG]],1),'Form Fix'!$A$6:$F$911,4,0),0) -> 0 | T35: =IFERROR(VLOOKUP(CONCATENATE(Fix_Mapping[[#This Row],[KODE BARANG]],2),'Form Fix'!$A$6:$F$911,4,0),0) -> 0 | U35: =IFERROR(VLOOKUP(CONCATENATE(Fix_Mapping[[#This Row],[KODE BARANG]],3),'Form Fix'!$A$6:$F$911,4,0),0) -> 0 | V35: =IFERROR(VLOOKUP(CONCATENATE(Fix_Mapping[[#This Row],[KODE BARANG]],4),'Form Fix'!$A$6:$F$911,4,0),0) -> 0 | W35: =IFERROR(VLOOKUP(CONCATENATE(Fix_Mapping[[#This Row],[KODE BARANG]],5),'Form Fix'!$A$6:$F$911,4,0),0) -> 0
A36: R1021203010010 | B36: RB DETTOL BODY SOAP HK FRESH 100GR X 144 PCS | C36: 144 | D36: PCS | E36: DETTOL BODY SOAP | F36: 5864.5695 | G36: 844498.01 | H36: 6509.6722 | I36: 937392.79 | J36: 6409.3656 | K36: 922948.65 | L36: 7114.3958 | M36: 1024473 | N36: 6409.3656 | O36: 922948.65 | P36: 7114.3958 | Q36: 1024473 | S36: =IFERROR(VLOOKUP(CONCATENATE(Fix_Mapping[[#This Row],[KODE BARANG]],1),'Form Fix'!$A$6:$F$911,4,0),0) -> 0 | T36: =IFERROR(VLOOKUP(CONCATENATE(Fix_Mapping[[#This Row],[KODE BARANG]],2),'Form Fix'!$A$6:$F$911,4,0),0) -> 0 | U36: =IFERROR(VLOOKUP(CONCATENATE(Fix_Mapping[[#This Row],[KODE BARANG]],3),'Form Fix'!$A$6:$F$911,4,0),0) -> 0 | V36: =IFERROR(VLOOKUP(CONCATENATE(Fix_Mapping[[#This Row],[KODE BARANG]],4),'Form Fix'!$A$6:$F$911,4,0),0) -> 0 | W36: =IFERROR(VLOOKUP(CONCATENATE(Fix_Mapping[[#This Row],[KODE BARANG]],5),'Form Fix'!$A$6:$F$911,4,0),0) -> 0
A37: R1021204010010 | B37: RB DETTOL BODY SOAP HK INVIGORATE 100GR X 144 PCS | C37: 144 | D37: PCS | E37: DETTOL BODY SOAP | F37: 5864.5695 | G37: 844498.01 | H37: 6509.6722 | I37: 937392.79 | J37: 6409.3656 | K37: 922948.65 | L37: 7114.3958 | M37: 1024473 | N37: 6409.3656 | O37: 922948.65 | P37: 7114.3958 | Q37: 1024473 | S37: =IFERROR(VLOOKUP(CONCATENATE(Fix_Mapping[[#This Row],[KODE BARANG]],1),'Form Fix'!$A$6:$F$911,4,0),0) -> 0 | T37: =IFERROR(VLOOKUP(CONCATENATE(Fix_Mapping[[#This Row],[KODE BARANG]],2),'Form Fix'!$A$6:$F$911,4,0),0) -> 0 | U37: =IFERROR(VLOOKUP(CONCATENATE(Fix_Mapping[[#This Row],[KODE BARANG]],3),'Form Fix'!$A$6:$F$911,4,0),0) -> 0 | V37: =IFERROR(VLOOKUP(CONCATENATE(Fix_Mapping[[#This Row],[KODE BARANG]],4),'Form Fix'!$A$6:$F$911,4,0),0) -> 0 | W37: =IFERROR(VLOOKUP(CONCATENATE(Fix_Mapping[[#This Row],[KODE BARANG]],5),'Form Fix'!$A$6:$F$911,4,0),0) -> 0
A38: R1021204010011 | B38: RB DETTOL BODY SOAP HK INVIGORATE 100GR X 36 PCS 3+1 | C38: 36 | D38: PCS | E38: DETTOL BODY SOAP | F38: 17593.696 | G38: 633373.06 | H38: 19529.003 | I38: 703044.1 | J38: 19228.083 | K38: 692211 | L38: 21343.173 | M38: 768354.21 | N38: 6409.3656 | O38: 230737.16 | P38: 7114.3958 | Q38: 256118.25 | S38: =IFERROR(VLOOKUP(CONCATENATE(Fix_Mapping[[#This Row],[KODE BARANG]],1),'Form Fix'!$A$6:$F$911,4,0),0) -> 0 | T38: =IFERROR(VLOOKUP(CONCATENATE(Fix_Mapping[[#This Row],[KODE BARANG]],2),'Form Fix'!$A$6:$F$911,4,0),0) -> 0 | U38: =IFERROR(VLOOKUP(CONCATENATE(Fix_Mapping[[#This Row],[KODE BARANG]],3),'Form Fix'!$A$6:$F$911,4,0),0) -> 0 | V38: =IFERROR(VLOOKUP(CONCATENATE(Fix_Mapping[[#This Row],[KODE BARANG]],4),'Form Fix'!$A$6:$F$911,4,0),0) -> 0 | W38: =IFERROR(VLOOKUP(CONCATENATE(Fix_Mapping[[#This Row],[KODE BARANG]],5),'Form Fix'!$A$6:$F$911,4,0),0) -> 0
A39: R1021205010010 | B39: RB DETTOL BODY SOAP HK LASTING 100GR X 144 PCS | C39: 144 | D39: PCS | E39: DETTOL BODY SOAP | F39: 5864.5695 | G39: 844498.01 | H39: 6509.6722 | I39: 937392.79 | J39: 6409.3656 | K39: 922948.65 | L39: 7114.3958 | M39: 1024473 | N39: 6409.3656 | O39: 922948.65 | P39: 7114.3958 | Q39: 1024473 | S39: =IFERROR(VLOOKUP(CONCATENATE(Fix_Mapping[[#This Row],[KODE BARANG]],1),'Form Fix'!$A$6:$F$911,4,0),0) -> 0 | T39: =IFERROR(VLOOKUP(CONCATENATE(Fix_Mapping[[#This Row],[KODE BARANG]],2),'Form Fix'!$A$6:$F$911,4,0),0) -> 0 | U39: =IFERROR(VLOOKUP(CONCATENATE(Fix_Mapping[[#This Row],[KODE BARANG]],3),'Form Fix'!$A$6:$F$911,4,0),0) -> 0 | V39: =IFERROR(VLOOKUP(CONCATENATE(Fix_Mapping[[#This Row],[KODE BARANG]],4),'Form Fix'!$A$6:$F$911,4,0),0) -> 0 | W39: =IFERROR(VLOOKUP(CONCATENATE(Fix_Mapping[[#This Row],[KODE BARANG]],5),'Form Fix'!$A$6:$F$911,4,0),0) -> 0
A40: R1021205010011 | B40: RB DETTOL BODY SOAP HK LASTING 100GR X 36 PCS 3+1 | C40: 36 | D40: PCS | E40: DETTOL BODY SOAP | F40: 17593.696 | G40: 633373.06 | H40: 19529.003 | I40: 703044.1 | J40: 19228.083 | K40: 692211 | L40: 21343.173 | M40: 768354.21 | N40: 6409.3656 | O40: 230737.16 | P40: 7114.3958 | Q40: 256118.25 | S40: =IFERROR(VLOOKUP(CONCATENATE(Fix_Mapping[[#This Row],[KODE BARANG]],1),'Form Fix'!$A$6:$F$911,4,0),0) -> 0 | T40: =IFERROR(VLOOKUP(CONCATENATE(Fix_Mapping[[#This Row],[KODE BARANG]],2),'Form Fix'!$A$6:$F$911,4,0),0) -> 0 | U40: =IFERROR(VLOOKUP(CONCATENATE(Fix_Mapping[[#This Row],[KODE BARANG]],3),'Form Fix'!$A$6:$F$911,4,0),0) -> 0 | V40: =IFERROR(VLOOKUP(CONCATENATE(Fix_Mapping[[#This Row],[KODE BARANG]],4),'Form Fix'!$A$6:$F$911,4,0),0) -> 0 | W40: =IFERROR(VLOOKUP(CONCATENATE(Fix_Mapping[[#This Row],[KODE BARANG]],5),'Form Fix'!$A$6:$F$911,4,0),0) -> 0
...

Sheet Query Map.BrgDoubleDms
A1: Kode BARANG Win2 | B1: Nama Win | C1: PCPL KODE 1 | D1: PCPL KODE 2 | E1: PCPL KODE 3 | F1: PCPL KODE 4 | G1: PCPL KODE 5
A2: R1011000010010 | B2: RB BRASSO METAL POOLISH 100ML X 48 PCS | C2: =IFERROR(VLOOKUP(CONCATENATE(Table43_1[[#This Row],[Kode BARANG Win2]],1),'Form Fix'!$A$6:$F$911,4,0),0) -> 3121445 | D2: =IFERROR(VLOOKUP(CONCATENATE(Table43_1[[#This Row],[Kode BARANG Win2]],2),'Form Fix'!$A$6:$F$911,4,0),0) -> 3055580 | E2: =IFERROR(VLOOKUP(CONCATENATE(Table43_1[[#This Row],[Kode BARANG Win2]],3),'Form Fix'!$A$6:$F$911,4,0),0) -> ID020064 | F2: =IFERROR(VLOOKUP(CONCATENATE(Table43_1[[#This Row],[Kode BARANG Win2]],4),'Form Fix'!$A$6:$F$911,4,0),0) -> 0 | G2: =IFERROR(VLOOKUP(CONCATENATE(Table43_1[[#This Row],[Kode BARANG Win2]],5),'Form Fix'!$A$6:$F$911,4,0),0) -> 0
A3: R1021001006010 | B3: RB DETTOL BODY SOAP COOL 60GR X 144 PCS | C3: =IFERROR(VLOOKUP(CONCATENATE(Table43_1[[#This Row],[Kode BARANG Win2]],1),'Form Fix'!$A$6:$F$911,4,0),0) -> 3171295 | D3: =IFERROR(VLOOKUP(CONCATENATE(Table43_1[[#This Row],[Kode BARANG Win2]],2),'Form Fix'!$A$6:$F$911,4,0),0) -> 3166934 | E3: =IFERROR(VLOOKUP(CONCATENATE(Table43_1[[#This Row],[Kode BARANG Win2]],3),'Form Fix'!$A$6:$F$911,4,0),0) -> 3119258 | F3: =IFERROR(VLOOKUP(CONCATENATE(Table43_1[[#This Row],[Kode BARANG Win2]],4),'Form Fix'!$A$6:$F$911,4,0),0) -> 3331432 | G3: =IFERROR(VLOOKUP(CONCATENATE(Table43_1[[#This Row],[Kode BARANG Win2]],5),'Form Fix'!$A$6:$F$911,4,0),0) -> 0
A4: R1021001010010 | B4: RB DETTOL BODY SOAP COOL 100GR X 144 PCS | C4: =IFERROR(VLOOKUP(CONCATENATE(Table43_1[[#This Row],[Kode BARANG Win2]],1),'Form Fix'!$A$6:$F$911,4,0),0) -> 3171286 | D4: =IFERROR(VLOOKUP(CONCATENATE(Table43_1[[#This Row],[Kode BARANG Win2]],2),'Form Fix'!$A$6:$F$911,4,0),0) -> 3166924 | E4: =IFERROR(VLOOKUP(CONCATENATE(Table43_1[[#This Row],[Kode BARANG Win2]],3),'Form Fix'!$A$6:$F$911,4,0),0) -> 3060311 | F4: =IFERROR(VLOOKUP(CONCATENATE(Table43_1[[#This Row],[Kode BARANG Win2]],4),'Form Fix'!$A$6:$F$911,4,0),0) -> 3087451 | G4: =IFERROR(VLOOKUP(CONCATENATE(Table43_1[[#This Row],[Kode BARANG Win2]],5),'Form Fix'!$A$6:$F$911,4,0),0) -> ID8195121M
A5: R1021002010010 | B5: RB DETTOL BODY SOAP FAMILY PROTECT 100GR X 144 PCS | C5: =IFERROR(VLOOKUP(CONCATENATE(Table43_1[[#This Row],[Kode BARANG Win2]],1),'Form Fix'!$A$6:$F$911,4,0),0) -> 3300517 | D5: =IFERROR(VLOOKUP(CONCATENATE(Table43_1[[#This Row],[Kode BARANG Win2]],2),'Form Fix'!$A$6:$F$911,4,0),0) -> 0 | E5: =IFERROR(VLOOKUP(CONCATENATE(Table43_1[[#This Row],[Kode BARANG Win2]],3),'Form Fix'!$A$6:$F$911,4,0),0) -> 0 | F5: =IFERROR(VLOOKUP(CONCATENATE(Table43_1[[#This Row],[Kode BARANG Win2]],4),'Form Fix'!$A$6:$F$911,4,0),0) -> 0 | G5: =IFERROR(VLOOKUP(CONCATENATE(Table43_1[[#This Row],[Kode BARANG Win2]],5),'Form Fix'!$A$6:$F$911,4,0),0) -> 0
A6: R1021003006010 | B6: RB DETTOL BODY SOAP FRESH 60GR X 144 PCS | C6: =IFERROR(VLOOKUP(CONCATENATE(Table43_1[[#This Row],[Kode BARANG Win2]],1),'Form Fix'!$A$6:$F$911,4,0),0) -> 3170933 | D6: =IFERROR(VLOOKUP(CONCATENATE(Table43_1[[#This Row],[Kode BARANG Win2]],2),'Form Fix'!$A$6:$F$911,4,0),0) -> 3147626 | E6: =IFERROR(VLOOKUP(CONCATENATE(Table43_1[[#This Row],[Kode BARANG Win2]],3),'Form Fix'!$A$6:$F$911,4,0),0) -> 0 | F6: =IFERROR(VLOOKUP(CONCATENATE(Table43_1[[#This Row],[Kode BARANG Win2]],4),'Form Fix'!$A$6:$F$911,4,0),0) -> 0 | G6: =IFERROR(VLOOKUP(CONCATENATE(Table43_1[[#This Row],[Kode BARANG Win2]],5),'Form Fix'!$A$6:$F$911,4,0),0) -> 0
A7: R1021003010010 | B7: RB DETTOL BODY SOAP FRESH 100GR X 144 PCS | C7: =IFERROR(VLOOKUP(CONCATENATE(Table43_1[[#This Row],[Kode BARANG Win2]],1),'Form Fix'!$A$6:$F$911,4,0),0) -> 3170945 | D7: =IFERROR(VLOOKUP(CONCATENATE(Table43_1[[#This Row],[Kode BARANG Win2]],2),'Form Fix'!$A$6:$F$911,4,0),0) -> 0 | E7: =IFERROR(VLOOKUP(CONCATENATE(Table43_1[[#This Row],[Kode BARANG Win2]],3),'Form Fix'!$A$6:$F$911,4,0),0) -> 0 | F7: =IFERROR(VLOOKUP(CONCATENATE(Table43_1[[#This Row],[Kode BARANG Win2]],4),'Form Fix'!$A$6:$F$911,4,0),0) -> 0 | G7: =IFERROR(VLOOKUP(CONCATENATE(Table43_1[[#This Row],[Kode BARANG Win2]],5),'Form Fix'!$A$6:$F$911,4,0),0) -> 0
A8: R1021004006010 | B8: RB DETTOL BODY SOAP LASTING 60GR X 144 PCS | C8: =IFERROR(VLOOKUP(CONCATENATE(Table43_1[[#This Row],[Kode BARANG Win2]],1),'Form Fix'!$A$6:$F$911,4,0),0) -> 3166937 | D8: =IFERROR(VLOOKUP(CONCATENATE(Table43_1[[#This Row],[Kode BARANG Win2]],2),'Form Fix'!$A$6:$F$911,4,0),0) -> 3148248 | E8: =IFERROR(VLOOKUP(CONCATENATE(Table43_1[[#This Row],[Kode BARANG Win2]],3),'Form Fix'!$A$6:$F$911,4,0),0) -> 0 | F8: =IFERROR(VLOOKUP(CONCATENATE(Table43_1[[#This Row],[Kode BARANG Win2]],4),'Form Fix'!$A$6:$F$911,4,0),0) -> 0 | G8: =IFERROR(VLOOKUP(CONCATENATE(Table43_1[[#This Row],[Kode BARANG Win2]],5),'Form Fix'!$A$6:$F$911,4,0),0) -> 0
A9: R1021004010010 | B9: RB DETTOL BODY SOAP LASTING 100GR X 144 PCS | C9: =IFERROR(VLOOKUP(CONCATENATE(Table43_1[[#This Row],[Kode BARANG Win2]],1),'Form Fix'!$A$6:$F$911,4,0),0) -> 3166942 | D9: =IFERROR(VLOOKUP(CONCATENATE(Table43_1[[#This Row],[Kode BARANG Win2]],2),'Form Fix'!$A$6:$F$911,4,0),0) -> 3060668 | E9: =IFERROR(VLOOKUP(CONCATENATE(Table43_1[[#This Row],[Kode BARANG Win2]],3),'Form Fix'!$A$6:$F$911,4,0),0) -> 3087594 | F9: =IFERROR(VLOOKUP(CONCATENATE(Table43_1[[#This Row],[Kode BARANG Win2]],4),'Form Fix'!$A$6:$F$911,4,0),0) -> ID8195069M | G9: =IFERROR(VLOOKUP(CONCATENATE(Table43_1[[#This Row],[Kode BARANG Win2]],5),'Form Fix'!$A$6:$F$911,4,0),0) -> 3031729
A10: R1021005006010 | B10: RB DETTOL BODY SOAP ORIGINAL 60GR X 144 PCS | C10: =IFERROR(VLOOKUP(CONCATENATE(Table43_1[[#This Row],[Kode BARANG Win2]],1),'Form Fix'!$A$6:$F$911,4,0),0) -> 3166975 | D10: =IFERROR(VLOOKUP(CONCATENATE(Table43_1[[#This Row],[Kode BARANG Win2]],2),'Form Fix'!$A$6:$F$911,4,0),0) -> 3331433 | E10: =IFERROR(VLOOKUP(CONCATENATE(Table43_1[[#This Row],[Kode BARANG Win2]],3),'Form Fix'!$A$6:$F$911,4,0),0) -> 3119259 | F10: =IFERROR(VLOOKUP(CONCATENATE(Table43_1[[#This Row],[Kode BARANG Win2]],4),'Form Fix'!$A$6:$F$911,4,0),0) -> 3238406 | G10: =IFERROR(VLOOKUP(CONCATENATE(Table43_1[[#This Row],[Kode BARANG Win2]],5),'Form Fix'!$A$6:$F$911,4,0),0) -> 3224742
A11: R1021005010010 | B11: RB DETTOL BODY SOAP ORIGINAL 100GR X 144 PCS | C11: =IFERROR(VLOOKUP(CONCATENATE(Table43_1[[#This Row],[Kode BARANG Win2]],1),'Form Fix'!$A$6:$F$911,4,0),0) -> 3166958 | D11: =IFERROR(VLOOKUP(CONCATENATE(Table43_1[[#This Row],[Kode BARANG Win2]],2),'Form Fix'!$A$6:$F$911,4,0),0) -> 3083294 | E11: =IFERROR(VLOOKUP(CONCATENATE(Table43_1[[#This Row],[Kode BARANG Win2]],3),'Form Fix'!$A$6:$F$911,4,0),0) -> 3238701 | F11: =IFERROR(VLOOKUP(CONCATENATE(Table43_1[[#This Row],[Kode BARANG Win2]],4),'Form Fix'!$A$6:$F$911,4,0),0) -> 3061093 | G11: =IFERROR(VLOOKUP(CONCATENATE(Table43_1[[#This Row],[Kode BARANG Win2]],5),'Form Fix'!$A$6:$F$911,4,0),0) -> 3224745
A12: R1021006006010 | B12: RB DETTOL BODY SOAP RE-ENERGIZER 60GR X 144 PCS | C12: =IFERROR(VLOOKUP(CONCATENATE(Table43_1[[#This Row],[Kode BARANG Win2]],1),'Form Fix'!$A$6:$F$911,4,0),0) -> 3193502 | D12: =IFERROR(VLOOKUP(CONCATENATE(Table43_1[[#This Row],[Kode BARANG Win2]],2),'Form Fix'!$A$6:$F$911,4,0),0) -> 0 | E12: =IFERROR(VLOOKUP(CONCATENATE(Table43_1[[#This Row],[Kode BARANG Win2]],3),'Form Fix'!$A$6:$F$911,4,0),0) -> 0 | F12: =IFERROR(VLOOKUP(CONCATENATE(Table43_1[[#This Row],[Kode BARANG Win2]],4),'Form Fix'!$A$6:$F$911,4,0),0) -> 0 | G12: =IFERROR(VLOOKUP(CONCATENATE(Table43_1[[#This Row],[Kode BARANG Win2]],5),'Form Fix'!$A$6:$F$911,4,0),0) -> 0
A13: R1021007006010 | B13: RB DETTOL BODY SOAP SKINCARE 60GR X 144 PCS | C13: =IFERROR(VLOOKUP(CONCATENATE(Table43_1[[#This Row],[Kode BARANG Win2]],1),'Form Fix'!$A$6:$F$911,4,0),0) -> 3193501 | D13: =IFERROR(VLOOKUP(CONCATENATE(Table43_1[[#This Row],[Kode BARANG Win2]],2),'Form Fix'!$A$6:$F$911,4,0),0) -> 3337511 | E13: =IFERROR(VLOOKUP(CONCATENATE(Table43_1[[#This Row],[Kode BARANG Win2]],3),'Form Fix'!$A$6:$F$911,4,0),0) -> 0 | F13: =IFERROR(VLOOKUP(CONCATENATE(Table43_1[[#This Row],[Kode BARANG Win2]],4),'Form Fix'!$A$6:$F$911,4,0),0) -> 0 | G13: =IFERROR(VLOOKUP(CONCATENATE(Table43_1[[#This Row],[Kode BARANG Win2]],5),'Form Fix'!$A$6:$F$911,4,0),0) -> 0
... A201: R1100000003010 | B201: RB MULTI PURPOSE CLEANER LEMON 30S X 9 PCS | C201: =IFERROR(VLOOKUP(CONCATENATE(Table43_1[[#This Row],[Kode BARANG Win2]],1),'Form Fix'!$A$6:$F$911,4,0),0) -> 0 | D201: =IFERROR(VLOOKUP(CONCATENATE(Table43_1[[#This Row],[Kode BARANG Win2]],2),'Form Fix'!$A$6:$F$911,4,0),0) -> 0 | E201: =IFERROR(VLOOKUP(CONCATENATE(Table43_1[[#This Row],[Kode BARANG Win2]],3),'Form Fix'!$A$6:$F$911,4,0),0) -> 0 | F201: =IFERROR(VLOOKUP(CONCATENATE(Table43_1[[#This Row],[Kode BARANG Win2]],4),'Form Fix'!$A$6:$F$911,4,0),0) -> 0 | G201: =IFERROR(VLOOKUP(CONCATENATE(Table43_1[[#This Row],[Kode BARANG Win2]],5),'Form Fix'!$A$6:$F$911,4,0),0) -> 0

Sheet Form Fix
C1: UPDATE TGL
P2: =COUNTIF(Table43[LEN 50], ">50") -> 97
D3: PASTE NAMA DAN CODE PRINCIPLE (Buat Format seperti ini dan Ambil dari Daftar Harga Principle) | Q3: CPI | AN3: Daftar Harga | BC3: Update Per
J4: ISI SESUAIKAN ANTARA DMS vs WIN | L4: HASIL CODE KELOMPOK, CODE BARANG & NAMA BARANG WIN | Q4: Kolom Principle | AN4: Harga Beli | AR4: Harga Jual GT | AV4: Harga Jual MT | AZ4: MARGIN | BH4: To Win, diisi oleh Admin
A5: CONCATENATE MAPPING | B5: No. Urut Item Sama | C5: NO | D5: Kode Pcpl | E5: Klp Brg Pcpl | F5: Nama Barang Principle | G5: ISI/CTN | H5: Column3 | I5: Ket. Tambahan / Pembantu | J5: SATUAN Fix Win | K5: Nama Kelompok Win | L5: Kode Kelompok Win | M5: Kode BARANG Win2 | N5: LEN 15 | O5: Nama Win | P5: LEN 50 | Q5: Nama Pcpl | R5: kode 2 Digit (hrf+No) | S5: Nama KLP | T5: kode 2 Digit (Nomor) | U5: Nama Sub KLP | V5: kode 1 Digit (Nomor) | W5: Nama Sub KLP2 | X5: kode 1 Digit (Nomor)5 | Y5: Nama Aroma/ Rasa | Z5: kode 2 Digit (Nomor)2 | AA5: Nama Gramasi atau Jumlah Pack per CTN | AB5: kode 4 Digit (Nomor) | AC5: Nama Jenis Kemasan | AD5: kode 1 Digit (Nomor)3 | AE5: Nama Promo | AF5: kode 1 Digit (Nomor)4 | AG5: Gunakan ini apabila item tersebut sachet | AH5: kode 1 Digit (Nomor)32 | AI5: KET TAMBAHAN2 | AJ5: KET TAMBAHAN3 | AK5: KET. GOLONGAN | AL5: kode 1 Digit (Nomor) | AM5: Tanda Kode Revisi | AN5: Harga Beli Pcs (-PPN) | AO5: Harga Beli Krt (- PPN) | AP5: Harga Beli Pcs (+PPN) | AQ5: Harga Beli Krt (+PPN) | AR5: Harga Jual Pcs GT (-PPN) | AS5: Harga Jual Krt GT (- PPN) | AT5: Harga Jual Pcs GT (+PPN | AU5: Harga Jual Krt GT (+PPN) | AV5: Harga Jual Pcs MT (-PPN) | AW5: Harga Jual Krt MT (- PPN) | AX5: Harga Jual Pcs MT (+PPN) | AY5: Harga Jual Krt MT (+PPN) | AZ5: MARGIN | BA5: Column1 | BB5: Column2 | BC5: Efektif Pembuatan | BD5: Efektif Naik Harga | BE5: Status Pembuatan | BF5: Status Harga | BG5: Status Barang | BH5: Mata Uang | BI5: Kode Golongan | BJ5: Nama Golongan | BK5: Kode PCPL To Win | BL5: Kode Jenis Produk | BM5: SAT BSR | BN5: GD | BO5: Kode PRK | BP5: Kode PRK SJ | BQ5: Kode Job | BR5: Approval | BS5: Nama Principle
