Workbook
Name Consol: "Error"

Sheet PRICE LIST Motasa
A3: KELOMPOK PRODUK | B3: KODE PRODUK PRINSIPAL | C3: NAMA ITEM | D3: ISI/CTN | E3: SATUAN | F3: HARGA INCLUDE PPN 11% IN CTN | G3: HARGA/PCS
A4: ANTANGIN GROUP | B4: 10002 | C4: ANTANGIN JRG PLUS JAHE MERAH TD20 | D4: 1000 | E4: STRIP | F4: 3210000 | G4: =F4/D4 -> 3210
A5: ANTANGIN GROUP | B5: 10063 | C5: ANTANGIN JUNIORS SD5 | D5: 300 | E5: SACHET | F5: 600000 | G5: =F5/D5 -> 2000
A6: ANTANGIN GROUP | B6: 10074 | C6: ANTANGIN JRG + MADU SD12 | D6: 360 | E6: SACHET | F6: 1116000 | G6: =F6/D6 -> 3100
A7: ANTANGIN GROUP | B7: 10075 | C7: ANTANGIN MINT SD12 | D7: 360 | E7: SACHET | F7: 1116000 | G7: =F7/D7 -> 3100
A8: ANTANGIN GROUP | B8: 10077 | C8: ANTANGIN MINT SD5 | D8: 300 | E8: SACHET | F8: 930000 | G8: =F8/D8 -> 3100
A9: ANTANGIN GROUP | B9: 10110 | C9: ANTANGIN GOOD NIGTH TD20 | D9: 1000 | E9: STRIP | F9: 4036000 | G9: =F9/D9 -> 4036
A10: ANTANGIN GROUP | B10: 10112 | C10: ANTANGIN HABBATUSSAUDA SD12 | D10: 360 | E10: SACHET | F10: 1116000 | G10: =F10/D10 -> 3100
A11: ANTANGIN GROUP | B11: 10134 | C11: ANTANGIN HABBATUSSAUDA SD14 | D11: 420 | E11: SACHET | F11: 1115998.8 | G11: =F11/D11 -> 2657.14
A12: ANTANGIN GROUP | B12: 10135 | C12: ANTANGIN MINT SD14 | D12: 420 | E12: SACHET | F12: 1115998.8 | G12: =F12/D12 -> 2657.14
A13: CANDY GROUP | B13: 10039 | C13: OB HERBAL PERMEN HERBAL RASA MINT S5 | D13: 270 | E13: SACHET | F13: 558090 | G13: =F13/D13 -> 2067
A14: CANDY GROUP | B14: 10048 | C14: ANTANGIN PERMEN HERBAL RASA MADU MINT T30 | D14: 180 | E14: SACHET | F14: 372060 | G14: =F14/D14 -> 2067
A15: CANDY GROUP | B15: 10067 | C15: ANTANGIN PERMEN ANEKA RASA T250 | D15: 6 | E15: TOPLES | F15: 213666 | G15: =F15/D15 -> 35611
... A149: MADU GROUP | B149: 60108 | C149: MADU TJ STRAWBERRY D12 (DUS) | D149: 24 | E149: DUS | F149: 201531.6 | G149: =F149/D149 -> 8397.15

Sheet FORM DASAR KLP
A3: KODE PRODUK PRINSIPAL | B3: KELOMPOK PRODUK By Principle | C3: NAMA ITEM | D3: ISI/CTN | E3: SATUAN | F3: HARGA INCLUDE PPN 11% IN CTN | G3: HARGA/PCS
A4: 10002 | B4: ANTANGIN GROUP | C4: ANTANGIN JRG PLUS JAHE MERAH TD20 | D4: 1000 | E4: STRIP | F4: 3563100 | G4: =F4/D4 -> 3563.1
A5: 10063 | B5: ANTANGIN GROUP | C5: ANTANGIN JUNIORS SD5 | D5: 300 | E5: SACHET | F5: 666000 | G5: =F5/D5 -> 2220
A6: 10074 | B6: ANTANGIN GROUP | C6: ANTANGIN JRG + MADU SD12 | D6: 360 | E6: SACHET | F6: 1238760 | G6: =F6/D6 -> 3441
A7: 10075 | B7: ANTANGIN GROUP | C7: ANTANGIN MINT SD12 | D7: 360 | E7: SACHET | F7: 1238760 | G7: =F7/D7 -> 3441
A8: 10077 | B8: ANTANGIN GROUP | C8: ANTANGIN MINT SD5 | D8: 300 | E8: SACHET | F8: 1032300 | G8: =F8/D8 -> 3441
A9: 10110 | B9: ANTANGIN GROUP | C9: ANTANGIN GOOD NIGTH TD20 | D9: 1000 | E9: STRIP | F9: 4479960 | G9: =F9/D9 -> 4479.96
A10: 10112 | B10: ANTANGIN GROUP | C10: ANTANGIN HABBATUSSAUDA SD12 | D10: 360 | E10: SACHET | F10: 1238760 | G10: =F10/D10 -> 3441
A11: 10134 | B11: ANTANGIN GROUP | C11: ANTANGIN HABBATUSSAUDA SD14 | D11: 420 | E11: SACHET | F11: 1238758.7 | G11: =F11/D11 -> 2949.4254
A12: 10135 | B12: ANTANGIN GROUP | C12: ANTANGIN MINT SD14 | D12: 420 | E12: SACHET | F12: 1238758.7 | G12: =F12/D12 -> 2949.4254
A13: 10039 | B13: CANDY GROUP | C13: OB HERBAL PERMEN HERBAL RASA MINT S5 | D13: 270 | E13: SACHET | F13: 619479.9 | G13: =F13/D13 -> 2294.37
A14: 10048 | B14: CANDY GROUP | C14: ANTANGIN PERMEN HERBAL RASA MADU MINT T30 | D14: 180 | E14: SACHET | F14: 412986.6 | G14: =F14/D14 -> 2294.37
A15: 10067 | B15: CANDY GROUP | C15: ANTANGIN PERMEN ANEKA RASA T250 | D15: 6 | E15: TOPLES | F15: 237169.26 | G15: =F15/D15 -> 39528.21
... A149: 60108 | B149: MADU GROUP | C149: MADU TJ STRAWBERRY D12 (DUS) | D149: 24 | E149: DUS | F149: 223700.08 | G149: =F149/D149 -> 9320.8365

Sheet Cara Buat
A3: 1 | B3: Sortir Daftar Produk Principle sesuai Nama lalu sortir lagi by kelompok | D3: 1 | E3: Buat satu folder master barang, master kelompok, price list, mapping produk win to pcpl dan mapping produk pcpl to win
A4: 2 | B4: Copy dan Paste kan ke Sheet Form Master (sesuaikan kolom nya) | D4: 2 | E4: Master barang, master kelompok, price list, mapping produk win to pcpl dan mapping produk pcpl to win berdiri sendiri dalam satu book
A5: 3 | B5: Sheet kuning adalah rumus, jangan diganggu

Sheet Pvt Map 1
A3: Kode BARANG Win2 | B3: SATUAN Fix Win | C3: Kode Pcpl | D3: ISI/CTN | E3: Sum of No. Urut Item Sama
A4: F4011100007010 | B4: BOX | C4: 040411111 | D4: 6 | E4: 1
A5: F4012101040010 | B5: PCH | C5: 050413100 | D5: 24 | E5: 1
A6: F4012102040010 | B6: PCH | C6: 050415100 | D6: 24 | E6: 1
A7: F4012001048020 | B7: PUMP | C7: 050413200 | D7: 24 | E7: 1
A8: F4012002048020 | B8: PUMP | C8: 050415200 | D8: 24 | E8: 1
A9: F4013001007010 | B9: PCS | C9: 040413100 | D9: 72 | E9: 1
A10: F4013002007010 | B10: PCS | C10: 040415100 | D10: 72 | E10: 1
A11: F4021001010010 | B11: PCS | C11: 040402200 | D11: 72 | E11: 1
A12: F4031101040010 | B12: PUMP | C12: 050703100 | D12: 24 | E12: 1
A13: F4031102040020 | B13: PCH | C13: 050702100 | D13: 24 | E13: 1
A14: F4031103040020 | B14: PCH | C14: 050701100 | D14: 24 | E14: 1
A15: F4031001048030 | B15: BTL | C15: 050703101 | D15: 24 | E15: 1
... A74: F4065002008011 | B74: TUBE | C74: 191701307 | D74: 48 | E74: 1
A75: F4065002008011 | B75: TUBE | C75: 191703000 | D75: 48 | E75: 1
A76: F4065003002010 | B76: TUBE | C76: 191702000 | D76: 12 | E76: 1
A77: F4066001008010 | B77: PCS | C77: 041716400 | D77: 144 | E77: 1
A78: F4066002008010 | B78: PCS | C78: 041720400 | D78: 144 | E78: 1
A79: F4066003008010 | B79: PCS | C79: 041717400 | D79: 144 | E79: 1
A80: F4066004008010 | B80: PCS | C80: 041715400 | D80: 144 | E80: 1
A81: F4066005008010 | B81: PCS | C81: 041718400 | D81: 144 | E81: 1
A82: F4066006008010 | B82: PCS | C82: 041719400 | D82: 144 | E82: 1
A83: F4067101018010 | B83: PCH | C83: 051706300 | D83: 48 | E83: 1
A84: F4067102018010 | B84: PCH | C84: 051703300 | D84: 48 | E84: 1
A85: F4067103018010 | B85: PCH | C85: 051704300 | D85: 48 | E85: 1
A86: F4067104018010 | B86: PCH | C86: 051705300 | D86: 48 | E86: 1
A87: F4067005018010 | B87: PCH | C87: 051702300 | D87: 48 | E87: 1
A88: F4067005048020 | B88: PUMP | C88: 051702800 | D88: 24 | E88: 1
... A132: F4067011048020 | B132: PUMP | C132: 051705800 | D132: 24 | E132: 1
A133: F4053004003020 | B133: BTL | C133: 112603000 | D133: 48 | E133: 1
A134: F4053001003020 | B134: BTL | C134: 112601000 | D134: 48 | E134: 1
A135: F4053002003020 | B135: BTL | C135: 112604000 | D135: 48 | E135: 1
A136: F4053003003020 | B136: BTL | C136: 112602000 | D136: 48 | E136: 1
A137: F4061104040011 | B137: PCH | C137: 051701495 | D137: 12 | E137: 1
A138: F4061104040011 | B138: PCH | C138: 051701012 | D138: 12
A139: F4061204042010 | B139: PCH | C139: 051701400 | D139: 24 | E139: 1
A140: F4061301042010 | B140: PCH | C140: 051702400 | D140: 24 | E140: 1
A141: F4061403042010 | B141: PCH | C141: 051703400 | D141: 24 | E141: 1
A142: F4061510042010 | B142: PCH | C142: 051704400 | D142: 24 | E142: 1
A143: F4061611042010 | B143: PCH | C143: 051705400 | D143: 24 | E143: 1
...

Sheet Table Pvt 1
A1: Kode Barang Win | B1: Kode Pcpl | C1: SATUAN Fix Win | D1: ISI/CTN | E1: Kode PCPL yang sama | F1: Column1
A2: F4011100007010 | B2: 040411111 | C2: BOX | D2: 6 | E2: 1 | F2: =Pvt_Map_1[[#This Row],[Kode Barang Win]] -> F4011100007010
A3: F4012101040010 | B3: 050413100 | C3: PCH | D3: 24 | E3: 1 | F3: =Pvt_Map_1[[#This Row],[Kode Barang Win]] -> F4012101040010
A4: F4012102040010 | B4: 050415100 | C4: PCH | D4: 24 | E4: 1 | F4: =Pvt_Map_1[[#This Row],[Kode Barang Win]] -> F4012102040010
A5: F4012001048020 | B5: 050413200 | C5: PUMP | D5: 24 | E5: 1 | F5: =Pvt_Map_1[[#This Row],[Kode Barang Win]] -> F4012001048020
A6: F4012002048020 | B6: 050415200 | C6: PUMP | D6: 24 | E6: 1 | F6: =Pvt_Map_1[[#This Row],[Kode Barang Win]] -> F4012002048020
A7: F4013001007010 | B7: 040413100 | C7: PCS | D7: 72 | E7: 1 | F7: =Pvt_Map_1[[#This Row],[Kode Barang Win]] -> F4013001007010
A8: F4013002007010 | B8: 040415100 | C8: PCS | D8: 72 | E8: 1 | F8: =Pvt_Map_1[[#This Row],[Kode Barang Win]] -> F4013002007010
A9: F4021001010010 | B9: 040402200 | C9: PCS | D9: 72 | E9: 1 | F9: =Pvt_Map_1[[#This Row],[Kode Barang Win]] -> F4021001010010
A10: F4031101040010 | B10: 050703100 | C10: PUMP | D10: 24 | E10: 1 | F10: =Pvt_Map_1[[#This Row],[Kode Barang Win]] -> F4031101040010
A11: F4031102040020 | B11: 050702100 | C11: PCH | D11: 24 | E11: 1 | F11: =Pvt_Map_1[[#This Row],[Kode Barang Win]] -> F4031102040020
A12: F4031103040020 | B12: 050701100 | C12: PCH | D12: 24 | E12: 1 | F12: =Pvt_Map_1[[#This Row],[Kode Barang Win]] -> F4031103040020
A13: F4031001048030 | B13: 050703101 | C13: BTL | D13: 24 | E13: 1 | F13: =Pvt_Map_1[[#This Row],[Kode Barang Win]] -> F4031001048030
... A72: F4065002008011 | B72: 191701307 | C72: TUBE | D72: 48 | E72: 1 | F72: =Pvt_Map_1[[#This Row],[Kode Barang Win]] -> F4065002008011
A73: F4065002008011 | B73: 191703000 | C73: TUBE | D73: 48 | E73: 1 | F73: =Pvt_Map_1[[#This Row],[Kode Barang Win]] -> F4065002008011
A74: F4065003002010 | B74: 191702000 | C74: TUBE | D74: 12 | E74: 1 | F74: =Pvt_Map_1[[#This Row],[Kode Barang Win]] -> F4065003002010
A75: F4066001008010 | B75: 041716400 | C75: PCS | D75: 144 | E75: 1 | F75: =Pvt_Map_1[[#This Row],[Kode Barang Win]] -> F4066001008010
A76: F4066002008010 | B76: 041720400 | C76: PCS | D76: 144 | E76: 1 | F76: =Pvt_Map_1[[#This Row],[Kode Barang Win]] -> F4066002008010
A77: F4066003008010 | B77: 041717400 | C77: PCS | D77: 144 | E77: 1 | F77: =Pvt_Map_1[[#This Row],[Kode Barang Win]] -> F4066003008010
A78: F4066004008010 | B78: 041715400 | C78: PCS | D78: 144 | E78: 1 | F78: =Pvt_Map_1[[#This Row],[Kode Barang Win]] -> F4066004008010
A79: F4066005008010 | B79: 041718400 | C79: PCS | D79: 144 | E79: 1 | F79: =Pvt_Map_1[[#This Row],[Kode Barang Win]] -> F4066005008010
A80: F4066006008010 | B80: 041719400 | C80: PCS | D80: 144 | E80: 1 | F80: =Pvt_Map_1[[#This Row],[Kode Barang Win]] -> F4066006008010
A81: F4067101018010 | B81: 051706300 | C81: PCH | D81: 48 | E81: 1 | F81: =Pvt_Map_1[[#This Row],[Kode Barang Win]] -> F4067101018010
A82: F4067102018010 | B82: 051703300 | C82: PCH | D82: 48 | E82: 1 | F82: =Pvt_Map_1[[#This Row],[Kode Barang Win]] -> F4067102018010
A83: F4067103018010 | B83: 051704300 | C83: PCH | D83: 48 | E83: 1 | F83: =Pvt_Map_1[[#This Row],[Kode Barang Win]] -> F4067103018010
A84: F4067104018010 | B84: 051705300 | C84: PCH | D84: 48 | E84: 1 | F84: =Pvt_Map_1[[#This Row],[Kode Barang Win]] -> F4067104018010
A85: F4067005018010 | B85: 051702300 | C85: PCH | D85: 48 | E85: 1 | F85: =Pvt_Map_1[[#This Row],[Kode Barang Win]] -> F4067005018010
A86: F4067005048020 | B86: 051702800 | C86: PUMP | D86: 24 | E86: 1 | F86: =Pvt_Map_1[[#This Row],[Kode Barang Win]] -> F4067005048020
... A130: F4067011048020 | B130: 051705800 | C130: PUMP | D130: 24 | E130: 1 | F130: =Pvt_Map_1[[#This Row],[Kode Barang Win]] -> F4067011048020
A131: F4053004003020 | B131: 112603000 | C131: BTL | D131: 48 | E131: 1 | F131: =Pvt_Map_1[[#This Row],[Kode Barang Win]] -> F4053004003020
A132: F4053001003020 | B132: 112601000 | C132: BTL | D132: 48 | E132: 1 | F132: =Pvt_Map_1[[#This Row],[Kode Barang Win]] -> F4053001003020
A133: F4053002003020 | B133: 112604000 | C133: BTL | D133: 48 | E133: 1 | F133: =Pvt_Map_1[[#This Row],[Kode Barang Win]] -> F4053002003020
A134: F4053003003020 | B134: 112602000 | C134: BTL | D134: 48 | E134: 1 | F134: =Pvt_Map_1[[#This Row],[Kode Barang Win]] -> F4053003003020
A135: F4061104040011 | B135: 051701495 | C135: PCH | D135: 12 | E135: 1 | F135: =Pvt_Map_1[[#This Row],[Kode Barang Win]] -> F4061104040011
A136: F4061104040011 | B136: 051701012 | C136: PCH | D136: 12 | F136: =Pvt_Map_1[[#This Row],[Kode Barang Win]] -> F4061104040011
A137: F4061204042010 | B137: 051701400 | C137: PCH | D137: 24 | E137: 1 | F137: =Pvt_Map_1[[#This Row],[Kode Barang Win]] -> F4061204042010
A138: F4061301042010 | B138: 051702400 | C138: PCH | D138: 24 | E138: 1 | F138: =Pvt_Map_1[[#This Row],[Kode Barang Win]] -> F4061301042010
A139: F4061403042010 | B139: 051703400 | C139: PCH | D139: 24 | E139: 1 | F139: =Pvt_Map_1[[#This Row],[Kode Barang Win]] -> F4061403042010
A140: F4061510042010 | B140: 051704400 | C140: PCH | D140: 24 | E140: 1 | F140: =Pvt_Map_1[[#This Row],[Kode Barang Win]] -> F4061510042010
A141: F4061611042010 | B141: 051705400 | C141: PCH | D141: 24 | E141: 1 | F141: =Pvt_Map_1[[#This Row],[Kode Barang Win]] -> F4061611042010
...

Sheet Fix Mapping
A1: KODE BARANG | B1: NAMA BARANG | C1: ISI/CTN | D1: SATUAN | E1: NAMA KELOMPOK | F1: Harga Beli Pcs (-PPN) | G1: Harga Beli Krt (- PPN) | H1: Harga Beli Pcs (+PPN) | I1: Harga Beli Krt (+PPN) | J1: Harga Jual Pcs GT (-PPN) | K1: Harga Jual Krt GT (- PPN) | L1: Harga Jual Pcs GT (+PPN | M1: Harga Jual Krt GT (+PPN) | N1: Harga Jual Pcs MT (-PPN) | O1: Harga Jual Krt MT (- PPN) | P1: Harga Jual Pcs MT (+PPN) | Q1: Harga Jual Krt MT (+PPN) | R1: NAMA PRINCIPLE | S1: PCPL KODE 1 | T1: PCPL KODE 2 | U1: PCPL KODE 3 | V1: PCPL KODE 4 | W1: PCPL KODE 5
A2: F4011100007010 | B2: DERMYTHOL BAR LUNCH 70G X 6 BOX | C2: 6 | D2: BOX | E2: DERMYTHOL BAR | F2: 30029.189 | G2: 180175.14 | H2: 33332.4 | I2: 199994.4 | J2: 32432.432 | K2: 194594.59 | L2: 36000 | M2: 216000 | O2: 0 | P2: 0 | Q2: 0 | R2: PT. FOKUS RITEL NUSAPRIMA | S2: =IFERROR(VLOOKUP(CONCATENATE(Fix_Mapping[[#This Row],[KODE BARANG]],1),'Form Fix'!$A$6:$F$286,4,0),0) -> 040411111 | T2: =IFERROR(VLOOKUP(CONCATENATE(Fix_Mapping[[#This Row],[KODE BARANG]],2),'Form Fix'!$A$6:$F$286,4,0),0) -> 0 | U2: =IFERROR(VLOOKUP(CONCATENATE(Fix_Mapping[[#This Row],[KODE BARANG]],3),'Form Fix'!$A$6:$F$286,4,0),0) -> 0 | V2: =IFERROR(VLOOKUP(CONCATENATE(Fix_Mapping[[#This Row],[KODE BARANG]],4),'Form Fix'!$A$6:$F$286,4,0),0) -> 0 | W2: =IFERROR(VLOOKUP(CONCATENATE(Fix_Mapping[[#This Row],[KODE BARANG]],5),'Form Fix'!$A$6:$F$286,4,0),0) -> 0
A3: F4012101040010 | B3: DERMYTHOL BCL REF HYGIENIC BIO SLFR 400ML X 24 PCH | C3: 24 | D3: PCH | E3: DERMYTHOL BCL | F3: 21937.991 | G3: 526511.78 | H3: 24351.17 | I3: 584428.08 | J3: 23693.694 | K3: 568648.65 | L3: 26300 | M3: 631200 | O3: 0 | P3: 0 | Q3: 0 | R3: PT. FOKUS RITEL NUSAPRIMA | S3: =IFERROR(VLOOKUP(CONCATENATE(Fix_Mapping[[#This Row],[KODE BARANG]],1),'Form Fix'!$A$6:$F$286,4,0),0) -> 050413100 | T3: =IFERROR(VLOOKUP(CONCATENATE(Fix_Mapping[[#This Row],[KODE BARANG]],2),'Form Fix'!$A$6:$F$286,4,0),0) -> 0 | U3: =IFERROR(VLOOKUP(CONCATENATE(Fix_Mapping[[#This Row],[KODE BARANG]],3),'Form Fix'!$A$6:$F$286,4,0),0) -> 0 | V3: =IFERROR(VLOOKUP(CONCATENATE(Fix_Mapping[[#This Row],[KODE BARANG]],4),'Form Fix'!$A$6:$F$286,4,0),0) -> 0 | W3: =IFERROR(VLOOKUP(CONCATENATE(Fix_Mapping[[#This Row],[KODE BARANG]],5),'Form Fix'!$A$6:$F$286,4,0),0) -> 0
A4: F4012102040010 | B4: DERMYTHOL BCL REF HYGIENIC PROTECT 400ML X 24 PCH | C4: 24 | D4: PCH | E4: DERMYTHOL BCL | F4: 21937.991 | G4: 526511.78 | H4: 24351.17 | I4: 584428.08 | J4: 23693.694 | K4: 568648.65 | L4: 26300 | M4: 631200 | O4: 0 | P4: 0 | Q4: 0 | R4: PT. FOKUS RITEL NUSAPRIMA | S4: =IFERROR(VLOOKUP(CONCATENATE(Fix_Mapping[[#This Row],[KODE BARANG]],1),'Form Fix'!$A$6:$F$286,4,0),0) -> 050415100 | T4: =IFERROR(VLOOKUP(CONCATENATE(Fix_Mapping[[#This Row],[KODE BARANG]],2),'Form Fix'!$A$6:$F$286,4,0),0) -> 0 | U4: =IFERROR(VLOOKUP(CONCATENATE(Fix_Mapping[[#This Row],[KODE BARANG]],3),'Form Fix'!$A$6:$F$286,4,0),0) -> 0 | V4: =IFERROR(VLOOKUP(CONCATENATE(Fix_Mapping[[#This Row],[KODE BARANG]],4),'Form Fix'!$A$6:$F$286,4,0),0) -> 0 | W4: =IFERROR(VLOOKUP(CONCATENATE(Fix_Mapping[[#This Row],[KODE BARANG]],5),'Form Fix'!$A$6:$F$286,4,0),0) -> 0
A5: F4012001048020 | B5: DERMYTHOL BCL HYGIENIC BIO SULFUR 480ML X 24 PUMP | C5: 24 | D5: PUMP | E5: DERMYTHOL BCL | F5: 35034.054 | G5: 840817.3 | H5: 38887.8 | I5: 933307.2 | J5: 37837.838 | K5: 908108.11 | L5: 42000 | M5: 1008000 | O5: 0 | P5: 0 | Q5: 0 | R5: PT. FOKUS RITEL NUSAPRIMA | S5: =IFERROR(VLOOKUP(CONCATENATE(Fix_Mapping[[#This Row],[KODE BARANG]],1),'Form Fix'!$A$6:$F$286,4,0),0) -> 050413200 | T5: =IFERROR(VLOOKUP(CONCATENATE(Fix_Mapping[[#This Row],[KODE BARANG]],2),'Form Fix'!$A$6:$F$286,4,0),0) -> 0 | U5: =IFERROR(VLOOKUP(CONCATENATE(Fix_Mapping[[#This Row],[KODE BARANG]],3),'Form Fix'!$A$6:$F$286,4,0),0) -> 0 | V5: =IFERROR(VLOOKUP(CONCATENATE(Fix_Mapping[[#This Row],[KODE BARANG]],4),'Form Fix'!$A$6:$F$286,4,0),0) -> 0 | W5: =IFERROR(VLOOKUP(CONCATENATE(Fix_Mapping[[#This Row],[KODE BARANG]],5),'Form Fix'!$A$6:$F$286,4,0),0) -> 0
A6: F4012002048020 | B6: DERMYTHOL BCL HYGIENIC PROTECT 480ML X 24 PUMP | C6: 24 | D6: PUMP | E6: DERMYTHOL BCL | F6: 35034.054 | G6: 840817.3 | H6: 38887.8 | I6: 933307.2 | J6: 37837.838 | K6: 908108.11 | L6: 42000 | M6: 1008000 | O6: 0 | P6: 0 | Q6: 0 | R6: PT. FOKUS RITEL NUSAPRIMA | S6: =IFERROR(VLOOKUP(CONCATENATE(Fix_Mapping[[#This Row],[KODE BARANG]],1),'Form Fix'!$A$6:$F$286,4,0),0) -> 050415200 | T6: =IFERROR(VLOOKUP(CONCATENATE(Fix_Mapping[[#This Row],[KODE BARANG]],2),'Form Fix'!$A$6:$F$286,4,0),0) -> 0 | U6: =IFERROR(VLOOKUP(CONCATENATE(Fix_Mapping[[#This Row],[KODE BARANG]],3),'Form Fix'!$A$6:$F$286,4,0),0) -> 0 | V6: =IFERROR(VLOOKUP(CONCATENATE(Fix_Mapping[[#This Row],[KODE BARANG]],4),'Form Fix'!$A$6:$F$286,4,0),0) -> 0 | W6: =IFERROR(VLOOKUP(CONCATENATE(Fix_Mapping[[#This Row],[KODE BARANG]],5),'Form Fix'!$A$6:$F$286,4,0),0) -> 0
A7: F4013001007010 | B7: DERMYTHOL SABUN HYGIENIC BIO SULFUR 70G X 72 PCS | C7: 72 | D7: PCS | E7: DERMYTHOL SABUN | F7: 2585.8468 | G7: 186180.97 | H7: 2870.29 | I7: 206660.88 | J7: 2792.7928 | K7: 201081.08 | L7: 3100 | M7: 223200 | O7: 0 | P7: 0 | Q7: 0 | R7: PT. FOKUS RITEL NUSAPRIMA | S7: =IFERROR(VLOOKUP(CONCATENATE(Fix_Mapping[[#This Row],[KODE BARANG]],1),'Form Fix'!$A$6:$F$286,4,0),0) -> 040413100 | T7: =IFERROR(VLOOKUP(CONCATENATE(Fix_Mapping[[#This Row],[KODE BARANG]],2),'Form Fix'!$A$6:$F$286,4,0),0) -> 0 | U7: =IFERROR(VLOOKUP(CONCATENATE(Fix_Mapping[[#This Row],[KODE BARANG]],3),'Form Fix'!$A$6:$F$286,4,0),0) -> 0 | V7: =IFERROR(VLOOKUP(CONCATENATE(Fix_Mapping[[#This Row],[KODE BARANG]],4),'Form Fix'!$A$6:$F$286,4,0),0) -> 0 | W7: =IFERROR(VLOOKUP(CONCATENATE(Fix_Mapping[[#This Row],[KODE BARANG]],5),'Form Fix'!$A$6:$F$286,4,0),0) -> 0
A8: F4013002007010 | B8: DERMYTHOL SABUN HYGIENIC PROTECT 70G X 72 PCS | C8: 72 | D8: PCS | E8: DERMYTHOL SABUN | F8: 2585.8468 | G8: 186180.97 | H8: 2870.29 | I8: 206660.88 | J8: 2792.7928 | K8: 201081.08 | L8: 3100 | M8: 223200 | O8: 0 | P8: 0 | Q8: 0 | R8: PT. FOKUS RITEL NUSAPRIMA | S8: =IFERROR(VLOOKUP(CONCATENATE(Fix_Mapping[[#This Row],[KODE BARANG]],1),'Form Fix'!$A$6:$F$286,4,0),0) -> 040415100 | T8: =IFERROR(VLOOKUP(CONCATENATE(Fix_Mapping[[#This Row],[KODE BARANG]],2),'Form Fix'!$A$6:$F$286,4,0),0) -> 0 | U8: =IFERROR(VLOOKUP(CONCATENATE(Fix_Mapping[[#This Row],[KODE BARANG]],3),'Form Fix'!$A$6:$F$286,4,0),0) -> 0 | V8: =IFERROR(VLOOKUP(CONCATENATE(Fix_Mapping[[#This Row],[KODE BARANG]],4),'Form Fix'!$A$6:$F$286,4,0),0) -> 0 | W8: =IFERROR(VLOOKUP(CONCATENATE(Fix_Mapping[[#This Row],[KODE BARANG]],5),'Form Fix'!$A$6:$F$286,4,0),0) -> 0
A9: F4021001010010 | B9: DREAM SABUN PAPAYA 100G X 72 PCS | C9: 72 | D9: PCS | E9: DREAM SABUN | F9: 7507.2973 | G9: 540525.41 | H9: 8333.1 | I9: 599983.2 | J9: 8108.1081 | K9: 583783.78 | L9: 9000 | M9: 648000 | O9: 0 | P9: 0 | Q9: 0 | R9: PT. FOKUS RITEL NUSAPRIMA | S9: =IFERROR(VLOOKUP(CONCATENATE(Fix_Mapping[[#This Row],[KODE BARANG]],1),'Form Fix'!$A$6:$F$286,4,0),0) -> 040402200 | T9: =IFERROR(VLOOKUP(CONCATENATE(Fix_Mapping[[#This Row],[KODE BARANG]],2),'Form Fix'!$A$6:$F$286,4,0),0) -> 0 | U9: =IFERROR(VLOOKUP(CONCATENATE(Fix_Mapping[[#This Row],[KODE BARANG]],3),'Form Fix'!$A$6:$F$286,4,0),0) -> 0 | V9: =IFERROR(VLOOKUP(CONCATENATE(Fix_Mapping[[#This Row],[KODE BARANG]],4),'Form Fix'!$A$6:$F$286,4,0),0) -> 0 | W9: =IFERROR(VLOOKUP(CONCATENATE(Fix_Mapping[[#This Row],[KODE BARANG]],5),'Form Fix'!$A$6:$F$286,4,0),0) -> 0
A10: F4031101040010 | B10: GRDN OF NA EEM BCL REF MDNGHT GRDN 400ML X 24 PUMP | C10: 24 | D10: PUMP | E10: GRDN OF NA EEM BCL | F10: 19685.802 | G10: 472459.24 | H10: 21851.24 | I10: 524429.76 | J10: 21261.261 | K10: 510270.27 | L10: 23600 | M10: 566400 | O10: 0 | P10: 0 | Q10: 0 | R10: PT. FOKUS RITEL NUSAPRIMA | S10: =IFERROR(VLOOKUP(CONCATENATE(Fix_Mapping[[#This Row],[KODE BARANG]],1),'Form Fix'!$A$6:$F$286,4,0),0) -> 050703100 | T10: =IFERROR(VLOOKUP(CONCATENATE(Fix_Mapping[[#This Row],[KODE BARANG]],2),'Form Fix'!$A$6:$F$286,4,0),0) -> 0 | U10: =IFERROR(VLOOKUP(CONCATENATE(Fix_Mapping[[#This Row],[KODE BARANG]],3),'Form Fix'!$A$6:$F$286,4,0),0) -> 0 | V10: =IFERROR(VLOOKUP(CONCATENATE(Fix_Mapping[[#This Row],[KODE BARANG]],4),'Form Fix'!$A$6:$F$286,4,0),0) -> 0 | W10: =IFERROR(VLOOKUP(CONCATENATE(Fix_Mapping[[#This Row],[KODE BARANG]],5),'Form Fix'!$A$6:$F$286,4,0),0) -> 0
A11: F4031102040020 | B11: GRDN OF NA EEM BCL REF ROYAL JASMNE 400ML X 24 PCH | C11: 24 | D11: PCH | E11: GRDN OF NA EEM BCL | F11: 19685.802 | G11: 472459.24 | H11: 21851.24 | I11: 524429.76 | J11: 21261.261 | K11: 510270.27 | L11: 23600 | M11: 566400 | O11: 0 | P11: 0 | Q11: 0 | R11: PT. FOKUS RITEL NUSAPRIMA | S11: =IFERROR(VLOOKUP(CONCATENATE(Fix_Mapping[[#This Row],[KODE BARANG]],1),'Form Fix'!$A$6:$F$286,4,0),0) -> 050702100 | T11: =IFERROR(VLOOKUP(CONCATENATE(Fix_Mapping[[#This Row],[KODE BARANG]],2),'Form Fix'!$A$6:$F$286,4,0),0) -> 0 | U11: =IFERROR(VLOOKUP(CONCATENATE(Fix_Mapping[[#This Row],[KODE BARANG]],3),'Form Fix'!$A$6:$F$286,4,0),0) -> 0 | V11: =IFERROR(VLOOKUP(CONCATENATE(Fix_Mapping[[#This Row],[KODE BARANG]],4),'Form Fix'!$A$6:$F$286,4,0),0) -> 0 | W11: =IFERROR(VLOOKUP(CONCATENATE(Fix_Mapping[[#This Row],[KODE BARANG]],5),'Form Fix'!$A$6:$F$286,4,0),0) -> 0
A12: F4031103040020 | B12: GRDN OF NA EEM BCL REF TAIFI ROSE 400ML X 24 PCH | C12: 24 | D12: PCH | E12: GRDN OF NA EEM BCL | F12: 19685.802 | G12: 472459.24 | H12: 21851.24 | I12: 524429.76 | J12: 21261.261 | K12: 510270.27 | L12: 23600 | M12: 566400 | O12: 0 | P12: 0 | Q12: 0 | R12: PT. FOKUS RITEL NUSAPRIMA | S12: =IFERROR(VLOOKUP(CONCATENATE(Fix_Mapping[[#This Row],[KODE BARANG]],1),'Form Fix'!$A$6:$F$286,4,0),0) -> 050701100 | T12: =IFERROR(VLOOKUP(CONCATENATE(Fix_Mapping[[#This Row],[KODE BARANG]],2),'Form Fix'!$A$6:$F$286,4,0),0) -> 0 | U12: =IFERROR(VLOOKUP(CONCATENATE(Fix_Mapping[[#This Row],[KODE BARANG]],3),'Form Fix'!$A$6:$F$286,4,0),0) -> 0 | V12: =IFERROR(VLOOKUP(CONCATENATE(Fix_Mapping[[#This Row],[KODE BARANG]],4),'Form Fix'!$A$6:$F$286,4,0),0) -> 0 | W12: =IFERROR(VLOOKUP(CONCATENATE(Fix_Mapping[[#This Row],[KODE BARANG]],5),'Form Fix'!$A$6:$F$286,4,0),0) -> 0
A13: F4031001048030 | B13: GRDN OF NA EEM BCL MDNGHT GRDN 480ML X 24 BTL | C13: 24 | D13: BTL | E13: GRDN OF NA EEM BCL | F13: 28360.901 | G13: 680661.62 | H13: 31480.6 | I13: 755534.4 | J13: 30630.631 | K13: 735135.14 | L13: 34000 | M13: 816000 | O13: 0 | P13: 0 | Q13: 0 | R13: PT. FOKUS RITEL NUSAPRIMA | S13: =IFERROR(VLOOKUP(CONCATENATE(Fix_Mapping[[#This Row],[KODE BARANG]],1),'Form Fix'!$A$6:$F$286,4,0),0) -> 050703101 | T13: =IFERROR(VLOOKUP(CONCATENATE(Fix_Mapping[[#This Row],[KODE BARANG]],2),'Form Fix'!$A$6:$F$286,4,0),0) -> 0 | U13: =IFERROR(VLOOKUP(CONCATENATE(Fix_Mapping[[#This Row],[KODE BARANG]],3),'Form Fix'!$A$6:$F$286,4,0),0) -> 0 | V13: =IFERROR(VLOOKUP(CONCATENATE(Fix_Mapping[[#This Row],[KODE BARANG]],4),'Form Fix'!$A$6:$F$286,4,0),0) -> 0 | W13: =IFERROR(VLOOKUP(CONCATENATE(Fix_Mapping[[#This Row],[KODE BARANG]],5),'Form Fix'!$A$6:$F$286,4,0),0) -> 0
... A125: F4072003048020 | B125: ZEN BODY WSH SHISO & SULPHUR 480ML X 24 PUMP | C125: 24 | D125: PUMP | E125: ZEN BODY WSH | F125: 31697.477 | G125: 760739.46 | H125: 35184.2 | I125: 844420.8 | J125: 34234.234 | K125: 821621.62 | L125: 38000 | M125: 912000 | O125: 0 | P125: 0 | Q125: 0 | R125: PT. FOKUS RITEL NUSAPRIMA | S125: =IFERROR(VLOOKUP(CONCATENATE(Fix_Mapping[[#This Row],[KODE BARANG]],1),'Form Fix'!$A$6:$F$286,4,0),0) -> 052505500 | T125: =IFERROR(VLOOKUP(CONCATENATE(Fix_Mapping[[#This Row],[KODE BARANG]],2),'Form Fix'!$A$6:$F$286,4,0),0) -> 0 | U125: =IFERROR(VLOOKUP(CONCATENATE(Fix_Mapping[[#This Row],[KODE BARANG]],3),'Form Fix'!$A$6:$F$286,4,0),0) -> 0 | V125: =IFERROR(VLOOKUP(CONCATENATE(Fix_Mapping[[#This Row],[KODE BARANG]],4),'Form Fix'!$A$6:$F$286,4,0),0) -> 0 | W125: =IFERROR(VLOOKUP(CONCATENATE(Fix_Mapping[[#This Row],[KODE BARANG]],5),'Form Fix'!$A$6:$F$286,4,0),0) -> 0
A126: F4073101007010 | B126: ZEN SABUN LUNCH MIX 70G X 6 BOX | C126: 6 | D126: BOX | E126: ZEN SABUN | G126: 0 | H126: 0 | I126: 0 | K126: 0 | L126: 0 | M126: 0 | O126: 0 | P126: 0 | Q126: 0 | S126: =IFERROR(VLOOKUP(CONCATENATE(Fix_Mapping[[#This Row],[KODE BARANG]],1),'Form Fix'!$A$6:$F$286,4,0),0) -> 042501702 | T126: =IFERROR(VLOOKUP(CONCATENATE(Fix_Mapping[[#This Row],[KODE BARANG]],2),'Form Fix'!$A$6:$F$286,4,0),0) -> 0 | U126: =IFERROR(VLOOKUP(CONCATENATE(Fix_Mapping[[#This Row],[KODE BARANG]],3),'Form Fix'!$A$6:$F$286,4,0),0) -> 0 | V126: =IFERROR(VLOOKUP(CONCATENATE(Fix_Mapping[[#This Row],[KODE BARANG]],4),'Form Fix'!$A$6:$F$286,4,0),0) -> 0 | W126: =IFERROR(VLOOKUP(CONCATENATE(Fix_Mapping[[#This Row],[KODE BARANG]],5),'Form Fix'!$A$6:$F$286,4,0),0) -> 0
A127: F4073002006010 | B127: ZEN SABUN SHINSO & SULPHUR 60G X 72 PCS | C127: 72 | D127: PCS | E127: ZEN SABUN | F127: 2836.0901 | G127: 204198.49 | H127: 3148.06 | I127: 226660.32 | J127: 3063.0631 | K127: 220540.54 | L127: 3400 | M127: 244800 | O127: 0 | P127: 0 | Q127: 0 | R127: PT. FOKUS RITEL NUSAPRIMA | S127: =IFERROR(VLOOKUP(CONCATENATE(Fix_Mapping[[#This Row],[KODE BARANG]],1),'Form Fix'!$A$6:$F$286,4,0),0) -> 042505001 | T127: =IFERROR(VLOOKUP(CONCATENATE(Fix_Mapping[[#This Row],[KODE BARANG]],2),'Form Fix'!$A$6:$F$286,4,0),0) -> 0 | U127: =IFERROR(VLOOKUP(CONCATENATE(Fix_Mapping[[#This Row],[KODE BARANG]],3),'Form Fix'!$A$6:$F$286,4,0),0) -> 0 | V127: =IFERROR(VLOOKUP(CONCATENATE(Fix_Mapping[[#This Row],[KODE BARANG]],4),'Form Fix'!$A$6:$F$286,4,0),0) -> 0 | W127: =IFERROR(VLOOKUP(CONCATENATE(Fix_Mapping[[#This Row],[KODE BARANG]],5),'Form Fix'!$A$6:$F$286,4,0),0) -> 0
A128: F4073003007020 | B128: ZEN SABUN SHISO & ECHINACEA 70G X 24 PACK | C128: 24 | D128: PACK | E128: ZEN SABUN | F128: 7340.4685 | G128: 176171.24 | H128: 8147.92 | I128: 195550.08 | J128: 7927.9279 | K128: 190270.27 | L128: 8800 | M128: 211200 | O128: 0 | P128: 0 | Q128: 0 | R128: PT. FOKUS RITEL NUSAPRIMA | S128: =IFERROR(VLOOKUP(CONCATENATE(Fix_Mapping[[#This Row],[KODE BARANG]],1),'Form Fix'!$A$6:$F$286,4,0),0) -> 042505800 | T128: =IFERROR(VLOOKUP(CONCATENATE(Fix_Mapping[[#This Row],[KODE BARANG]],2),'Form Fix'!$A$6:$F$286,4,0),0) -> 042504004 | U128: =IFERROR(VLOOKUP(CONCATENATE(Fix_Mapping[[#This Row],[KODE BARANG]],3),'Form Fix'!$A$6:$F$286,4,0),0) -> 0 | V128: =IFERROR(VLOOKUP(CONCATENATE(Fix_Mapping[[#This Row],[KODE BARANG]],4),'Form Fix'!$A$6:$F$286,4,0),0) -> 0 | W128: =IFERROR(VLOOKUP(CONCATENATE(Fix_Mapping[[#This Row],[KODE BARANG]],5),'Form Fix'!$A$6:$F$286,4,0),0) -> 0
A129: F4073004007020 | B129: ZEN SABUN SHISO & JUNIPER BERRIES 70G X 24 PACK | C129: 24 | D129: PACK | E129: ZEN SABUN | F129: 7340.4685 | G129: 176171.24 | H129: 8147.92 | I129: 195550.08 | J129: 7927.9279 | K129: 190270.27 | L129: 8800 | M129: 211200 | O129: 0 | P129: 0 | Q129: 0 | R129: PT. FOKUS RITEL NUSAPRIMA | S129: =IFERROR(VLOOKUP(CONCATENATE(Fix_Mapping[[#This Row],[KODE BARANG]],1),'Form Fix'!$A$6:$F$286,4,0),0) -> 042506800 | T129: =IFERROR(VLOOKUP(CONCATENATE(Fix_Mapping[[#This Row],[KODE BARANG]],2),'Form Fix'!$A$6:$F$286,4,0),0) -> 042506008 | U129: =IFERROR(VLOOKUP(CONCATENATE(Fix_Mapping[[#This Row],[KODE BARANG]],3),'Form Fix'!$A$6:$F$286,4,0),0) -> 042506012 | V129: =IFERROR(VLOOKUP(CONCATENATE(Fix_Mapping[[#This Row],[KODE BARANG]],4),'Form Fix'!$A$6:$F$286,4,0),0) -> 0 | W129: =IFERROR(VLOOKUP(CONCATENATE(Fix_Mapping[[#This Row],[KODE BARANG]],5),'Form Fix'!$A$6:$F$286,4,0),0) -> 0
A130: F4073005007020 | B130: ZEN SABUN SHISO & SANDALWOOD 70G X 24 PACK | C130: 24 | D130: PACK | E130: ZEN SABUN | F130: 7340.4685 | G130: 176171.24 | H130: 8147.92 | I130: 195550.08 | J130: 7927.9279 | K130: 190270.27 | L130: 8800 | M130: 211200 | O130: 0 | P130: 0 | Q130: 0 | R130: PT. FOKUS RITEL NUSAPRIMA | S130: =IFERROR(VLOOKUP(CONCATENATE(Fix_Mapping[[#This Row],[KODE BARANG]],1),'Form Fix'!$A$6:$F$286,4,0),0) -> 042501800 | T130: =IFERROR(VLOOKUP(CONCATENATE(Fix_Mapping[[#This Row],[KODE BARANG]],2),'Form Fix'!$A$6:$F$286,4,0),0) -> 042501008 | U130: =IFERROR(VLOOKUP(CONCATENATE(Fix_Mapping[[#This Row],[KODE BARANG]],3),'Form Fix'!$A$6:$F$286,4,0),0) -> 042501011 | V130: =IFERROR(VLOOKUP(CONCATENATE(Fix_Mapping[[#This Row],[KODE BARANG]],4),'Form Fix'!$A$6:$F$286,4,0),0) -> 0 | W130: =IFERROR(VLOOKUP(CONCATENATE(Fix_Mapping[[#This Row],[KODE BARANG]],5),'Form Fix'!$A$6:$F$286,4,0),0) -> 0
A131: F4073006007020 | B131: ZEN SABUN SHISO & SEA SALT 70G X 24 PACK | C131: 24 | D131: PACK | E131: ZEN SABUN | F131: 7340.4685 | G131: 176171.24 | H131: 8147.92 | I131: 195550.08 | J131: 7927.9279 | K131: 190270.27 | L131: 8800 | M131: 211200 | O131: 0 | P131: 0 | Q131: 0 | R131: PT. FOKUS RITEL NUSAPRIMA | S131: =IFERROR(VLOOKUP(CONCATENATE(Fix_Mapping[[#This Row],[KODE BARANG]],1),'Form Fix'!$A$6:$F$286,4,0),0) -> 042502800 | T131: =IFERROR(VLOOKUP(CONCATENATE(Fix_Mapping[[#This Row],[KODE BARANG]],2),'Form Fix'!$A$6:$F$286,4,0),0) -> 042503004 | U131: =IFERROR(VLOOKUP(CONCATENATE(Fix_Mapping[[#This Row],[KODE BARANG]],3),'Form Fix'!$A$6:$F$286,4,0),0) -> 0 | V131: =IFERROR(VLOOKUP(CONCATENATE(Fix_Mapping[[#This Row],[KODE BARANG]],4),'Form Fix'!$A$6:$F$286,4,0),0) -> 0 | W131: =IFERROR(VLOOKUP(CONCATENATE(Fix_Mapping[[#This Row],[KODE BARANG]],5),'Form Fix'!$A$6:$F$286,4,0),0) -> 0
A132: F4073007007020 | B132: ZEN SABUN SHISO & SULPHUR 70G X 24 PACK | C132: 24 | D132: PACK | E132: ZEN SABUN | F132: 7340.4685 | G132: 176171.24 | H132: 8147.92 | I132: 195550.08 | J132: 7927.9279 | K132: 190270.27 | L132: 8800 | M132: 211200 | O132: 0 | P132: 0 | Q132: 0 | R132: PT. FOKUS RITEL NUSAPRIMA | S132: =IFERROR(VLOOKUP(CONCATENATE(Fix_Mapping[[#This Row],[KODE BARANG]],1),'Form Fix'!$A$6:$F$286,4,0),0) -> 042503800 | T132: =IFERROR(VLOOKUP(CONCATENATE(Fix_Mapping[[#This Row],[KODE BARANG]],2),'Form Fix'!$A$6:$F$286,4,0),0) -> 042505005 | U132: =IFERROR(VLOOKUP(CONCATENATE(Fix_Mapping[[#This Row],[KODE BARANG]],3),'Form Fix'!$A$6:$F$286,4,0),0) -> 0 | V132: =IFERROR(VLOOKUP(CONCATENATE(Fix_Mapping[[#This Row],[KODE BARANG]],4),'Form Fix'!$A$6:$F$286,4,0),0) -> 0 | W132: =IFERROR(VLOOKUP(CONCATENATE(Fix_Mapping[[#This Row],[KODE BARANG]],5),'Form Fix'!$A$6:$F$286,4,0),0) -> 0
A133: F4073008007020 | B133: ZEN SABUN SHISO & TEA TREE 70G X 24 PACK | C133: 24 | D133: PACK | E133: ZEN SABUN | F133: 7340.4685 | G133: 176171.24 | H133: 8147.92 | I133: 195550.08 | J133: 7927.9279 | K133: 190270.27 | L133: 8800 | M133: 211200 | O133: 0 | P133: 0 | Q133: 0 | R133: PT. FOKUS RITEL NUSAPRIMA | S133: =IFERROR(VLOOKUP(CONCATENATE(Fix_Mapping[[#This Row],[KODE BARANG]],1),'Form Fix'!$A$6:$F$286,4,0),0) -> 042504800 | T133: =IFERROR(VLOOKUP(CONCATENATE(Fix_Mapping[[#This Row],[KODE BARANG]],2),'Form Fix'!$A$6:$F$286,4,0),0) -> 042502008 | U133: =IFERROR(VLOOKUP(CONCATENATE(Fix_Mapping[[#This Row],[KODE BARANG]],3),'Form Fix'!$A$6:$F$286,4,0),0) -> 0 | V133: =IFERROR(VLOOKUP(CONCATENATE(Fix_Mapping[[#This Row],[KODE BARANG]],4),'Form Fix'!$A$6:$F$286,4,0),0) -> 0 | W133: =IFERROR(VLOOKUP(CONCATENATE(Fix_Mapping[[#This Row],[KODE BARANG]],5),'Form Fix'!$A$6:$F$286,4,0),0) -> 0
A134: F4073208007020 | B134: ZEN SABUN 4P SHISO & TEA TREE 70G X 18 PACK | C134: 18 | D134: PACK | E134: ZEN SABUN | F134: 9342.4144 | G134: 168163.46 | H134: 10370.08 | I134: 186661.44 | J134: 10090.09 | K134: 181621.62 | L134: 11200 | M134: 201600 | O134: 0 | P134: 0 | Q134: 0 | R134: PT. FOKUS RITEL NUSAPRIMA | S134: =IFERROR(VLOOKUP(CONCATENATE(Fix_Mapping[[#This Row],[KODE BARANG]],1),'Form Fix'!$A$6:$F$286,4,0),0) -> 042502500 | T134: =IFERROR(VLOOKUP(CONCATENATE(Fix_Mapping[[#This Row],[KODE BARANG]],2),'Form Fix'!$A$6:$F$286,4,0),0) -> 042502501 | U134: =IFERROR(VLOOKUP(CONCATENATE(Fix_Mapping[[#This Row],[KODE BARANG]],3),'Form Fix'!$A$6:$F$286,4,0),0) -> 0 | V134: =IFERROR(VLOOKUP(CONCATENATE(Fix_Mapping[[#This Row],[KODE BARANG]],4),'Form Fix'!$A$6:$F$286,4,0),0) -> 0 | W134: =IFERROR(VLOOKUP(CONCATENATE(Fix_Mapping[[#This Row],[KODE BARANG]],5),'Form Fix'!$A$6:$F$286,4,0),0) -> 0
A135: F4073208006020 | B135: ZEN SABUN 4P SHISO & TEA TREE 60G X 18 PACK | C135: 18 | D135: PACK | E135: ZEN SABUN | F135: 8675.0991 | G135: 156151.78 | H135: 9629.36 | I135: 173328.48 | J135: 9369.3694 | K135: 168648.65 | L135: 10400 | M135: 187200 | O135: 0 | P135: 0 | Q135: 0 | R135: PT. FOKUS RITEL NUSAPRIMA | S135: =IFERROR(VLOOKUP(CONCATENATE(Fix_Mapping[[#This Row],[KODE BARANG]],1),'Form Fix'!$A$6:$F$286,4,0),0) -> 0 | T135: =IFERROR(VLOOKUP(CONCATENATE(Fix_Mapping[[#This Row],[KODE BARANG]],2),'Form Fix'!$A$6:$F$286,4,0),0) -> 0 | U135: =IFERROR(VLOOKUP(CONCATENATE(Fix_Mapping[[#This Row],[KODE BARANG]],3),'Form Fix'!$A$6:$F$286,4,0),0) -> 042502503 | V135: =IFERROR(VLOOKUP(CONCATENATE(Fix_Mapping[[#This Row],[KODE BARANG]],4),'Form Fix'!$A$6:$F$286,4,0),0) -> 0 | W135: =IFERROR(VLOOKUP(CONCATENATE(Fix_Mapping[[#This Row],[KODE BARANG]],5),'Form Fix'!$A$6:$F$286,4,0),0) -> 0
A136: F4073101007010N | B136: ZEN SABUN LUNCH MIX 70G X 6 BOX | C136: 6 | D136: BOX | E136: ZEN SABUN | F136: 34033.081 | G136: 204198.49 | H136: 37776.72 | I136: 226660.32 | J136: 36756.757 | K136: 220540.54 | L136: 40800 | M136: 244800 | O136: 0 | P136: 0 | Q136: 0 | R136: PT. FOKUS RITEL NUSAPRIMA | S136: =IFERROR(VLOOKUP(CONCATENATE(Fix_Mapping[[#This Row],[KODE BARANG]],1),'Form Fix'!$A$6:$F$286,4,0),0) -> 042501703 | T136: =IFERROR(VLOOKUP(CONCATENATE(Fix_Mapping[[#This Row],[KODE BARANG]],2),'Form Fix'!$A$6:$F$286,4,0),0) -> 0 | U136: =IFERROR(VLOOKUP(CONCATENATE(Fix_Mapping[[#This Row],[KODE BARANG]],3),'Form Fix'!$A$6:$F$286,4,0),0) -> 0 | V136: =IFERROR(VLOOKUP(CONCATENATE(Fix_Mapping[[#This Row],[KODE BARANG]],4),'Form Fix'!$A$6:$F$286,4,0),0) -> 0 | W136: =IFERROR(VLOOKUP(CONCATENATE(Fix_Mapping[[#This Row],[KODE BARANG]],5),'Form Fix'!$A$6:$F$286,4,0),0) -> 0

Sheet Query Map.BrgDoubleDms
A1: Kode BARANG Win2 | B1: Nama Win | C1: PCPL KODE 1 | D1: PCPL KODE 2 | E1: PCPL KODE 3 | F1: PCPL KODE 4 | G1: PCPL KODE 5
A2: F4011100007010 | B2: DERMYTHOL BAR LUNCH 70G X 6 BOX | C2: =IFERROR(VLOOKUP(CONCATENATE(Table43_1[[#This Row],[Kode BARANG Win2]],1),'Form Fix'!$A$6:$F$205,4,0),0) -> 040411111 | D2: =IFERROR(VLOOKUP(CONCATENATE(Table43_1[[#This Row],[Kode BARANG Win2]],2),'Form Fix'!$A$6:$F$205,4,0),0) -> 0 | E2: =IFERROR(VLOOKUP(CONCATENATE(Table43_1[[#This Row],[Kode BARANG Win2]],3),'Form Fix'!$A$6:$F$205,4,0),0) -> 0 | F2: =IFERROR(VLOOKUP(CONCATENATE(Table43_1[[#This Row],[Kode BARANG Win2]],4),'Form Fix'!$A$6:$F$205,4,0),0) -> 0 | G2: =IFERROR(VLOOKUP(CONCATENATE(Table43_1[[#This Row],[Kode BARANG Win2]],5),'Form Fix'!$A$6:$F$205,4,0),0) -> 0
A3: F4012101040010 | B3: DERMYTHOL BCL REF HYGIENIC BIO SLFR 400ML X 24 PCH | C3: =IFERROR(VLOOKUP(CONCATENATE(Table43_1[[#This Row],[Kode BARANG Win2]],1),'Form Fix'!$A$6:$F$205,4,0),0) -> 050413100 | D3: =IFERROR(VLOOKUP(CONCATENATE(Table43_1[[#This Row],[Kode BARANG Win2]],2),'Form Fix'!$A$6:$F$205,4,0),0) -> 0 | E3: =IFERROR(VLOOKUP(CONCATENATE(Table43_1[[#This Row],[Kode BARANG Win2]],3),'Form Fix'!$A$6:$F$205,4,0),0) -> 0 | F3: =IFERROR(VLOOKUP(CONCATENATE(Table43_1[[#This Row],[Kode BARANG Win2]],4),'Form Fix'!$A$6:$F$205,4,0),0) -> 0 | G3: =IFERROR(VLOOKUP(CONCATENATE(Table43_1[[#This Row],[Kode BARANG Win2]],5),'Form Fix'!$A$6:$F$205,4,0),0) -> 0
A4: F4012102040010 | B4: DERMYTHOL BCL REF HYGIENIC PROTECT 400ML X 24 PCH | C4: =IFERROR(VLOOKUP(CONCATENATE(Table43_1[[#This Row],[Kode BARANG Win2]],1),'Form Fix'!$A$6:$F$205,4,0),0) -> 050415100 | D4: =IFERROR(VLOOKUP(CONCATENATE(Table43_1[[#This Row],[Kode BARANG Win2]],2),'Form Fix'!$A$6:$F$205,4,0),0) -> 0 | E4: =IFERROR(VLOOKUP(CONCATENATE(Table43_1[[#This Row],[Kode BARANG Win2]],3),'Form Fix'!$A$6:$F$205,4,0),0) -> 0 | F4: =IFERROR(VLOOKUP(CONCATENATE(Table43_1[[#This Row],[Kode BARANG Win2]],4),'Form Fix'!$A$6:$F$205,4,0),0) -> 0 | G4: =IFERROR(VLOOKUP(CONCATENATE(Table43_1[[#This Row],[Kode BARANG Win2]],5),'Form Fix'!$A$6:$F$205,4,0),0) -> 0
A5: F4012001048020 | B5: DERMYTHOL BCL HYGIENIC BIO SULFUR 480ML X 24 PUMP | C5: =IFERROR(VLOOKUP(CONCATENATE(Table43_1[[#This Row],[Kode BARANG Win2]],1),'Form Fix'!$A$6:$F$205,4,0),0) -> 050413200 | D5: =IFERROR(VLOOKUP(CONCATENATE(Table43_1[[#This Row],[Kode BARANG Win2]],2),'Form Fix'!$A$6:$F$205,4,0),0) -> 0 | E5: =IFERROR(VLOOKUP(CONCATENATE(Table43_1[[#This Row],[Kode BARANG Win2]],3),'Form Fix'!$A$6:$F$205,4,0),0) -> 0 | F5: =IFERROR(VLOOKUP(CONCATENATE(Table43_1[[#This Row],[Kode BARANG Win2]],4),'Form Fix'!$A$6:$F$205,4,0),0) -> 0 | G5: =IFERROR(VLOOKUP(CONCATENATE(Table43_1[[#This Row],[Kode BARANG Win2]],5),'Form Fix'!$A$6:$F$205,4,0),0) -> 0
A6: F4012002048020 | B6: DERMYTHOL BCL HYGIENIC PROTECT 480ML X 24 PUMP | C6: =IFERROR(VLOOKUP(CONCATENATE(Table43_1[[#This Row],[Kode BARANG Win2]],1),'Form Fix'!$A$6:$F$205,4,0),0) -> 050415200 | D6: =IFERROR(VLOOKUP(CONCATENATE(Table43_1[[#This Row],[Kode BARANG Win2]],2),'Form Fix'!$A$6:$F$205,4,0),0) -> 0 | E6: =IFERROR(VLOOKUP(CONCATENATE(Table43_1[[#This Row],[Kode BARANG Win2]],3),'Form Fix'!$A$6:$F$205,4,0),0) -> 0 | F6: =IFERROR(VLOOKUP(CONCATENATE(Table43_1[[#This Row],[Kode BARANG Win2]],4),'Form Fix'!$A$6:$F$205,4,0),0) -> 0 | G6: =IFERROR(VLOOKUP(CONCATENATE(Table43_1[[#This Row],[Kode BARANG Win2]],5),'Form Fix'!$A$6:$F$205,4,0),0) -> 0
A7: F4013001007010 | B7: DERMYTHOL SABUN HYGIENIC BIO SULFUR 70G X 72 PCS | C7: =IFERROR(VLOOKUP(CONCATENATE(Table43_1[[#This Row],[Kode BARANG Win2]],1),'Form Fix'!$A$6:$F$205,4,0),0) -> 040413100 | D7: =IFERROR(VLOOKUP(CONCATENATE(Table43_1[[#This Row],[Kode BARANG Win2]],2),'Form Fix'!$A$6:$F$205,4,0),0) -> 0 | E7: =IFERROR(VLOOKUP(CONCATENATE(Table43_1[[#This Row],[Kode BARANG Win2]],3),'Form Fix'!$A$6:$F$205,4,0),0) -> 0 | F7: =IFERROR(VLOOKUP(CONCATENATE(Table43_1[[#This Row],[Kode BARANG Win2]],4),'Form Fix'!$A$6:$F$205,4,0),0) -> 0 | G7: =IFERROR(VLOOKUP(CONCATENATE(Table43_1[[#This Row],[Kode BARANG Win2]],5),'Form Fix'!$A$6:$F$205,4,0),0) -> 0
A8: F4013002007010 | B8: DERMYTHOL SABUN HYGIENIC PROTECT 70G X 72 PCS | C8: =IFERROR(VLOOKUP(CONCATENATE(Table43_1[[#This Row],[Kode BARANG Win2]],1),'Form Fix'!$A$6:$F$205,4,0),0) -> 040415100 | D8: =IFERROR(VLOOKUP(CONCATENATE(Table43_1[[#This Row],[Kode BARANG Win2]],2),'Form Fix'!$A$6:$F$205,4,0),0) -> 0 | E8: =IFERROR(VLOOKUP(CONCATENATE(Table43_1[[#This Row],[Kode BARANG Win2]],3),'Form Fix'!$A$6:$F$205,4,0),0) -> 0 | F8: =IFERROR(VLOOKUP(CONCATENATE(Table43_1[[#This Row],[Kode BARANG Win2]],4),'Form Fix'!$A$6:$F$205,4,0),0) -> 0 | G8: =IFERROR(VLOOKUP(CONCATENATE(Table43_1[[#This Row],[Kode BARANG Win2]],5),'Form Fix'!$A$6:$F$205,4,0),0) -> 0
A9: F4021001010010 | B9: DREAM SABUN PAPAYA 100G X 72 PCS | C9: =IFERROR(VLOOKUP(CONCATENATE(Table43_1[[#This Row],[Kode BARANG Win2]],1),'Form Fix'!$A$6:$F$205,4,0),0) -> 040402200 | D9: =IFERROR(VLOOKUP(CONCATENATE(Table43_1[[#This Row],[Kode BARANG Win2]],2),'Form Fix'!$A$6:$F$205,4,0),0) -> 0 | E9: =IFERROR(VLOOKUP(CONCATENATE(Table43_1[[#This Row],[Kode BARANG Win2]],3),'Form Fix'!$A$6:$F$205,4,0),0) -> 0 | F9: =IFERROR(VLOOKUP(CONCATENATE(Table43_1[[#This Row],[Kode BARANG Win2]],4),'Form Fix'!$A$6:$F$205,4,0),0) -> 0 | G9: =IFERROR(VLOOKUP(CONCATENATE(Table43_1[[#This Row],[Kode BARANG Win2]],5),'Form Fix'!$A$6:$F$205,4,0),0) -> 0
A10: F4031101040010 | B10: GRDN OF NA EEM BCL REF MDNGHT GRDN 400ML X 24 PUMP | C10: =IFERROR(VLOOKUP(CONCATENATE(Table43_1[[#This Row],[Kode BARANG Win2]],1),'Form Fix'!$A$6:$F$205,4,0),0) -> 050703100 | D10: =IFERROR(VLOOKUP(CONCATENATE(Table43_1[[#This Row],[Kode BARANG Win2]],2),'Form Fix'!$A$6:$F$205,4,0),0) -> 0 | E10: =IFERROR(VLOOKUP(CONCATENATE(Table43_1[[#This Row],[Kode BARANG Win2]],3),'Form Fix'!$A$6:$F$205,4,0),0) -> 0 | F10: =IFERROR(VLOOKUP(CONCATENATE(Table43_1[[#This Row],[Kode BARANG Win2]],4),'Form Fix'!$A$6:$F$205,4,0),0) -> 0 | G10: =IFERROR(VLOOKUP(CONCATENATE(Table43_1[[#This Row],[Kode BARANG Win2]],5),'Form Fix'!$A$6:$F$205,4,0),0) -> 0
A11: F4031101040020 | B11: GRDN OF NA EEM BCL REF MDNGHT GRDN 400ML X 24 PCH | C11: =IFERROR(VLOOKUP(CONCATENATE(Table43_1[[#This Row],[Kode BARANG Win2]],1),'Form Fix'!$A$6:$F$205,4,0),0) -> 050703100 | D11: =IFERROR(VLOOKUP(CONCATENATE(Table43_1[[#This Row],[Kode BARANG Win2]],2),'Form Fix'!$A$6:$F$205,4,0),0) -> 0 | E11: =IFERROR(VLOOKUP(CONCATENATE(Table43_1[[#This Row],[Kode BARANG Win2]],3),'Form Fix'!$A$6:$F$205,4,0),0) -> 0 | F11: =IFERROR(VLOOKUP(CONCATENATE(Table43_1[[#This Row],[Kode BARANG Win2]],4),'Form Fix'!$A$6:$F$205,4,0),0) -> 0 | G11: =IFERROR(VLOOKUP(CONCATENATE(Table43_1[[#This Row],[Kode BARANG Win2]],5),'Form Fix'!$A$6:$F$205,4,0),0) -> 0
A12: F4031102040020 | B12: GRDN OF NA EEM BCL REF ROYAL JASMNE 400ML X 24 PCH | C12: =IFERROR(VLOOKUP(CONCATENATE(Table43_1[[#This Row],[Kode BARANG Win2]],1),'Form Fix'!$A$6:$F$205,4,0),0) -> 050702100 | D12: =IFERROR(VLOOKUP(CONCATENATE(Table43_1[[#This Row],[Kode BARANG Win2]],2),'Form Fix'!$A$6:$F$205,4,0),0) -> 0 | E12: =IFERROR(VLOOKUP(CONCATENATE(Table43_1[[#This Row],[Kode BARANG Win2]],3),'Form Fix'!$A$6:$F$205,4,0),0) -> 0 | F12: =IFERROR(VLOOKUP(CONCATENATE(Table43_1[[#This Row],[Kode BARANG Win2]],4),'Form Fix'!$A$6:$F$205,4,0),0) -> 0 | G12: =IFERROR(VLOOKUP(CONCATENATE(Table43_1[[#This Row],[Kode BARANG Win2]],5),'Form Fix'!$A$6:$F$205,4,0),0) -> 0
A13: F4031103040020 | B13: GRDN OF NA EEM BCL REF TAIFI ROSE 400ML X 24 PCH | C13: =IFERROR(VLOOKUP(CONCATENATE(Table43_1[[#This Row],[Kode BARANG Win2]],1),'Form Fix'!$A$6:$F$205,4,0),0) -> 050701100 | D13: =IFERROR(VLOOKUP(CONCATENATE(Table43_1[[#This Row],[Kode BARANG Win2]],2),'Form Fix'!$A$6:$F$205,4,0),0) -> 0 | E13: =IFERROR(VLOOKUP(CONCATENATE(Table43_1[[#This Row],[Kode BARANG Win2]],3),'Form Fix'!$A$6:$F$205,4,0),0) -> 0 | F13: =IFERROR(VLOOKUP(CONCATENATE(Table43_1[[#This Row],[Kode BARANG Win2]],4),'Form Fix'!$A$6:$F$205,4,0),0) -> 0 | G13: =IFERROR(VLOOKUP(CONCATENATE(Table43_1[[#This Row],[Kode BARANG Win2]],5),'Form Fix'!$A$6:$F$205,4,0),0) -> 0
... A176: F4073101007010N | B176: ZEN SABUN LUNCH MIX 70G X 6 BOX | C176: =IFERROR(VLOOKUP(CONCATENATE(Table43_1[[#This Row],[Kode BARANG Win2]],1),'Form Fix'!$A$6:$F$205,4,0),0) -> 042501703 | D176: =IFERROR(VLOOKUP(CONCATENATE(Table43_1[[#This Row],[Kode BARANG Win2]],2),'Form Fix'!$A$6:$F$205,4,0),0) -> 0 | E176: =IFERROR(VLOOKUP(CONCATENATE(Table43_1[[#This Row],[Kode BARANG Win2]],3),'Form Fix'!$A$6:$F$205,4,0),0) -> 0 | F176: =IFERROR(VLOOKUP(CONCATENATE(Table43_1[[#This Row],[Kode BARANG Win2]],4),'Form Fix'!$A$6:$F$205,4,0),0) -> 0 | G176: =IFERROR(VLOOKUP(CONCATENATE(Table43_1[[#This Row],[Kode BARANG Win2]],5),'Form Fix'!$A$6:$F$205,4,0),0) -> 0
B177: X | C177: =IFERROR(VLOOKUP(CONCATENATE(Table43_1[[#This Row],[Kode BARANG Win2]],1),'Form Fix'!$A$6:$F$205,4,0),0) -> 0 | D177: =IFERROR(VLOOKUP(CONCATENATE(Table43_1[[#This Row],[Kode BARANG Win2]],2),'Form Fix'!$A$6:$F$205,4,0),0) -> 0 | E177: =IFERROR(VLOOKUP(CONCATENATE(Table43_1[[#This Row],[Kode BARANG Win2]],3),'Form Fix'!$A$6:$F$205,4,0),0) -> 0 | F177: =IFERROR(VLOOKUP(CONCATENATE(Table43_1[[#This Row],[Kode BARANG Win2]],4),'Form Fix'!$A$6:$F$205,4,0),0) -> 0 | G177: =IFERROR(VLOOKUP(CONCATENATE(Table43_1[[#This Row],[Kode BARANG Win2]],5),'Form Fix'!$A$6:$F$205,4,0),0) -> 0

Sheet Form Fix
C1: UPDATE TGL
O2: =COUNTIF(Table43[LEN 50], ">50") -> 4
D3: PASTE NAMA DAN CODE PRINCIPLE (Buat Format seperti ini dan Ambil dari Daftar Harga Principle) | P3: CPI | AL3: Daftar Harga | AY3: Update Per
I4: ISI SESUAIKAN ANTARA DMS vs WIN | K4: HASIL CODE KELOMPOK, CODE BARANG & NAMA BARANG WIN | P4: Kolom Principle | AL4: Harga Beli | AP4: Harga Jual GT | AT4: Harga Jual MT | AX4: MARGIN | BD4: To Win, diisi oleh Admin
A5: CONCATENATE MAPPING | B5: No. Urut Item Sama | C5: NO | D5: Kode Pcpl | E5: Klp Brg Pcpl | F5: Nama Barang Principle | G5: ISI/CTN | H5: Ket. Tambahan / Pembantu | I5: SATUAN Fix Win | J5: Nama Kelompok Win | K5: Kode Kelompok Win | L5: Kode BARANG Win2 | M5: LEN 15 | N5: Nama Win | O5: LEN 50 | P5: Nama Pcpl | Q5: kode 2 Digit (hrf+No) | R5: Nama KLP | S5: kode 2 Digit (Nomor) | T5: Nama Sub KLP | U5: kode 1 Digit (Nomor) | V5: Nama Sub KLP2 | W5: kode 1 Digit (Nomor)5 | X5: Nama Aroma/ Rasa | Y5: kode 2 Digit (Nomor)2 | Z5: Nama Gramasi atau Jumlah Pack per CTN | AA5: kode 4 Digit (Nomor) | AB5: Nama Jenis Kemasan | AC5: kode 1 Digit (Nomor)3 | AD5: Nama Promo | AE5: kode 1 Digit (Nomor)4 | AF5: Gunakan ini apabila item tersebut sachet | AG5: kode 1 Digit (Nomor)32 | AH5: KET TAMBAHAN2 | AI5: KET. GOLONGAN | AJ5: kode 1 Digit (Nomor) | AK5: Tanda Kode Revisi | AL5: Harga Beli Pcs (-PPN) | AM5: Harga Beli Krt (- PPN) | AN5: Harga Beli Pcs (+PPN) | AO5: Harga Beli Krt (+PPN) | AP5: Harga Jual Pcs GT (-PPN) | AQ5: Harga Jual Krt GT (- PPN) | AR5: Harga Jual Pcs GT (+PPN | AS5: Harga Jual Krt GT (+PPN) | AT5: Harga Jual Pcs MT (-PPN) | AU5: Harga Jual Krt MT (- PPN) | AV5: Harga Jual Pcs MT (+PPN) | AW5: Harga Jual Krt MT (+PPN) | AX5: MARGIN | AY5: Efektif Pembuatan | AZ5: Efektif Naik Harga | BA5: Status Pembuatan | BB5: Status Harga | BC5: Status Barang | BD5: Mata Uang | BE5: Kode Golongan | BF5: Nama Golongan | BG5: Kode PCPL To Win | BH5: Kode Jenis Produk | BI5: SAT BSR | BJ5: GD | BK5: Kode PRK | BL5: Kode PRK SJ | BM5: Kode Job | BN5: Approval | BO5: Nama Principle
A6: =CONCATENATE(Table43[[#This Row],[Kode BARANG Win2]],Table43[[#This Row],[No. Urut Item Sama]]) -> F40111000070101 | B6: 1 | C6: 1 | D6: 040411111 | E6: DERMYTHOL | F6: DERMYTHOL BAR 12x6x70Gr (Lunchbox) Mix Varian | G6: 6 | H6: 8992946535182 | I6: =Table43[[#This Row],[Nama Jenis Kemasan]] -> BOX | J6: =TRIM(CONCATENATE(Table43[[#This Row],[Nama KLP]]," ",Table43[[#This Row],[Nama Sub KLP]])) -> DERMYTHOL BAR | K6: =CONCATENATE(Table43[[#This Row],[kode 2 Digit (hrf+No)]],Table43[[#This Row],[kode 2 Digit (Nomor)]],Table43[[#This Row],[kode 1 Digit (Nomor)]]) -> F4011 | L6: =IF(AG6="",CONCATENATE(Q6,S6,U6,W6,Y6,AA6,AC6,AE6,Table43[[#This Row],[Tanda Kode Revisi]]),CONCATENATE(Q6,S6,U6,W6,Y6,AA6,AC6,AG6)) -> F4011100007010 | M6: =LEN(L6) -> 14 | N6: =IF(AF6<>"",TRIM(UPPER(CONCATENATE(P6," ",R6," ",T6," ",V6," ",X6," ",Z6," ","X"," ",Table43[[#This Row],[ISI/CTN]]," ",AF6," ",AB6," ",AD6," ",AH6))),TRIM(UPPER(CONCATENATE(P6," ",R6," ",T6," ",V6," ",X6," ",Z6," ","X"," ",Table43[[#This Row],[ISI/CTN]]," ",AB6," ",AD6," ",AH6)))) -> DERMYTHOL BAR LUNCH 70G X 6 BOX | O6: =LEN(N6) -> 31 | Q6: F4 | R6: DERMYTHOL | S6: 01 | T6: BAR | U6: 1 | V6: LUNCH | W6: 1 | Y6: 00 | Z6: 70G | AA6: 0070 | AB6: BOX | AC6: 1 | AE6: 0 | AI6: GRAM | AJ6: 1 | AL6: 30029.189 | AM6: =Table43[[#This Row],[Harga Beli Pcs (-PPN)]]*Table43[[#This Row],[ISI/CTN]] -> 180175.14 | AN6: =Table43[[#This Row],[Harga Beli Pcs (-PPN)]]*1.11 -> 33332.4 | AO6: =Table43[[#This Row],[Harga Beli Krt (- PPN)]]*1.11 -> 199994.4 | AP6: 32432.432 | AQ6: =Table43[[#This Row],[Harga Jual Pcs GT (-PPN)]]*Table43[[#This Row],[ISI/CTN]] -> 194594.59 | AR6: =Table43[[#This Row],[Harga Jual Pcs GT (-PPN)]]*1.11 -> 36000 | AS6: =Table43[[#This Row],[Harga Jual Krt GT (- PPN)]]*1.11 -> 216000 | AU6: =Table43[[#This Row],[Harga Jual Pcs MT (-PPN)]]*Table43[[#This Row],[ISI/CTN]] -> 0 | AV6: =Table43[[#This Row],[Harga Jual Pcs MT (-PPN)]]*1.11 -> 0 | AW6: =Table43[[#This Row],[Harga Jual Pcs MT (+PPN)]]*Table43[[#This Row],[ISI/CTN]] -> 0 | AX6: =IFERROR((Table43[[#This Row],[Harga Jual Pcs GT (-PPN)]]-Table43[[#This Row],[Harga Beli Pcs (-PPN)]])/Table43[[#This Row],[Harga Jual Pcs GT (-PPN)]],0) -> 0.0741 | AY6: 45848 | BA6: =IF(TODAY()-Table43[[#This Row],[Efektif Pembuatan]]>60,"Lama","Baru") -> Lama | BB6: =IF(TODAY()-Table43[[#This Row],[Efektif Naik Harga]]<30,"Naik","Sama") -> Sama | BC6: Aktif | BD6: =IF(Table43[[#This Row],[Kode BARANG Win2]]<>"","IDR","") -> IDR | BE6: =CONCATENATE(Table43[[#This Row],[kode 1 Digit (Nomor)]],Table43[[#This Row],[kode 4 Digit (Nomor)]]) -> 10070 | BF6: =Table43[[#This Row],[Nama Gramasi atau Jumlah Pack per CTN]] -> 70G | BG6: S-FRN | BH6: 45MIX | BI6: =IF(Table43[[#This Row],[SATUAN Fix Win]]<>"","KRT") -> KRT | BJ6: =IF(Table43[[#This Row],[SATUAN Fix Win]]<>"","GD01") -> GD01 | BK6: =IF(Table43[[#This Row],[SATUAN Fix Win]]<>"",11611) -> 11611 | BL6: =IF(Table43[[#This Row],[SATUAN Fix Win]]<>"",11612) -> 11612 | BM6: 0101 | BN6: =IF(Table43[[#This Row],[SATUAN Fix Win]]<>"",1) -> 1 | BO6: PT. FOKUS RITEL NUSAPRIMA
A7: =CONCATENATE(Table43[[#This Row],[Kode BARANG Win2]],Table43[[#This Row],[No. Urut Item Sama]]) -> F40121010400101 | B7: 1 | C7: 2 | D7: 050413100 | E7: DERMYTHOL | F7: DERMYTHOL Body Cleanser Hygienic Bio Sulfur Ref 24x400Ml | G7: 24 | H7: 8992946534341 | I7: =Table43[[#This Row],[Nama Jenis Kemasan]] -> PCH | J7: =TRIM(CONCATENATE(Table43[[#This Row],[Nama KLP]]," ",Table43[[#This Row],[Nama Sub KLP]])) -> DERMYTHOL BCL | K7: =CONCATENATE(Table43[[#This Row],[kode 2 Digit (hrf+No)]],Table43[[#This Row],[kode 2 Digit (Nomor)]],Table43[[#This Row],[kode 1 Digit (Nomor)]]) -> F4012 | L7: =IF(AG7="",CONCATENATE(Q7,S7,U7,W7,Y7,AA7,AC7,AE7,Table43[[#This Row],[Tanda Kode Revisi]]),CONCATENATE(Q7,S7,U7,W7,Y7,AA7,AC7,AG7)) -> F4012101040010 | M7: =LEN(L7) -> 14 | N7: =IF(AF7<>"",TRIM(UPPER(CONCATENATE(P7," ",R7," ",T7," ",V7," ",X7," ",Z7," ","X"," ",Table43[[#This Row],[ISI/CTN]]," ",AF7," ",AB7," ",AD7," ",AH7))),TRIM(UPPER(CONCATENATE(P7," ",R7," ",T7," ",V7," ",X7," ",Z7," ","X"," ",Table43[[#This Row],[ISI/CTN]]," ",AB7," ",AD7," ",AH7)))) -> DERMYTHOL BCL REF HYGIENIC BIO SLFR 400ML X 24 PCH | O7: =LEN(N7) -> 50 | Q7: F4 | R7: DERMYTHOL | S7: 01 | T7: BCL | U7: 2 | V7: REF | W7: 1 | X7: HYGIENIC BIO SLFR | Y7: 01 | Z7: 400ML | AA7: 0400 | AB7: PCH | AC7: 1 | AE7: 0 | AI7: LITER | AJ7: 2 | AL7: 21937.991 | AM7: =Table43[[#This Row],[Harga Beli Pcs (-PPN)]]*Table43[[#This Row],[ISI/CTN]] -> 526511.78 | AN7: =Table43[[#This Row],[Harga Beli Pcs (-PPN)]]*1.11 -> 24351.17 | AO7: =Table43[[#This Row],[Harga Beli Krt (- PPN)]]*1.11 -> 584428.08 | AP7: 23693.694 | AQ7: =Table43[[#This Row],[Harga Jual Pcs GT (-PPN)]]*Table43[[#This Row],[ISI/CTN]] -> 568648.65 | AR7: =Table43[[#This Row],[Harga Jual Pcs GT (-PPN)]]*1.11 -> 26300 | AS7: =Table43[[#This Row],[Harga Jual Krt GT (- PPN)]]*1.11 -> 631200 | AU7: =Table43[[#This Row],[Harga Jual Pcs MT (-PPN)]]*Table43[[#This Row],[ISI/CTN]] -> 0 | AV7: =Table43[[#This Row],[Harga Jual Pcs MT (-PPN)]]*1.11 -> 0 | AW7: =Table43[[#This Row],[Harga Jual Pcs MT (+PPN)]]*Table43[[#This Row],[ISI/CTN]] -> 0 | AX7: =IFERROR((Table43[[#This Row],[Harga Jual Pcs GT (-PPN)]]-Table43[[#This Row],[Harga Beli Pcs (-PPN)]])/Table43[[#This Row],[Harga Jual Pcs GT (-PPN)]],0) -> 0.0741 | AY7: 45848 | BA7: =IF(TODAY()-Table43[[#This Row],[Efektif Pembuatan]]>60,"Lama","Baru") -> Lama | BB7: =IF(TODAY()-Table43[[#This Row],[Efektif Naik Harga]]<30,"Naik","Sama") -> Sama | BC7: Aktif | BD7: =IF(Table43[[#This Row],[Kode BARANG Win2]]<>"","IDR","") -> IDR | BE7: =CONCATENATE(Table43[[#This Row],[kode 1 Digit (Nomor)]],Table43[[#This Row],[kode 4 Digit (Nomor)]]) -> 20400 | BF7: =Table43[[#This Row],[Nama Gramasi atau Jumlah Pack per CTN]] -> 400ML | BG7: S-FRN | BH7: 45MIX | BI7: =IF(Table43[[#This Row],[SATUAN Fix Win]]<>"","KRT") -> KRT | BJ7: =IF(Table43[[#This Row],[SATUAN Fix Win]]<>"","GD01") -> GD01 | BK7: =IF(Table43[[#This Row],[SATUAN Fix Win]]<>"",11611) -> 11611 | BL7: =IF(Table43[[#This Row],[SATUAN Fix Win]]<>"",11612) -> 11612 | BM7: 0101 | BN7: =IF(Table43[[#This Row],[SATUAN Fix Win]]<>"",1) -> 1 | BO7: PT. FOKUS RITEL NUSAPRIMA
A8: =CONCATENATE(Table43[[#This Row],[Kode BARANG Win2]],Table43[[#This Row],[No. Urut Item Sama]]) -> F40121020400101 | B8: 1 | C8: 3 | D8: 050415100 | E8: DERMYTHOL | F8: DERMYTHOL Body Cleanser Hygienic Protect Ref 24x400Ml | G8: 24 | H8: 8992946534324 | I8: =Table43[[#This Row],[Nama Jenis Kemasan]] -> PCH | J8: =TRIM(CONCATENATE(Table43[[#This Row],[Nama KLP]]," ",Table43[[#This Row],[Nama Sub KLP]])) -> DERMYTHOL BCL | K8: =CONCATENATE(Table43[[#This Row],[kode 2 Digit (hrf+No)]],Table43[[#This Row],[kode 2 Digit (Nomor)]],Table43[[#This Row],[kode 1 Digit (Nomor)]]) -> F4012 | L8: =IF(AG8="",CONCATENATE(Q8,S8,U8,W8,Y8,AA8,AC8,AE8,Table43[[#This Row],[Tanda Kode Revisi]]),CONCATENATE(Q8,S8,U8,W8,Y8,AA8,AC8,AG8)) -> F4012102040010 | M8: =LEN(L8) -> 14 | N8: =IF(AF8<>"",TRIM(UPPER(CONCATENATE(P8," ",R8," ",T8," ",V8," ",X8," ",Z8," ","X"," ",Table43[[#This Row],[ISI/CTN]]," ",AF8," ",AB8," ",AD8," ",AH8))),TRIM(UPPER(CONCATENATE(P8," ",R8," ",T8," ",V8," ",X8," ",Z8," ","X"," ",Table43[[#This Row],[ISI/CTN]]," ",AB8," ",AD8," ",AH8)))) -> DERMYTHOL BCL REF HYGIENIC PROTECT 400ML X 24 PCH | O8: =LEN(N8) -> 49 | Q8: F4 | R8: DERMYTHOL | S8: 01 | T8: BCL | U8: 2 | V8: REF | W8: 1 | X8: HYGIENIC PROTECT | Y8: 02 | Z8: 400ML | AA8: 0400 | AB8: PCH | AC8: 1 | AE8: 0 | AI8: LITER | AJ8: 2 | AL8: 21937.991 | AM8: =Table43[[#This Row],[Harga Beli Pcs (-PPN)]]*Table43[[#This Row],[ISI/CTN]] -> 526511.78 | AN8: =Table43[[#This Row],[Harga Beli Pcs (-PPN)]]*1.11 -> 24351.17 | AO8: =Table43[[#This Row],[Harga Beli Krt (- PPN)]]*1.11 -> 584428.08 | AP8: 23693.694 | AQ8: =Table43[[#This Row],[Harga Jual Pcs GT (-PPN)]]*Table43[[#This Row],[ISI/CTN]] -> 568648.65 | AR8: =Table43[[#This Row],[Harga Jual Pcs GT (-PPN)]]*1.11 -> 26300 | AS8: =Table43[[#This Row],[Harga Jual Krt GT (- PPN)]]*1.11 -> 631200 | AU8: =Table43[[#This Row],[Harga Jual Pcs MT (-PPN)]]*Table43[[#This Row],[ISI/CTN]] -> 0 | AV8: =Table43[[#This Row],[Harga Jual Pcs MT (-PPN)]]*1.11 -> 0 | AW8: =Table43[[#This Row],[Harga Jual Pcs MT (+PPN)]]*Table43[[#This Row],[ISI/CTN]] -> 0 | AX8: =IFERROR((Table43[[#This Row],[Harga Jual Pcs GT (-PPN)]]-Table43[[#This Row],[Harga Beli Pcs (-PPN)]])/Table43[[#This Row],[Harga Jual Pcs GT (-PPN)]],0) -> 0.0741 | AY8: 45848 | BA8: =IF(TODAY()-Table43[[#This Row],[Efektif Pembuatan]]>60,"Lama","Baru") -> Lama | BB8: =IF(TODAY()-Table43[[#This Row],[Efektif Naik Harga]]<30,"Naik","Sama") -> Sama | BC8: Aktif | BD8: =IF(Table43[[#This Row],[Kode BARANG Win2]]<>"","IDR","") -> IDR | BE8: =CONCATENATE(Table43[[#This Row],[kode 1 Digit (Nomor)]],Table43[[#This Row],[kode 4 Digit (Nomor)]]) -> 20400 | BF8: =Table43[[#This Row],[Nama Gramasi atau Jumlah Pack per CTN]] -> 400ML | BG8: S-FRN | BH8: 45MIX | BI8: =IF(Table43[[#This Row],[SATUAN Fix Win]]<>"","KRT") -> KRT | BJ8: =IF(Table43[[#This Row],[SATUAN Fix Win]]<>"","GD01") -> GD01 | BK8: =IF(Table43[[#This Row],[SATUAN Fix Win]]<>"",11611) -> 11611 | BL8: =IF(Table43[[#This Row],[SATUAN Fix Win]]<>"",11612) -> 11612 | BM8: 0101 | BN8: =IF(Table43[[#This Row],[SATUAN Fix Win]]<>"",1) -> 1 | BO8: PT. FOKUS RITEL NUSAPRIMA
A9: =CONCATENATE(Table43[[#This Row],[Kode BARANG Win2]],Table43[[#This Row],[No. Urut Item Sama]]) -> F40120010480201 | B9: 1 | C9: 4 | D9: 050413200 | E9: DERMYTHOL | F9: DERMYTHOL Body Cleanser Hygienic Bio Sulfur Btl 24x480Ml | G9: 24 | H9: 8992946534287 | I9: =Table43[[#This Row],[Nama Jenis Kemasan]] -> PUMP | J9: =TRIM(CONCATENATE(Table43[[#This Row],[Nama KLP]]," ",Table43[[#This Row],[Nama Sub KLP]])) -> DERMYTHOL BCL | K9: =CONCATENATE(Table43[[#This Row],[kode 2 Digit (hrf+No)]],Table43[[#This Row],[kode 2 Digit (Nomor)]],Table43[[#This Row],[kode 1 Digit (Nomor)]]) -> F4012 | L9: =IF(AG9="",CONCATENATE(Q9,S9,U9,W9,Y9,AA9,AC9,AE9,Table43[[#This Row],[Tanda Kode Revisi]]),CONCATENATE(Q9,S9,U9,W9,Y9,AA9,AC9,AG9)) -> F4012001048020 | M9: =LEN(L9) -> 14 | N9: =IF(AF9<>"",TRIM(UPPER(CONCATENATE(P9," ",R9," ",T9," ",V9," ",X9," ",Z9," ","X"," ",Table43[[#This Row],[ISI/CTN]]," ",AF9," ",AB9," ",AD9," ",AH9))),TRIM(UPPER(CONCATENATE(P9," ",R9," ",T9," ",V9," ",X9," ",Z9," ","X"," ",Table43[[#This Row],[ISI/CTN]]," ",AB9," ",AD9," ",AH9)))) -> DERMYTHOL BCL HYGIENIC BIO SULFUR 480ML X 24 PUMP | O9: =LEN(N9) -> 49 | Q9: F4 | R9: DERMYTHOL | S9: 01 | T9: BCL | U9: 2 | W9: 0 | X9: HYGIENIC BIO SULFUR | Y9: 01 | Z9: 480ML | AA9: 0480 | AB9: PUMP | AC9: 2 | AE9: 0 | AI9: LITER | AJ9: 2 | AL9: 35034.054 | AM9: =Table43[[#This Row],[Harga Beli Pcs (-PPN)]]*Table43[[#This Row],[ISI/CTN]] -> 840817.3 | AN9: =Table43[[#This Row],[Harga Beli Pcs (-PPN)]]*1.11 -> 38887.8 | AO9: =Table43[[#This Row],[Harga Beli Krt (- PPN)]]*1.11 -> 933307.2 | AP9: 37837.838 | AQ9: =Table43[[#This Row],[Harga Jual Pcs GT (-PPN)]]*Table43[[#This Row],[ISI/CTN]] -> 908108.11 | AR9: =Table43[[#This Row],[Harga Jual Pcs GT (-PPN)]]*1.11 -> 42000 | AS9: =Table43[[#This Row],[Harga Jual Krt GT (- PPN)]]*1.11 -> 1008000 | AU9: =Table43[[#This Row],[Harga Jual Pcs MT (-PPN)]]*Table43[[#This Row],[ISI/CTN]] -> 0 | AV9: =Table43[[#This Row],[Harga Jual Pcs MT (-PPN)]]*1.11 -> 0 | AW9: =Table43[[#This Row],[Harga Jual Pcs MT (+PPN)]]*Table43[[#This Row],[ISI/CTN]] -> 0 | AX9: =IFERROR((Table43[[#This Row],[Harga Jual Pcs GT (-PPN)]]-Table43[[#This Row],[Harga Beli Pcs (-PPN)]])/Table43[[#This Row],[Harga Jual Pcs GT (-PPN)]],0) -> 0.0741 | AY9: 45848 | BA9: =IF(TODAY()-Table43[[#This Row],[Efektif Pembuatan]]>60,"Lama","Baru") -> Lama | BB9: =IF(TODAY()-Table43[[#This Row],[Efektif Naik Harga]]<30,"Naik","Sama") -> Sama | BC9: Aktif | BD9: =IF(Table43[[#This Row],[Kode BARANG Win2]]<>"","IDR","") -> IDR | BE9: =CONCATENATE(Table43[[#This Row],[kode 1 Digit (Nomor)]],Table43[[#This Row],[kode 4 Digit (Nomor)]]) -> 20480 | BF9: =Table43[[#This Row],[Nama Gramasi atau Jumlah Pack per CTN]] -> 480ML | BG9: S-FRN | BH9: 45MIX | BI9: =IF(Table43[[#This Row],[SATUAN Fix Win]]<>"","KRT") -> KRT | BJ9: =IF(Table43[[#This Row],[SATUAN Fix Win]]<>"","GD01") -> GD01 | BK9: =IF(Table43[[#This Row],[SATUAN Fix Win]]<>"",11611) -> 11611 | BL9: =IF(Table43[[#This Row],[SATUAN Fix Win]]<>"",11612) -> 11612 | BM9: 0101 | BN9: =IF(Table43[[#This Row],[SATUAN Fix Win]]<>"",1) -> 1 | BO9: PT. FOKUS RITEL NUSAPRIMA
